<?xml version="1.0" ?>
<!-- =================================================================================== -->
<!-- |    This document was autogenerated by xacro from engineer.urdf.xacro            | -->
<!-- |    EDITING THIS FILE BY HAND IS NOT RECOMMENDED                                 | -->
<!-- =================================================================================== -->
<robot name="engineer">
  <link name="base_link">
    <inertial>
      <mass value="14.321805"/>
      <origin xyz="-0.011828 -0.007426 0.160123"/>
      <inertia ixx="1.06e0" ixy="1.071e-3" ixz="3.011e-2" iyy="9.494e-1" iyz="2.344e-2" izz="7.430e-1"/>
    </inertial>
    <visual>
      <origin rpy="0 0 0" xyz="0 0 0"/>
      <geometry>
        <mesh filename="package://rm_description/meshes/engineer/base_link.stl" scale="0.001 0.001 0.001"/>
      </geometry>
    </visual>
    <collision>
      <origin rpy="0 0 0" xyz="0 0 0"/>
      <geometry>
        <mesh filename="package://rm_description/meshes/engineer/base_collision.stl" scale="0.001 0.001 0.001"/>
      </geometry>
    </collision>
    <collision>
      <origin rpy="0 0 0" xyz="0 0.251 0.387"/>
      <geometry>
        <box size="0.43 0.0387 0.567"/>
      </geometry>
    </collision>
    <collision>
      <origin rpy="0 0 0" xyz="0 -0.251 0.407"/>
      <geometry>
        <box size="0.43 0.0387 0.567"/>
      </geometry>
    </collision>
    <selfCollide>true</selfCollide>
  </link>
  <link name="card">
    <inertial>
      <mass value="0.807434"/>
      <origin xyz="0.038318 -0.188972 -0.009577"/>
      <inertia ixx="3.069e-2" ixy="5.419e-3" ixz="2.460e-4" iyy="4.318e-3" iyz="3.398e-2" izz="4.126e-3"/>
    </inertial>
    <visual>
      <origin rpy="0 0 -1.57" xyz="0 0 0"/>
      <geometry>
        <mesh filename="package://rm_description/meshes/engineer/card.stl" scale="0.001 0.001 0.001"/>
      </geometry>
    </visual>
  </link>
  <link name="drag">
    <inertial>
      <mass value="0.404605"/>
      <origin xyz="0.053283 0.032371 0.017125"/>
      <inertia ixx="5.893e-3" ixy="1.346e-4" ixz="-8.957569e-5" iyy="2.879e-3" iyz="-4.020e-4" izz="8.206e-3"/>
    </inertial>
    <visual>
      <origin rpy="0 0 0" xyz="0 0 0"/>
      <geometry>
        <mesh filename="package://rm_description/meshes/engineer/drag.stl" scale="0.001 0.001 0.001"/>
      </geometry>
    </visual>
  </link>
  <joint name="card_joint" type="prismatic">
    <parent link="base_link"/>
    <child link="card"/>
    <origin rpy="0 0 -1.57" xyz="0.244 0. 0.036"/>
    <axis xyz="0 1 0"/>
    <limit effort="200" lower="-0.01" upper="0.6" velocity="3"/>
  </joint>
  <joint name="drag_joint" type="revolute">
    <parent link="base_link"/>
    <child link="drag"/>
    <origin rpy="0 0 0" xyz="0.245 0 0.06"/>
    <axis xyz="0 1 0"/>
    <limit effort="200" lower="-10" upper="20" velocity="6"/>
  </joint>
  <transmission name="trans_card_joint">
    <type>transmission_interface/SimpleTransmission</type>
    <actuator name="card_joint_motor">
      <mechanicalReduction>1800</mechanicalReduction>
    </actuator>
    <joint name="card_joint">
      <offset>0</offset>
      <hardwareInterface>hardware_interface/EffortJointInterface</hardwareInterface>
    </joint>
  </transmission>
  <transmission name="trans_drag_joint">
    <type>transmission_interface/SimpleTransmission</type>
    <actuator name="drag_joint_motor">
      <mechanicalReduction>2</mechanicalReduction>
    </actuator>
    <joint name="drag_joint">
      <offset>0</offset>
      <hardwareInterface>hardware_interface/EffortJointInterface</hardwareInterface>
    </joint>
  </transmission>
  <link name="left_front_pivot">
    <visual>
      <origin rpy="0 0 0" xyz="0 0 0"/>
      <geometry>
        <mesh filename="package://rm_description/meshes/common/swerve_pivot.stl" scale="0.001 0.001 0.001"/>
      </geometry>
    </visual>
    <inertial>
      <mass value="0.114131"/>
      <origin rpy="0 0 0" xyz="-0.00005 0.017079 -0.041536"/>
      <inertia ixx="1.335e-4" ixy="26.001e-9" ixz="65.031e-9" iyy="1.372e-4" iyz="20051.742e-9" izz="66866.081e-9"/>
    </inertial>
  </link>
  <joint name="left_front_pivot_joint" type="revolute">
    <axis xyz="0 0 1"/>
    <origin rpy="0 0 0" xyz="0.2115 0.206 0.06795"/>
    <parent link="base_link"/>
    <child link="left_front_pivot"/>
    <dynamics damping="0.0" friction="0.1"/>
    <limit effort="1.2" lower="-1e10" upper="1e10" velocity="50"/>
  </joint>
  <link name="left_front_wheel">
    <visual>
      <origin rpy="0 0 0" xyz="0 0 0"/>
      <geometry>
        <mesh filename="package://rm_description/meshes/common/swerve_wheel.stl" scale="0.001 0.001 0.001"/>
      </geometry>
    </visual>
    <inertial>
      <mass value="0.267401"/>
      <origin rpy="0 0 0" xyz="-0.000004 0.000125 0.000001"/>
      <inertia ixx="3.585e-4" ixy="0" ixz="13.459e-9" iyy="6.846e-4" iyz="0" izz="3.584e-4"/>
    </inertial>
    <collision>
      <origin rpy="1.5707963267948966 0 0" xyz="0 0 0"/>
      <geometry>
        <cylinder length="0.02" radius="0.055"/>
      </geometry>
    </collision>
  </link>
  <joint name="left_front_wheel_joint" type="revolute">
    <axis xyz="0 1 0"/>
    <origin rpy="0 0 0" xyz="0 0 -0.06635"/>
    <parent link="left_front_pivot"/>
    <child link="left_front_wheel"/>
    <limit effort="3" lower="-1e10" upper="1e10" velocity="76"/>
    <dynamics damping="0.0" friction="0.05"/>
  </joint>
  <gazebo reference="left_front_wheel">
    <mu1 value="1.0"/>
    <mu2 value="1.0"/>
    <kp value="1000000.0"/>
    <kd value="100.0"/>
    <material>Gazebo/Black</material>
  </gazebo>
  <link name="right_front_pivot">
    <visual>
      <origin rpy="0 0 0" xyz="0 0 0"/>
      <geometry>
        <mesh filename="package://rm_description/meshes/common/swerve_pivot.stl" scale="0.001 0.001 0.001"/>
      </geometry>
    </visual>
    <inertial>
      <mass value="0.114131"/>
      <origin rpy="0 0 0" xyz="-0.00005 0.017079 -0.041536"/>
      <inertia ixx="1.335e-4" ixy="26.001e-9" ixz="65.031e-9" iyy="1.372e-4" iyz="20051.742e-9" izz="66866.081e-9"/>
    </inertial>
  </link>
  <joint name="right_front_pivot_joint" type="revolute">
    <axis xyz="0 0 1"/>
    <origin rpy="0 0 0" xyz="0.2115 -0.206 0.06795"/>
    <parent link="base_link"/>
    <child link="right_front_pivot"/>
    <dynamics damping="0.0" friction="0.1"/>
    <limit effort="1.2" lower="-1e10" upper="1e10" velocity="50"/>
  </joint>
  <link name="right_front_wheel">
    <visual>
      <origin rpy="0 0 0" xyz="0 0 0"/>
      <geometry>
        <mesh filename="package://rm_description/meshes/common/swerve_wheel.stl" scale="0.001 0.001 0.001"/>
      </geometry>
    </visual>
    <inertial>
      <mass value="0.267401"/>
      <origin rpy="0 0 0" xyz="-0.000004 0.000125 0.000001"/>
      <inertia ixx="3.585e-4" ixy="0" ixz="13.459e-9" iyy="6.846e-4" iyz="0" izz="3.584e-4"/>
    </inertial>
    <collision>
      <origin rpy="1.5707963267948966 0 0" xyz="0 0 0"/>
      <geometry>
        <cylinder length="0.02" radius="0.055"/>
      </geometry>
    </collision>
  </link>
  <joint name="right_front_wheel_joint" type="revolute">
    <axis xyz="0 1 0"/>
    <origin rpy="0 0 0" xyz="0 0 -0.06635"/>
    <parent link="right_front_pivot"/>
    <child link="right_front_wheel"/>
    <limit effort="3" lower="-1e10" upper="1e10" velocity="76"/>
    <dynamics damping="0.0" friction="0.05"/>
  </joint>
  <gazebo reference="right_front_wheel">
    <mu1 value="1.0"/>
    <mu2 value="1.0"/>
    <kp value="1000000.0"/>
    <kd value="100.0"/>
    <material>Gazebo/Black</material>
  </gazebo>
  <link name="left_back_pivot">
    <visual>
      <origin rpy="0 0 0" xyz="0 0 0"/>
      <geometry>
        <mesh filename="package://rm_description/meshes/common/swerve_pivot.stl" scale="0.001 0.001 0.001"/>
      </geometry>
    </visual>
    <inertial>
      <mass value="0.114131"/>
      <origin rpy="0 0 0" xyz="-0.00005 0.017079 -0.041536"/>
      <inertia ixx="1.335e-4" ixy="26.001e-9" ixz="65.031e-9" iyy="1.372e-4" iyz="20051.742e-9" izz="66866.081e-9"/>
    </inertial>
  </link>
  <joint name="left_back_pivot_joint" type="revolute">
    <axis xyz="0 0 1"/>
    <origin rpy="0 0 0" xyz="-0.2115 0.206 0.06795"/>
    <parent link="base_link"/>
    <child link="left_back_pivot"/>
    <dynamics damping="0.0" friction="0.1"/>
    <limit effort="1.2" lower="-1e10" upper="1e10" velocity="50"/>
  </joint>
  <link name="left_back_wheel">
    <visual>
      <origin rpy="0 0 0" xyz="0 0 0"/>
      <geometry>
        <mesh filename="package://rm_description/meshes/common/swerve_wheel.stl" scale="0.001 0.001 0.001"/>
      </geometry>
    </visual>
    <inertial>
      <mass value="0.267401"/>
      <origin rpy="0 0 0" xyz="-0.000004 0.000125 0.000001"/>
      <inertia ixx="3.585e-4" ixy="0" ixz="13.459e-9" iyy="6.846e-4" iyz="0" izz="3.584e-4"/>
    </inertial>
    <collision>
      <origin rpy="1.5707963267948966 0 0" xyz="0 0 0"/>
      <geometry>
        <cylinder length="0.02" radius="0.055"/>
      </geometry>
    </collision>
  </link>
  <joint name="left_back_wheel_joint" type="revolute">
    <axis xyz="0 1 0"/>
    <origin rpy="0 0 0" xyz="0 0 -0.06635"/>
    <parent link="left_back_pivot"/>
    <child link="left_back_wheel"/>
    <limit effort="3" lower="-1e10" upper="1e10" velocity="76"/>
    <dynamics damping="0.0" friction="0.05"/>
  </joint>
  <gazebo reference="left_back_wheel">
    <mu1 value="1.0"/>
    <mu2 value="1.0"/>
    <kp value="1000000.0"/>
    <kd value="100.0"/>
    <material>Gazebo/Black</material>
  </gazebo>
  <link name="right_back_pivot">
    <visual>
      <origin rpy="0 0 0" xyz="0 0 0"/>
      <geometry>
        <mesh filename="package://rm_description/meshes/common/swerve_pivot.stl" scale="0.001 0.001 0.001"/>
      </geometry>
    </visual>
    <inertial>
      <mass value="0.114131"/>
      <origin rpy="0 0 0" xyz="-0.00005 0.017079 -0.041536"/>
      <inertia ixx="1.335e-4" ixy="26.001e-9" ixz="65.031e-9" iyy="1.372e-4" iyz="20051.742e-9" izz="66866.081e-9"/>
    </inertial>
  </link>
  <joint name="right_back_pivot_joint" type="revolute">
    <axis xyz="0 0 1"/>
    <origin rpy="0 0 0" xyz="-0.2115 -0.206 0.06795"/>
    <parent link="base_link"/>
    <child link="right_back_pivot"/>
    <dynamics damping="0.0" friction="0.1"/>
    <limit effort="1.2" lower="-1e10" upper="1e10" velocity="50"/>
  </joint>
  <link name="right_back_wheel">
    <visual>
      <origin rpy="0 0 0" xyz="0 0 0"/>
      <geometry>
        <mesh filename="package://rm_description/meshes/common/swerve_wheel.stl" scale="0.001 0.001 0.001"/>
      </geometry>
    </visual>
    <inertial>
      <mass value="0.267401"/>
      <origin rpy="0 0 0" xyz="-0.000004 0.000125 0.000001"/>
      <inertia ixx="3.585e-4" ixy="0" ixz="13.459e-9" iyy="6.846e-4" iyz="0" izz="3.584e-4"/>
    </inertial>
    <collision>
      <origin rpy="1.5707963267948966 0 0" xyz="0 0 0"/>
      <geometry>
        <cylinder length="0.02" radius="0.055"/>
      </geometry>
    </collision>
  </link>
  <joint name="right_back_wheel_joint" type="revolute">
    <axis xyz="0 1 0"/>
    <origin rpy="0 0 0" xyz="0 0 -0.06635"/>
    <parent link="right_back_pivot"/>
    <child link="right_back_wheel"/>
    <limit effort="3" lower="-1e10" upper="1e10" velocity="76"/>
    <dynamics damping="0.0" friction="0.05"/>
  </joint>
  <gazebo reference="right_back_wheel">
    <mu1 value="1.0"/>
    <mu2 value="1.0"/>
    <kp value="1000000.0"/>
    <kd value="100.0"/>
    <material>Gazebo/Black</material>
  </gazebo>
  <transmission name="left_front_pivot_trans">
    <type>transmission_interface/SimpleTransmission</type>
    <actuator name="left_front_pivot_motor">
      <mechanicalReduction>-1</mechanicalReduction>
    </actuator>
    <joint name="left_front_pivot_joint">
      <offset>4.481304</offset>
      <hardwareInterface>hardware_interface/EffortJointInterface</hardwareInterface>
    </joint>
  </transmission>
  <transmission name="left_front_wheel_trans">
    <type>transmission_interface/SimpleTransmission</type>
    <actuator name="left_front_wheel_motor">
      <mechanicalReduction>13</mechanicalReduction>
    </actuator>
    <joint name="left_front_wheel_joint">
      <hardwareInterface>hardware_interface/EffortJointInterface</hardwareInterface>
    </joint>
  </transmission>
  <transmission name="right_front_pivot_trans">
    <type>transmission_interface/SimpleTransmission</type>
    <actuator name="right_front_pivot_motor">
      <mechanicalReduction>-1</mechanicalReduction>
    </actuator>
    <joint name="right_front_pivot_joint">
      <offset>0.733332</offset>
      <hardwareInterface>hardware_interface/EffortJointInterface</hardwareInterface>
    </joint>
  </transmission>
  <transmission name="right_front_wheel_trans">
    <type>transmission_interface/SimpleTransmission</type>
    <actuator name="right_front_wheel_motor">
      <mechanicalReduction>13</mechanicalReduction>
    </actuator>
    <joint name="right_front_wheel_joint">
      <hardwareInterface>hardware_interface/EffortJointInterface</hardwareInterface>
    </joint>
  </transmission>
  <transmission name="left_back_pivot_trans">
    <type>transmission_interface/SimpleTransmission</type>
    <actuator name="left_back_pivot_motor">
      <mechanicalReduction>-1</mechanicalReduction>
    </actuator>
    <joint name="left_back_pivot_joint">
      <offset>4.25117</offset>
      <hardwareInterface>hardware_interface/EffortJointInterface</hardwareInterface>
    </joint>
  </transmission>
  <transmission name="left_back_wheel_trans">
    <type>transmission_interface/SimpleTransmission</type>
    <actuator name="left_back_wheel_motor">
      <mechanicalReduction>13</mechanicalReduction>
    </actuator>
    <joint name="left_back_wheel_joint">
      <hardwareInterface>hardware_interface/EffortJointInterface</hardwareInterface>
    </joint>
  </transmission>
  <transmission name="right_back_pivot_trans">
    <type>transmission_interface/SimpleTransmission</type>
    <actuator name="right_back_pivot_motor">
      <mechanicalReduction>-1</mechanicalReduction>
    </actuator>
    <joint name="right_back_pivot_joint">
      <offset>0.80697</offset>
      <hardwareInterface>hardware_interface/EffortJointInterface</hardwareInterface>
    </joint>
  </transmission>
  <transmission name="right_back_wheel_trans">
    <type>transmission_interface/SimpleTransmission</type>
    <actuator name="right_back_wheel_motor">
      <mechanicalReduction>13</mechanicalReduction>
    </actuator>
    <joint name="right_back_wheel_joint">
      <hardwareInterface>hardware_interface/EffortJointInterface</hardwareInterface>
    </joint>
  </transmission>
  <!--  link  -->
  <link name="link1">
    <inertial>
      <mass value="3.266699"/>
      <origin xyz="0.044552 -0.00278 -0.024231"/>
      <inertia ixx="9.871e-2" ixy="4.488e-4" ixz="4.363e-3" iyy="1.028e-1" iyz="-1.680e-4" izz="1.941e-1"/>
    </inertial>
    <visual>
      <origin rpy="0 0 0" xyz="0 0 0"/>
      <geometry>
        <mesh filename="package://rm_description/meshes/engineer/link1.stl" scale="0.001 0.001 0.001"/>
      </geometry>
    </visual>
    <collision>
      <origin rpy="0 0 0" xyz="0 0 0"/>
      <geometry>
        <mesh filename="package://rm_description/meshes/engineer/link1_collision.stl" scale="0.001 0.001 0.001"/>
      </geometry>
    </collision>
    <selfCollide>true</selfCollide>
  </link>
  <link name="link2_1">
    <inertial>
      <mass value="3.952737"/>
      <origin xyz="-0.053803 0.000205 -0.026272"/>
      <inertia ixx="1.397e-1" ixy="3.8918305e-5" ixz="5.212e-3" iyy="1.367e-1" iyz="4.7399093e-5" izz="2.691e-1"/>
    </inertial>
    <visual>
      <origin rpy="0 0 0" xyz="0 0 0"/>
      <geometry>
        <mesh filename="package://rm_description/meshes/engineer/link2_1.stl" scale="0.001 0.001 0.001"/>
      </geometry>
    </visual>
    <collision>
      <origin rpy="0 0 0" xyz="0 0 0"/>
      <geometry>
        <mesh filename="package://rm_description/meshes/engineer/link2_1_collision.stl" scale="0.001 0.001 0.001"/>
      </geometry>
    </collision>
    <collision>
      <origin rpy="0 0 0" xyz="0.29 0.175 -0.025"/>
      <geometry>
        <box size="0.08 0.12 0.1"/>
      </geometry>
    </collision>
    <collision>
      <origin rpy="0 0 0" xyz="0.29 -0.175 -0.025"/>
      <geometry>
        <box size="0.08 0.12 0.1"/>
      </geometry>
    </collision>
    <selfCollide>true</selfCollide>
  </link>
  <link name="link2_2">
    <inertial>
      <mass value="1.355869"/>
      <origin xyz="-0.016479 0.004436 0.022901"/>
      <inertia ixx="9.431e-3" ixy="4.159e-4" ixz="6.466e-4" iyy="4.159e-4" iyz="-6.0491299e-5" izz="9.448e-3"/>
    </inertial>
    <visual>
      <geometry>
        <mesh filename="package://rm_description/meshes/engineer/link2_2.stl" scale="0.001 0.001 0.001"/>
      </geometry>
      <origin rpy="0 0 0" xyz="0 0 0"/>
    </visual>
    <collision>
      <origin rpy="0 0 0" xyz="0 0 0"/>
      <geometry>
        <mesh filename="package://rm_description/meshes/engineer/link2_2_collision.stl" scale="0.001 0.001 0.001"/>
      </geometry>
    </collision>
    <selfCollide>true</selfCollide>
  </link>
  <link name="link3">
    <inertial>
      <mass value="1.790039"/>
      <origin xyz="-0.004447 -0.100499 0.025621"/>
      <inertia ixx="3.962e-2" ixy="9.235e-4" ixz="2.985e-4" iyy="5.451e-3" iyz="-8.484e-3" izz="3.837e-2"/>
    </inertial>
    <visual>
      <origin rpy="0 0 0" xyz="0 0 0"/>
      <geometry>
        <mesh filename="package://rm_description/meshes/engineer/link3.stl" scale="0.001 0.001 0.001"/>
      </geometry>
    </visual>
    <collision>
      <origin rpy="0 0 0" xyz="0 0 0"/>
      <geometry>
        <mesh filename="package://rm_description/meshes/engineer/link3_collision.stl" scale="0.001 0.001 0.001"/>
      </geometry>
    </collision>
    <selfCollide>true</selfCollide>
  </link>
  <link name="link4">
    <inertial>
      <mass value="0.597915"/>
      <origin xyz="0.0033 -0.051861 0.000004"/>
      <inertia ixx="3.027e-3" ixy="-6.403167e-6" ixz="2.37196e-7" iyy="2.774e-4" iyz="-7.08963e-7" izz="3.084e-3"/>
    </inertial>
    <visual>
      <origin rpy="0 0 0" xyz="0 0 0"/>
      <geometry>
        <mesh filename="package://rm_description/meshes/engineer/link4.stl" scale="0.001 0.001 0.001"/>
      </geometry>
    </visual>
    <selfCollide>true</selfCollide>
  </link>
  <link name="link5">
    <inertial>
      <mass value="0.690989"/>
      <origin xyz="-0.019826 0.000116 0.034079"/>
      <inertia ixx="3.66e-3" ixy="3.03464e-7" ixz="1.075e-4" iyy="4.425e-3" iyz="-1.1195657e-5" izz="9.656e-4"/>
    </inertial>
    <visual>
      <origin rpy="0 0 0" xyz="0 0 0"/>
      <geometry>
        <mesh filename="package://rm_description/meshes/engineer/link5.stl" scale="0.001 0.001 0.001"/>
      </geometry>
    </visual>
    <collision>
      <origin rpy="0 0 0" xyz="0 0 0"/>
      <geometry>
        <mesh filename="package://rm_description/meshes/engineer/link5_collision.stl" scale="0.001 0.001 0.001"/>
      </geometry>
    </collision>
    <selfCollide>true</selfCollide>
  </link>
  <link name="link6">
    <inertial>
      <mass value="0.771338"/>
      <origin xyz="0.04148 -0.000028 -0.028949"/>
      <inertia ixx="2.206e-3" ixy="-3.0455e-8" ixz="-1.041e-4" iyy="4.988e-3" iyz="-4.58505e-7" izz="3.998e-3"/>
    </inertial>
    <visual>
      <origin rpy="0 0 0" xyz="0 0 0"/>
      <geometry>
        <mesh filename="package://rm_description/meshes/engineer/link6.stl" scale="0.001 0.001 0.001"/>
      </geometry>
    </visual>
    <collision>
      <origin rpy="0 0 0" xyz="0 0 0"/>
      <geometry>
        <mesh filename="package://rm_description/meshes/engineer/link6_collision.stl" scale="0.001 0.001 0.001"/>
      </geometry>
    </collision>
    <selfCollide>true</selfCollide>
  </link>
  <joint name="joint1" type="prismatic">
    <parent link="base_link"/>
    <child link="link1"/>
    <origin rpy="0 0 0" xyz="0 0 0.233"/>
    <axis xyz="0 0 1"/>
    <limit effort="609.75" lower="0" upper="0.24" velocity="1.2"/>
    <safety_controller k_position="6000." k_velocity="200." soft_lower_limit="0.0001" soft_upper_limit="0.2399"/>
    <dynamics damping="0.0" friction="0.1"/>
  </joint>
  <joint name="joint2" type="prismatic">
    <parent link="link1"/>
    <child link="link2_1"/>
    <origin rpy="0 0 0" xyz="-0.014 0. 0.0542"/>
    <axis xyz="1 0 0"/>
    <limit effort="110.0" lower="-0.35" upper="0.33" velocity="1.9"/>
    <safety_controller k_position="50000." k_velocity="600." soft_lower_limit="-0.347" soft_upper_limit="0.327"/>
    <dynamics damping="0.0" friction="0.1"/>
  </joint>
  <joint name="joint3" type="prismatic">
    <parent link="link2_1"/>
    <child link="link2_2"/>
    <origin rpy="0 0 0" xyz="-0.11 0. 0.013"/>
    <axis xyz="1 0 0"/>
    <limit effort="258.0" lower="-0.12" upper="0.31" velocity="0.964"/>
    <safety_controller k_position="80000." k_velocity="1000." soft_lower_limit="-0.119" soft_upper_limit="0.309"/>
    <dynamics damping="0.0" friction="0.1"/>
  </joint>
  <joint name="joint4" type="prismatic">
    <parent link="link2_2"/>
    <child link="link3"/>
    <origin rpy="0 0 0" xyz="0. 0. 0.078"/>
    <axis xyz="0 1 0"/>
    <limit effort="85.47" lower="-0.31" upper="0.31" velocity="2.92"/>
    <safety_controller k_position="8000." k_velocity="400." soft_lower_limit="-0.305" soft_upper_limit="0.305"/>
    <dynamics damping="0.0" friction="0.1"/>
  </joint>
  <joint name="joint5" type="revolute">
    <parent link="link3"/>
    <child link="link4"/>
    <origin rpy="0 0 0" xyz="0. 0. 0.06"/>
    <axis xyz="0 1 0"/>
    <limit effort="13.3" lower="0" upper="3.8445" velocity="18.8"/>
    <safety_controller k_position="300." k_velocity="3." soft_lower_limit="0.05" soft_upper_limit="3.7945"/>
    <dynamics damping="0.0" friction="0.1"/>
  </joint>
  <joint name="joint6" type="revolute">
    <parent link="link4"/>
    <child link="link5"/>
    <origin rpy="0 0 0" xyz="-0.06 0. 0."/>
    <axis xyz="1 0 0"/>
    <limit effort="13.3" lower="-0.9" upper="0.9" velocity="18.8"/>
    <safety_controller k_position="100." k_velocity="3." soft_lower_limit="-0.89" soft_upper_limit="0.89"/>
    <dynamics damping="0.0" friction="0.1"/>
  </joint>
  <joint name="joint7" type="revolute">
    <parent link="link5"/>
    <child link="link6"/>
    <origin rpy="0 0 0" xyz="0.06 0 0.253"/>
    <axis xyz="0 0 1"/>
    <limit effort="5" lower="-1.3" upper="4.5" velocity="50"/>
    <safety_controller k_position="50." k_velocity="0.6" soft_lower_limit="-1.1" soft_upper_limit="4.3"/>
    <dynamics damping="0.0" friction="0.1"/>
  </joint>
  <!-- transmission -->
  <transmission name="trans_joint1">
    <type>transmission_interface/SimpleTransmission</type>
    <actuator name="joint1_motor">
      <mechanicalReduction>2341.046</mechanicalReduction>
    </actuator>
    <joint name="joint1">
      <hardwareInterface>hardware_interface/EffortJointInterface</hardwareInterface>
      <offset>-0.0009</offset>
    </joint>
  </transmission>
  <transmission name="trans_joint2">
    <type>transmission_interface/SimpleTransmission</type>
    <actuator name="joint2_motor">
      <mechanicalReduction>-497.500437</mechanicalReduction>
    </actuator>
    <joint name="joint2">
      <hardwareInterface>hardware_interface/EffortJointInterface</hardwareInterface>
      <offset>-0.3503654</offset>
    </joint>
  </transmission>
  <transmission name="trans_joint3">
    <type>transmission_interface/SimpleTransmission</type>
    <actuator name="joint3_motor">
      <mechanicalReduction>995.000875</mechanicalReduction>
    </actuator>
    <joint name="joint3">
      <hardwareInterface>hardware_interface/EffortJointInterface</hardwareInterface>
      <offset>-0.1189088</offset>
    </joint>
  </transmission>
  <transmission name="trans_joint4">
    <type>transmission_interface/SimpleTransmission</type>
    <actuator name="joint4_motor">
      <mechanicalReduction>-328.093719</mechanicalReduction>
    </actuator>
    <joint name="joint4">
      <hardwareInterface>hardware_interface/EffortJointInterface</hardwareInterface>
      <offset>0</offset>
    </joint>
  </transmission>
  <transmission name="trans_joint5">
    <type>transmission_interface/SimpleTransmission</type>
    <actuator name="joint5_motor">
      <mechanicalReduction>-50.895</mechanicalReduction>
    </actuator>
    <joint name="joint5">
      <hardwareInterface>hardware_interface/EffortJointInterface</hardwareInterface>
      <offset>-0.21614</offset>
    </joint>
  </transmission>
  <transmission name="trans_joint6">
    <type>transmission_interface/SimpleTransmission</type>
    <actuator name="joint6_motor">
      <mechanicalReduction>-50.895</mechanicalReduction>
    </actuator>
    <joint name="joint6">
      <hardwareInterface>hardware_interface/EffortJointInterface</hardwareInterface>
      <offset>-0.8457765</offset>
    </joint>
  </transmission>
  <transmission name="trans_joint7">
    <type>transmission_interface/SimpleTransmission</type>
    <actuator name="joint7_motor">
      <mechanicalReduction>19.2032</mechanicalReduction>
    </actuator>
    <joint name="joint7">
      <hardwareInterface>hardware_interface/EffortJointInterface</hardwareInterface>
      <offset>-1.34528</offset>
    </joint>
  </transmission>
  <link name="gimbal_base">
    <inertial>
      <mass value="0.163485"/>
      <origin xyz="0.000652 0.002177 0.009113"/>
      <inertia ixx="7.4761869e-5" ixy="-1.177056e-6" ixz="-2.348598e-6" iyy="7.440176e-5" iyz="6.29861e-6" izz="6.3915e-5"/>
    </inertial>
    <visual>
      <origin rpy="0 0 0" xyz="0 0 0"/>
      <geometry>
        <mesh filename="package://rm_description/meshes/engineer/gimbal_base.stl" scale="0.001 0.001 0.001"/>
      </geometry>
    </visual>
    <collision>
      <origin rpy="0 0 0" xyz="0 0 0"/>
      <geometry>
        <mesh filename="package://rm_description/meshes/engineer/gimbal_collision.stl" scale="0.001 0.001 0.001"/>
      </geometry>
    </collision>
  </link>
  <link name="yaw">
    <inertial>
      <mass value="0.074489"/>
      <origin xyz="0.000003 -0.001925 0.013798"/>
      <inertia ixx="1.672e-4" ixy="-0.42e-9" ixz="1.5288e-8" iyy="5.1826669e-5" iyz="-5.33194e-7" izz="1.439e-4"/>
    </inertial>
    <visual>
      <origin rpy="0 0 0" xyz="0 0 0"/>
      <geometry>
        <mesh filename="package://rm_description/meshes/engineer/yaw.stl" scale="0.001 0.001 0.001"/>
      </geometry>
    </visual>
  </link>
  <link name="pitch">
    <inertial>
      <mass value="0.28963"/>
      <origin xyz="0.001291 0.005233 0.001395"/>
      <inertia ixx="2.976e-4" ixy="5.294138e-6" ixz="-5.514329e-6" iyy="1.889e-4" iyz="3.085924e-6" izz="4.132e-4"/>
    </inertial>
    <visual>
      <origin rpy="0 0 0" xyz="0 0 0"/>
      <geometry>
        <mesh filename="package://rm_description/meshes/engineer/pitch.stl" scale="0.001 0.001 0.001"/>
      </geometry>
    </visual>
  </link>
  <joint name="gimbal_base_joint" type="fixed">
    <origin rpy="0 0 0" xyz="0 -0.148333 0.039"/>
    <parent link="link3"/>
    <child link="gimbal_base"/>
  </joint>
  <joint name="yaw_joint" type="revolute">
    <origin rpy="0 0 0" xyz="0 0 0.03"/>
    <dynamics damping="0.0" friction="0.1"/>
    <limit effort="1.2" lower="-4.235" upper="0.48" velocity="13.82"/>
    <safety_controller k_position="100" k_velocity="0.1" soft_lower_limit="-4.205" soft_upper_limit="0.44999999999999996"/>
    <parent link="gimbal_base"/>
    <child link="yaw"/>
    <axis xyz="0 0 1"/>
  </joint>
  <joint name="pitch_joint" type="revolute">
    <origin rpy="0 0 0" xyz="0.  0. 0.056 "/>
    <dynamics damping="0.0" friction="0.1"/>
    <limit effort="1.2" lower="-1.07" upper="0.76" velocity="13.82"/>
    <safety_controller k_position="100" k_velocity="0.1" soft_lower_limit="-1.04" soft_upper_limit="0.73"/>
    <parent link="yaw"/>
    <child link="pitch"/>
    <axis xyz="0 1 0 "/>
  </joint>
  <transmission name="trans_yaw_joint">
    <type>transmission_interface/SimpleTransmission</type>
    <actuator name="yaw_joint_motor">
      <mechanicalReduction>-1</mechanicalReduction>
    </actuator>
    <joint name="yaw_joint">
      <offset>0.467</offset>
      <hardwareInterface>hardware_interface/EffortJointInterface</hardwareInterface>
    </joint>
  </transmission>
  <transmission name="trans_pitch_joint">
    <type>transmission_interface/SimpleTransmission</type>
    <actuator name="pitch_joint_motor">
      <mechanicalReduction>1</mechanicalReduction>
    </actuator>
    <joint name="pitch_joint">
      <offset>0.74321</offset>
      <hardwareInterface>hardware_interface/EffortJointInterface</hardwareInterface>
    </joint>
  </transmission>
  <gazebo>
    <plugin filename="librm_robot_hw_sim.so" name="rm_ros_control">
      <robotNamespace>/</robotNamespace>
      <robotSimType>rm_gazebo/RmRobotHWSim</robotSimType>
    </plugin>
  </gazebo>
</robot>
