<?xml version="1.0" ?>
<!-- =================================================================================== -->
<!-- |    This document was autogenerated by xacro from ../rm_description/urdf/engineer/engineer.urdf.xacro | -->
<!-- |    EDITING THIS FILE BY HAND IS NOT RECOMMENDED                                 | -->
<!-- =================================================================================== -->
<robot name="engineer">
  <link name="base_link">
    <inertial>
      <mass value="28.19"/>
      <origin xyz="-0.0206 -0.00126 -0.0164"/>
      <inertia ixx="1.32e+0" ixy="-8.378e-2" ixz="6.28e-2" iyy=" 1.549e+0" iyz="5.948e-2" izz="2.024e+0"/>
    </inertial>
    <visual>
      <origin rpy="0 0 0" xyz="0 0 0"/>
      <geometry>
        <mesh filename="package://rm_description/meshes/engineer/base.stl" scale="0.001 .001 0.001"/>
      </geometry>
    </visual>
    <collision>
      <origin rpy="0 0 0" xyz="0 0 0"/>
      <geometry>
        <box size="0.5845 0.526 0.2"/>
      </geometry>
    </collision>
    <!--            <collision>
                            <origin xyz="-0.033 -0.1 0.267" rpy="0 0 0.7853982"/>
                            <geometry>
                                <box size="0.0207 0.0207 0.334"/>
                            </geometry>
                        </collision>
                        <collision>
                            <origin xyz="-0.033 0.10 0.267" rpy="0 0 0.7853982"/>
                            <geometry>
                                <box size="0.0207 0.0207 0.334"/>
                            </geometry>
                        </collision>-->
    <collision>
      <origin rpy="0 0 0.7853982" xyz="-0.23225 -0.1 0.267"/>
      <geometry>
        <box size="0.0207 0.0207 0.334"/>
      </geometry>
    </collision>
    <collision>
      <origin rpy="0 0 0.7853982" xyz="-0.23225 0.1 0.267"/>
      <geometry>
        <box size="0.0207 0.0207 0.334"/>
      </geometry>
    </collision>
    <collision>
      <origin rpy="0 0 0" xyz="-0.193 -0.189 0.235"/>
      <geometry>
        <box size="0.186 0.1 0.3"/>
      </geometry>
    </collision>
    <collision>
      <origin rpy="0 0 0" xyz="-0.0623 -0.2405 0.242"/>
      <geometry>
        <box size="0.08 0.003 0.06"/>
      </geometry>
    </collision>
  </link>
  <!--  link  -->
  <link name="front_left_wheel">
    <visual>
      <geometry>
        <mesh filename="package://rm_description/meshes/common/right_threaded_mecanum_wheel.stl" scale="0.001 0.001 0.001"/>
      </geometry>
    </visual>
    <inertial>
      <mass value="0.59"/>
      <inertia ixx="1.416e-3" ixy="0.0" ixz="0.0" iyy="2.749e-3" iyz="0.0" izz="1.416e-3"/>
    </inertial>
  </link>
  <!--  joint  -->
  <joint name="front_left_wheel_joint" type="revolute">
    <axis xyz="0 1 0"/>
    <origin rpy="0 0 0" xyz="0.19 0.21 -0.109"/>
    <!--      limit not work while type="continuous"-->
    <limit effort="5" lower="-1e16" upper="1e16" velocity="50"/>
    <dynamics damping="0.0" friction="0.05"/>
    <parent link="base_link"/>
    <child link="front_left_wheel"/>
  </joint>
  <!--  link  -->
  <link name="front_right_wheel">
    <visual>
      <geometry>
        <mesh filename="package://rm_description/meshes/common/left_threaded_mecanum_wheel.stl" scale="0.001 0.001 0.001"/>
      </geometry>
    </visual>
    <inertial>
      <mass value="0.59"/>
      <inertia ixx="1.416e-3" ixy="0.0" ixz="0.0" iyy="2.749e-3" iyz="0.0" izz="1.416e-3"/>
    </inertial>
  </link>
  <!--  joint  -->
  <joint name="front_right_wheel_joint" type="revolute">
    <axis xyz="0 1 0"/>
    <origin rpy="0 0 0" xyz="0.19 -0.21 -0.109"/>
    <!--      limit not work while type="continuous"-->
    <limit effort="5" lower="-1e16" upper="1e16" velocity="50"/>
    <dynamics damping="0.0" friction="0.05"/>
    <parent link="base_link"/>
    <child link="front_right_wheel"/>
  </joint>
  <!--  link  -->
  <link name="back_left_wheel">
    <visual>
      <geometry>
        <mesh filename="package://rm_description/meshes/common/left_threaded_mecanum_wheel.stl" scale="0.001 0.001 0.001"/>
      </geometry>
    </visual>
    <inertial>
      <mass value="0.59"/>
      <inertia ixx="1.416e-3" ixy="0.0" ixz="0.0" iyy="2.749e-3" iyz="0.0" izz="1.416e-3"/>
    </inertial>
  </link>
  <!--  joint  -->
  <joint name="back_left_wheel_joint" type="revolute">
    <axis xyz="0 1 0"/>
    <origin rpy="0 0 0" xyz="-0.19 0.21 -0.109"/>
    <!--      limit not work while type="continuous"-->
    <limit effort="5" lower="-1e16" upper="1e16" velocity="50"/>
    <dynamics damping="0.0" friction="0.05"/>
    <parent link="base_link"/>
    <child link="back_left_wheel"/>
  </joint>
  <!--  link  -->
  <link name="back_right_wheel">
    <visual>
      <geometry>
        <mesh filename="package://rm_description/meshes/common/right_threaded_mecanum_wheel.stl" scale="0.001 0.001 0.001"/>
      </geometry>
    </visual>
    <inertial>
      <mass value="0.59"/>
      <inertia ixx="1.416e-3" ixy="0.0" ixz="0.0" iyy="2.749e-3" iyz="0.0" izz="1.416e-3"/>
    </inertial>
  </link>
  <!--  joint  -->
  <joint name="back_right_wheel_joint" type="revolute">
    <axis xyz="0 1 0"/>
    <origin rpy="0 0 0" xyz="-0.19 -0.21 -0.109"/>
    <!--      limit not work while type="continuous"-->
    <limit effort="5" lower="-1e16" upper="1e16" velocity="50"/>
    <dynamics damping="0.0" friction="0.05"/>
    <parent link="base_link"/>
    <child link="back_right_wheel"/>
  </joint>
  <transmission name="front_left_wheel_trans">
    <type>transmission_interface/SimpleTransmission</type>
    <actuator name="front_left_wheel_motor">
      <hardwareInterface>hardware_interface/EffortJointInterface</hardwareInterface>
      <mechanicalReduction>1</mechanicalReduction>
    </actuator>
    <joint name="front_left_wheel_joint">
      <hardwareInterface>hardware_interface/EffortJointInterface</hardwareInterface>
    </joint>
  </transmission>
  <transmission name="front_right_wheel_trans">
    <type>transmission_interface/SimpleTransmission</type>
    <actuator name="front_right_wheel_motor">
      <hardwareInterface>hardware_interface/EffortJointInterface</hardwareInterface>
      <mechanicalReduction>-1</mechanicalReduction>
    </actuator>
    <joint name="front_right_wheel_joint">
      <hardwareInterface>hardware_interface/EffortJointInterface</hardwareInterface>
    </joint>
  </transmission>
  <transmission name="back_left_wheel_trans">
    <type>transmission_interface/SimpleTransmission</type>
    <actuator name="back_left_wheel_motor">
      <hardwareInterface>hardware_interface/EffortJointInterface</hardwareInterface>
      <mechanicalReduction>1</mechanicalReduction>
    </actuator>
    <joint name="back_left_wheel_joint">
      <hardwareInterface>hardware_interface/EffortJointInterface</hardwareInterface>
    </joint>
  </transmission>
  <transmission name="back_right_wheel_trans">
    <type>transmission_interface/SimpleTransmission</type>
    <actuator name="back_right_wheel_motor">
      <hardwareInterface>hardware_interface/EffortJointInterface</hardwareInterface>
      <mechanicalReduction>-1</mechanicalReduction>
    </actuator>
    <joint name="back_right_wheel_joint">
      <hardwareInterface>hardware_interface/EffortJointInterface</hardwareInterface>
    </joint>
  </transmission>
  <!--  link  -->
  <link name="link1">
    <inertial>
      <mass value="1.7056"/>
      <origin xyz="0.004 0 0.0571"/>
      <inertia ixx="1.542e-2" ixy="0" ixz="-1.332e-3" iyy="1.028e-2" iyz="0" izz="1.017e-2"/>
    </inertial>
    <visual>
      <origin rpy="0 0 0" xyz="0 0 0"/>
      <geometry>
        <mesh filename="package://rm_description/meshes/engineer/link1.stl" scale="0.001 0.001 0.001"/>
      </geometry>
    </visual>
    <collision>
      <origin rpy="0 0 0" xyz="-0.045 0 0.035"/>
      <geometry>
        <box size="0.15 0.106 0.07"/>
      </geometry>
    </collision>
    <collision>
      <origin rpy="0 -0.95993 0" xyz="0.040 0 0.1"/>
      <geometry>
        <box size="0.17 0.106 0.095"/>
      </geometry>
    </collision>
    <collision>
      <origin rpy="1.5707963 0 0" xyz="0 0 0.05"/>
      <geometry>
        <cylinder length="0.188" radius="0.047"/>
      </geometry>
    </collision>
  </link>
  <link name="link2">
    <inertial>
      <mass value="1.4763"/>
      <origin xyz="0.05652 0 0"/>
      <inertia ixx="1.976e-3" ixy="5.791e-5" ixz="-2.47366e-7" iyy="8.418e-3" iyz="1.0e-7" izz="8.946e-3"/>
    </inertial>
    <visual>
      <origin rpy="0 0 0" xyz="0 0 0"/>
      <geometry>
        <mesh filename="package://rm_description/meshes/engineer/link2.stl" scale="0.001 0.001 0.001"/>
      </geometry>
    </visual>
    <collision>
      <origin xyz="0.062 0 0"/>
      <geometry>
        <box size="0.225 0.096 0.070"/>
      </geometry>
    </collision>
  </link>
  <link name="link3">
    <inertial>
      <mass value="0.5946"/>
      <origin xyz="0.0471 -0.0094 0.0003"/>
      <inertia ixx="6.49e-4" ixy="5.036e-5" ixz="-2.372e-5" iyy="2.739e-3" iyz="1.795e-6" izz="3.077e-3"/>
    </inertial>
    <visual>
      <origin rpy="0 0 0" xyz="0 0 0"/>
      <geometry>
        <mesh filename="package://rm_description/meshes/engineer/link3.stl" scale="0.001 0.001 0.001"/>
      </geometry>
    </visual>
    <collision>
      <origin xyz="0.063 0 0"/>
      <geometry>
        <box size="0.191 0.084 0.053"/>
      </geometry>
    </collision>
    <collision>
      <origin rpy="1.5707963 0 0" xyz="0 0 0"/>
      <geometry>
        <cylinder length="0.082" radius="0.047"/>
      </geometry>
    </collision>
  </link>
  <link name="link4">
    <inertial>
      <mass value="0.361"/>
      <origin xyz="0 0 0"/>
      <inertia ixx="2.593e-4" ixy="5.907e-3" ixz="2.629e-2" iyy="8.662e-5" iyz="0." izz="2.589e-4"/>
    </inertial>
    <visual>
      <origin rpy="0 0 0" xyz="0 0 0"/>
      <geometry>
        <mesh filename="package://rm_description/meshes/engineer/link4.stl" scale="0.001 0.001 0.001"/>
      </geometry>
    </visual>
    <collision>
      <origin rpy="0 0 0" xyz="0 0 0"/>
      <geometry>
        <box size="0.0513 0.074 0.0513"/>
      </geometry>
    </collision>
  </link>
  <link name="link5">
    <inertial>
      <mass value="0.249"/>
      <origin xyz="0.02737 0.0 0.0"/>
      <inertia ixx="6.090e-5" ixy="7.70024e-7" ixz="7.35489e-7" iyy="2.293e-4" iyz="0." izz=" 2.293e-4"/>
    </inertial>
    <visual>
      <origin rpy="0 0 0" xyz="0 0 0"/>
      <geometry>
        <mesh filename="package://rm_description/meshes/engineer/link5.stl" scale="0.001 0.001 0.001"/>
      </geometry>
    </visual>
    <collision>
      <origin rpy="0 0 0" xyz="0.015 0 0"/>
      <geometry>
        <box size="0.056 0.0513 0.0513"/>
      </geometry>
    </collision>
  </link>
  <!--  joint  -->
  <joint name="joint1" type="revolute">
    <axis xyz="0 0 1"/>
    <origin xyz="0.133 0 0.1"/>
    <!--      limit not work while type="continuous"-->
    <limit effort="20" lower="-3.141592653589793" upper="3.141592653589793" velocity="25"/>
    <dynamics damping="0.0" friction="0.1"/>
    <parent link="base_link"/>
    <child link="link1"/>
  </joint>
  <joint name="joint2" type="revolute">
    <axis xyz="0 1 0"/>
    <origin xyz="0.05909 0 0.1280"/>
    <limit effort="30" lower="-2.231" upper="0.407" velocity="10"/>
    <dynamics damping="0.0" friction="0.8"/>
    <parent link="link1"/>
    <child link="link2"/>
  </joint>
  <joint name="joint3" type="revolute">
    <axis xyz="0 1 0"/>
    <origin xyz="0.16 0 0"/>
    <limit effort="30" lower="-2.1645" upper="2.4078" velocity="10"/>
    <dynamics damping="0.0" friction="0.5"/>
    <parent link="link2"/>
    <child link="link3"/>
  </joint>
  <joint name="joint4" type="revolute">
    <axis xyz="0 1 0"/>
    <origin xyz="0.145 0 0"/>
    <limit effort="1.2" lower="-1.7278759594743864" upper="1.7278759594743864" velocity="34"/>
    <dynamics damping="0.0" friction="0.05"/>
    <parent link="link3"/>
    <child link="link4"/>
  </joint>
  <joint name="joint5" type="revolute">
    <axis xyz="1 0 0"/>
    <origin xyz="0 0 0"/>
    <limit effort="1.2" lower="-6.283185307179586" upper="6.283185307179586" velocity="34"/>
    <dynamics damping="0.0" friction="0.05"/>
    <parent link="link4"/>
    <child link="link5"/>
  </joint>
  <!-- transmission -->
  <transmission name="trans_joint1">
    <type>transmission_interface/SimpleTransmission</type>
    <actuator name="joint1_motor">
      <mechanicalReduction>4</mechanicalReduction>
    </actuator>
    <joint name="joint1">
      <hardwareInterface>hardware_interface/EffortJointInterface</hardwareInterface>
      <offset>-0.0148</offset>
    </joint>
  </transmission>
  <transmission name="trans_joint3">
    <type>transmission_interface/SimpleTransmission</type>
    <actuator name="joint3_motor">
      <mechanicalReduction>3</mechanicalReduction>
    </actuator>
    <joint name="joint3">
      <hardwareInterface>hardware_interface/EffortJointInterface</hardwareInterface>
      <offset>2.2875</offset>
    </joint>
  </transmission>
  <transmission name="trans_joint2">
    <type>transmission_interface/SimpleTransmission</type>
    <actuator name="joint2_motor">
      <mechanicalReduction>-3</mechanicalReduction>
    </actuator>
    <joint name="joint2">
      <hardwareInterface>hardware_interface/EffortJointInterface</hardwareInterface>
      <offset>0</offset>
    </joint>
  </transmission>
  <transmission name="trans_joint4">
    <type>transmission_interface/SimpleTransmission</type>
    <actuator name="joint4_motor">
      <hardwareInterface>hardware_interface/EffortJointInterface</hardwareInterface>
      <mechanicalReduction>1</mechanicalReduction>
    </actuator>
    <joint name="joint4">
      <hardwareInterface>hardware_interface/EffortJointInterface</hardwareInterface>
    </joint>
  </transmission>
  <transmission name="trans_joint5">
    <type>transmission_interface/SimpleTransmission</type>
    <actuator name="joint5_motor">
      <hardwareInterface>hardware_interface/EffortJointInterface</hardwareInterface>
      <mechanicalReduction>1</mechanicalReduction>
    </actuator>
    <joint name="joint5">
      <hardwareInterface>hardware_interface/EffortJointInterface</hardwareInterface>
    </joint>
  </transmission>
  <link name="palm">
    <inertial>
      <origin rpy="0 0 0" xyz="0.01877 0.0475 -0.000028"/>
      <mass value="0.406611"/>
      <inertia ixx="2.719e-3" ixy="-3.243e-4" ixz="228.248e-9" iyy="2.564e-4" iyz="1515.727e-9" izz="2.9e-3"/>
    </inertial>
    <visual>
      <geometry>
        <mesh filename="package://rm_description/meshes/engineer/palm.stl" scale="0.001 0.001 0.001"/>
      </geometry>
    </visual>
    <collision>
      <origin rpy="0 0 0" xyz="0.0225 0.0 0"/>
      <geometry>
        <box size="0.045 0.2658 0.0675"/>
      </geometry>
    </collision>
  </link>
  <link name="right_finger">
    <inertial>
      <origin rpy="0 0 0" xyz="0.01491 -0.06058 0"/>
      <mass value="0.203967"/>
      <inertia ixx="1.025e-3" ixy="3.865e-4" ixz="-1.144e-9" iyy="3.051e-4" iyz="4.649e-9" izz="1.295e-3"/>
    </inertial>
    <visual>
      <geometry>
        <mesh filename="package://rm_description/meshes/engineer/right_finger.stl" scale="0.001 0.001 0.001"/>
      </geometry>
    </visual>
    <collision>
      <origin rpy="0 0 0" xyz="0.011 -0.04 0"/>
      <geometry>
        <box size="0.048 0.026 0.030"/>
      </geometry>
    </collision>
    <collision>
      <origin rpy="0 0 0" xyz="0.0235 -0.0832 0"/>
      <geometry>
        <box size="0.022 0.1123 0.03"/>
      </geometry>
    </collision>
    <collision>
      <origin rpy="0 0 0" xyz="0.069 -0.13 0"/>
      <geometry>
        <box size="0.112 0.0157 0.03"/>
      </geometry>
    </collision>
    <collision>
      <origin rpy="0 0 0" xyz="0.105 -0.1232 0"/>
      <geometry>
        <box size="0.04 0.0323 0.03"/>
      </geometry>
    </collision>
  </link>
  <link name="left_finger">
    <inertial>
      <origin rpy="0 0 0" xyz="0.01491 0.061581 0"/>
      <mass value="0.203967"/>
      <inertia ixx="1.053e-3" ixy="-3.865e-4" ixz="-1.144e-9" iyy="3.051e-4" iyz="-4.733e-9" izz="1.323e-3"/>
    </inertial>
    <visual>
      <geometry>
        <mesh filename="package://rm_description/meshes/engineer/left_finger.stl" scale="0.001 0.001 0.001"/>
      </geometry>
    </visual>
    <collision>
      <origin rpy="0 0 0" xyz="0.011 0.04 0"/>
      <geometry>
        <box size="0.048 0.026 0.030"/>
      </geometry>
    </collision>
    <collision>
      <origin rpy="0 0 0" xyz="0.0235 0.0832 0"/>
      <geometry>
        <box size="0.022 0.1123 0.03"/>
      </geometry>
    </collision>
    <collision>
      <origin rpy="0 0 0" xyz="0.069 0.13 0"/>
      <geometry>
        <box size="0.112 0.0157 0.03"/>
      </geometry>
    </collision>
    <collision>
      <origin rpy="0 0 0" xyz="0.105 0.1232 0"/>
      <geometry>
        <box size="0.04 0.0323 0.03"/>
      </geometry>
    </collision>
  </link>
  <link name="camera">
    <inertial>
      <mass value="0.04"/>
      <origin xyz="0 0 0"/>
      <inertia ixx="0.01" ixy="0.0" ixz="0.0" iyy="0.01" iyz="0.0" izz="0.01"/>
    </inertial>
    <visual>
      <origin rpy="0 0 0" xyz=" 0 0 0 "/>
      <geometry>
        <box size="0.022 0.021 0.0226"/>
      </geometry>
      <material name="Black"/>
    </visual>
    <collision>
      <origin rpy="0 0 0" xyz="0.0 0.0 0.0"/>
      <geometry>
        <box size="0.01 0.04 0.04"/>
      </geometry>
    </collision>
  </link>
  <!--        <gazebo reference="camera">-->
  <!--            <masterial>Gazebo/White</masterial>-->
  <!--        </gazebo>-->
  <joint name="camera_joint" type="fixed">
    <parent link="palm"/>
    <child link="camera"/>
    <origin rpy="0 0 0" xyz="0.055 -0.085 0.0962"/>
    <axis xyz="0 1 0"/>
  </joint>
  <joint name="palm_joint" type="fixed">
    <parent link="link5"/>
    <child link="palm"/>
    <origin rpy="0 0 0" xyz="0.039 0 0"/>
  </joint>
  <joint name="right_finger_joint" type="prismatic">
    <parent link="palm"/>
    <child link="right_finger"/>
    <origin rpy="0 0 0" xyz="0.032 0 0"/>
    <axis xyz="0 1 0"/>
    <limit effort="588" lower="0.0" upper="0.02" velocity="3.772"/>
  </joint>
  <joint name="left_finger_joint" type="prismatic">
    <parent link="palm"/>
    <child link="left_finger"/>
    <origin rpy="0 0 0" xyz="0.032 0 0"/>
    <axis xyz="0 -1 0"/>
    <limit effort="588" lower="0.0" upper="0.02" velocity="3.772"/>
    <mimic joint="right_finger_joint"/>
  </joint>
  <transmission name="trans_right_finger_joint">
    <type>transmission_interface/SimpleTransmission</type>
    <joint name="right_finger_joint">
      <hardwareInterface>hardware_interface/EffortJointInterface</hardwareInterface>
      <offset>-0.0640</offset>
    </joint>
    <actuator name="right_finger_motor">
      <hardwareInterface>hardware_interface/EffortJointInterface</hardwareInterface>
      <mechanicalReduction>1</mechanicalReduction>
    </actuator>
  </transmission>
  <transmission name="trans_left_finger_joint">
    <type>transmission_interface/SimpleTransmission</type>
    <joint name="left_finger_joint">
      <hardwareInterface>hardware_interface/EffortJointInterface</hardwareInterface>
      <offset>-0.0640</offset>
    </joint>
    <actuator name="left_finger_motor">
      <hardwareInterface>hardware_interface/EffortJointInterface</hardwareInterface>
      <mechanicalReduction>1</mechanicalReduction>
    </actuator>
  </transmission>
  <gazebo reference="camera">
    <sensor name="camera_node" type="camera">
      <update_rate>30.0</update_rate>
      <camera name="head">
        <horizontal_fov>1.3962634</horizontal_fov>
        <image>
          <width>800</width>
          <height>800</height>
          <format>R8G8B8</format>
        </image>
        <clip>
          <near>0.02</near>
          <far>300</far>
        </clip>
        <noise>
          <type>gaussian</type>
          <mean>0.0</mean>
          <stddev>0.007</stddev>
        </noise>
      </camera>
      <plugin filename="libgazebo_ros_camera.so" name="gazebo_camera">
        <alwaysOn>true</alwaysOn>
        <updateRate>0.0</updateRate>
        <cameraName>/camera</cameraName>
        <imageTopicName>image_raw</imageTopicName>
        <cameraInfoTopicName>camera_info</cameraInfoTopicName>
        <frameName>camera</frameName>
        <hackBaseline>0.07</hackBaseline>
        <distortionK1>0.0</distortionK1>
        <distortionK2>0.0</distortionK2>
        <distortionK3>0.0</distortionK3>
        <distortionT1>0.0</distortionT1>
        <distortionT2>0.0</distortionT2>
      </plugin>
    </sensor>
  </gazebo>
  <gazebo>
    <plugin filename="librm_robot_hw_sim.so" name="rm_ros_control">
      <robotNamespace>/</robotNamespace>
      <robotSimType>rm_gazebo/RmRobotHWSim</robotSimType>
    </plugin>
  </gazebo>
</robot>
