<?xml version="1.0" ?>
<!-- =================================================================================== -->
<!-- |    This document was autogenerated by xacro from ../rm_description/urdf/engineer/engineer.urdf.xacro | -->
<!-- |    EDITING THIS FILE BY HAND IS NOT RECOMMENDED                                 | -->
<!-- =================================================================================== -->
<robot name="engineer">
  <link name="base_link">
    <visual>
      <origin rpy="0 0 0" xyz="0 0 0"/>
      <geometry>
        <mesh filename="package://rm_description/meshes/engineer/base_link.stl" scale="0.001 0.001 0.001"/>
      </geometry>
    </visual>
    <inertial>
      <mass value="17.965892"/>
      <origin xyz="0.001563 0.001197 0.140585"/>
      <inertia ixx="9.004e-1" ixy="7.479e-3" ixz="2.508e-2" iyy="9.798e-1" iyz="-3.061e-3" izz="1.044e0"/>
    </inertial>
    <collision>
      <origin rpy="0. 0. 0." xyz="0 0 0.0525"/>
      <geometry>
        <box size="0.59 0.59 0.105"/>
      </geometry>
    </collision>
    <collision>
      <origin rpy="0. 0. 0." xyz="0 0 0.165"/>
      <geometry>
        <box size="0.59 0.171 0.12"/>
      </geometry>
    </collision>
    <collision>
      <origin rpy="0. 0. 0." xyz="0 0.15 0.3675"/>
      <geometry>
        <box size="0.24 0.034 0.445"/>
      </geometry>
    </collision>
    <collision>
      <origin rpy="0. 0. 0." xyz="0 -0.15 0.3675"/>
      <geometry>
        <box size="0.24 0.034 0.445"/>
      </geometry>
    </collision>
    <collision>
      <origin rpy="0. 0. 0." xyz="0 0.187 0.46625"/>
      <geometry>
        <box size="0.27 0.024 0.6425"/>
      </geometry>
    </collision>
    <collision>
      <origin rpy="0. 0. 0." xyz="0 -0.187 0.46625"/>
      <geometry>
        <box size="0.27 0.024 0.6425"/>
      </geometry>
    </collision>
  </link>
  <link name="left_front_pivot">
    <visual>
      <origin rpy="0 0 0" xyz="0 0 0"/>
      <geometry>
        <mesh filename="package://rm_description/meshes/common/swerve_pivot.stl" scale="0.001 0.001 0.001"/>
      </geometry>
    </visual>
    <inertial>
      <mass value="0.114131"/>
      <origin rpy="0 0 0" xyz="-0.00005 0.017079 -0.041536"/>
      <inertia ixx="1.335e-4" ixy="26.001e-9" ixz="65.031e-9" iyy="1.372e-4" iyz="20051.742e-9" izz="66866.081e-9"/>
    </inertial>
  </link>
  <joint name="left_front_pivot_joint" type="revolute">
    <axis xyz="0 0 1"/>
    <origin rpy="0 0 0" xyz="0.219 0.2 0.06795"/>
    <parent link="base_link"/>
    <child link="left_front_pivot"/>
    <dynamics damping="0.0" friction="0.1"/>
    <limit effort="1.2" lower="-1e10" upper="1e10" velocity="50"/>
  </joint>
  <link name="left_front_wheel">
    <visual>
      <origin rpy="0 0 0" xyz="0 0 0"/>
      <geometry>
        <mesh filename="package://rm_description/meshes/common/swerve_wheel.stl" scale="0.001 0.001 0.001"/>
      </geometry>
    </visual>
    <inertial>
      <mass value="0.267401"/>
      <origin rpy="0 0 0" xyz="-0.000004 0.000125 0.000001"/>
      <inertia ixx="3.585e-4" ixy="0" ixz="13.459e-9" iyy="6.846e-4" iyz="0" izz="3.584e-4"/>
    </inertial>
    <collision>
      <origin rpy="1.5707963267948966 0 0" xyz="0 0 0"/>
      <geometry>
        <cylinder length="0.02" radius="0.055"/>
      </geometry>
    </collision>
  </link>
  <joint name="left_front_wheel_joint" type="revolute">
    <axis xyz="0 1 0"/>
    <origin rpy="0 0 0" xyz="0 0 -0.06635"/>
    <parent link="left_front_pivot"/>
    <child link="left_front_wheel"/>
    <limit effort="3" lower="-1e10" upper="1e10" velocity="76"/>
    <dynamics damping="0.0" friction="0.05"/>
  </joint>
  <gazebo reference="left_front_wheel">
    <mu1 value="1.0"/>
    <mu2 value="1.0"/>
    <kp value="1000000.0"/>
    <kd value="100.0"/>
    <material>Gazebo/Black</material>
  </gazebo>
  <link name="right_front_pivot">
    <visual>
      <origin rpy="0 0 0" xyz="0 0 0"/>
      <geometry>
        <mesh filename="package://rm_description/meshes/common/swerve_pivot.stl" scale="0.001 0.001 0.001"/>
      </geometry>
    </visual>
    <inertial>
      <mass value="0.114131"/>
      <origin rpy="0 0 0" xyz="-0.00005 0.017079 -0.041536"/>
      <inertia ixx="1.335e-4" ixy="26.001e-9" ixz="65.031e-9" iyy="1.372e-4" iyz="20051.742e-9" izz="66866.081e-9"/>
    </inertial>
  </link>
  <joint name="right_front_pivot_joint" type="revolute">
    <axis xyz="0 0 1"/>
    <origin rpy="0 0 0" xyz="0.219 -0.2 0.06795"/>
    <parent link="base_link"/>
    <child link="right_front_pivot"/>
    <dynamics damping="0.0" friction="0.1"/>
    <limit effort="1.2" lower="-1e10" upper="1e10" velocity="50"/>
  </joint>
  <link name="right_front_wheel">
    <visual>
      <origin rpy="0 0 0" xyz="0 0 0"/>
      <geometry>
        <mesh filename="package://rm_description/meshes/common/swerve_wheel.stl" scale="0.001 0.001 0.001"/>
      </geometry>
    </visual>
    <inertial>
      <mass value="0.267401"/>
      <origin rpy="0 0 0" xyz="-0.000004 0.000125 0.000001"/>
      <inertia ixx="3.585e-4" ixy="0" ixz="13.459e-9" iyy="6.846e-4" iyz="0" izz="3.584e-4"/>
    </inertial>
    <collision>
      <origin rpy="1.5707963267948966 0 0" xyz="0 0 0"/>
      <geometry>
        <cylinder length="0.02" radius="0.055"/>
      </geometry>
    </collision>
  </link>
  <joint name="right_front_wheel_joint" type="revolute">
    <axis xyz="0 1 0"/>
    <origin rpy="0 0 0" xyz="0 0 -0.06635"/>
    <parent link="right_front_pivot"/>
    <child link="right_front_wheel"/>
    <limit effort="3" lower="-1e10" upper="1e10" velocity="76"/>
    <dynamics damping="0.0" friction="0.05"/>
  </joint>
  <gazebo reference="right_front_wheel">
    <mu1 value="1.0"/>
    <mu2 value="1.0"/>
    <kp value="1000000.0"/>
    <kd value="100.0"/>
    <material>Gazebo/Black</material>
  </gazebo>
  <link name="left_back_pivot">
    <visual>
      <origin rpy="0 0 0" xyz="0 0 0"/>
      <geometry>
        <mesh filename="package://rm_description/meshes/common/swerve_pivot.stl" scale="0.001 0.001 0.001"/>
      </geometry>
    </visual>
    <inertial>
      <mass value="0.114131"/>
      <origin rpy="0 0 0" xyz="-0.00005 0.017079 -0.041536"/>
      <inertia ixx="1.335e-4" ixy="26.001e-9" ixz="65.031e-9" iyy="1.372e-4" iyz="20051.742e-9" izz="66866.081e-9"/>
    </inertial>
  </link>
  <joint name="left_back_pivot_joint" type="revolute">
    <axis xyz="0 0 1"/>
    <origin rpy="0 0 0" xyz="-0.219 0.2 0.06795"/>
    <parent link="base_link"/>
    <child link="left_back_pivot"/>
    <dynamics damping="0.0" friction="0.1"/>
    <limit effort="1.2" lower="-1e10" upper="1e10" velocity="50"/>
  </joint>
  <link name="left_back_wheel">
    <visual>
      <origin rpy="0 0 0" xyz="0 0 0"/>
      <geometry>
        <mesh filename="package://rm_description/meshes/common/swerve_wheel.stl" scale="0.001 0.001 0.001"/>
      </geometry>
    </visual>
    <inertial>
      <mass value="0.267401"/>
      <origin rpy="0 0 0" xyz="-0.000004 0.000125 0.000001"/>
      <inertia ixx="3.585e-4" ixy="0" ixz="13.459e-9" iyy="6.846e-4" iyz="0" izz="3.584e-4"/>
    </inertial>
    <collision>
      <origin rpy="1.5707963267948966 0 0" xyz="0 0 0"/>
      <geometry>
        <cylinder length="0.02" radius="0.055"/>
      </geometry>
    </collision>
  </link>
  <joint name="left_back_wheel_joint" type="revolute">
    <axis xyz="0 1 0"/>
    <origin rpy="0 0 0" xyz="0 0 -0.06635"/>
    <parent link="left_back_pivot"/>
    <child link="left_back_wheel"/>
    <limit effort="3" lower="-1e10" upper="1e10" velocity="76"/>
    <dynamics damping="0.0" friction="0.05"/>
  </joint>
  <gazebo reference="left_back_wheel">
    <mu1 value="1.0"/>
    <mu2 value="1.0"/>
    <kp value="1000000.0"/>
    <kd value="100.0"/>
    <material>Gazebo/Black</material>
  </gazebo>
  <link name="right_back_pivot">
    <visual>
      <origin rpy="0 0 0" xyz="0 0 0"/>
      <geometry>
        <mesh filename="package://rm_description/meshes/common/swerve_pivot.stl" scale="0.001 0.001 0.001"/>
      </geometry>
    </visual>
    <inertial>
      <mass value="0.114131"/>
      <origin rpy="0 0 0" xyz="-0.00005 0.017079 -0.041536"/>
      <inertia ixx="1.335e-4" ixy="26.001e-9" ixz="65.031e-9" iyy="1.372e-4" iyz="20051.742e-9" izz="66866.081e-9"/>
    </inertial>
  </link>
  <joint name="right_back_pivot_joint" type="revolute">
    <axis xyz="0 0 1"/>
    <origin rpy="0 0 0" xyz="-0.219 -0.2 0.06795"/>
    <parent link="base_link"/>
    <child link="right_back_pivot"/>
    <dynamics damping="0.0" friction="0.1"/>
    <limit effort="1.2" lower="-1e10" upper="1e10" velocity="50"/>
  </joint>
  <link name="right_back_wheel">
    <visual>
      <origin rpy="0 0 0" xyz="0 0 0"/>
      <geometry>
        <mesh filename="package://rm_description/meshes/common/swerve_wheel.stl" scale="0.001 0.001 0.001"/>
      </geometry>
    </visual>
    <inertial>
      <mass value="0.267401"/>
      <origin rpy="0 0 0" xyz="-0.000004 0.000125 0.000001"/>
      <inertia ixx="3.585e-4" ixy="0" ixz="13.459e-9" iyy="6.846e-4" iyz="0" izz="3.584e-4"/>
    </inertial>
    <collision>
      <origin rpy="1.5707963267948966 0 0" xyz="0 0 0"/>
      <geometry>
        <cylinder length="0.02" radius="0.055"/>
      </geometry>
    </collision>
  </link>
  <joint name="right_back_wheel_joint" type="revolute">
    <axis xyz="0 1 0"/>
    <origin rpy="0 0 0" xyz="0 0 -0.06635"/>
    <parent link="right_back_pivot"/>
    <child link="right_back_wheel"/>
    <limit effort="3" lower="-1e10" upper="1e10" velocity="76"/>
    <dynamics damping="0.0" friction="0.05"/>
  </joint>
  <gazebo reference="right_back_wheel">
    <mu1 value="1.0"/>
    <mu2 value="1.0"/>
    <kp value="1000000.0"/>
    <kd value="100.0"/>
    <material>Gazebo/Black</material>
  </gazebo>
  <transmission name="left_front_pivot_trans">
    <type>transmission_interface/SimpleTransmission</type>
    <actuator name="left_front_pivot_motor">
      <mechanicalReduction>-1</mechanicalReduction>
    </actuator>
    <joint name="left_front_pivot_joint">
      <offset>4.481304</offset>
      <hardwareInterface>hardware_interface/EffortJointInterface</hardwareInterface>
    </joint>
  </transmission>
  <transmission name="left_front_wheel_trans">
    <type>transmission_interface/SimpleTransmission</type>
    <actuator name="left_front_wheel_motor">
      <mechanicalReduction>13</mechanicalReduction>
    </actuator>
    <joint name="left_front_wheel_joint">
      <hardwareInterface>hardware_interface/EffortJointInterface</hardwareInterface>
    </joint>
  </transmission>
  <transmission name="right_front_pivot_trans">
    <type>transmission_interface/SimpleTransmission</type>
    <actuator name="right_front_pivot_motor">
      <mechanicalReduction>-1</mechanicalReduction>
    </actuator>
    <joint name="right_front_pivot_joint">
      <offset>0.733332</offset>
      <hardwareInterface>hardware_interface/EffortJointInterface</hardwareInterface>
    </joint>
  </transmission>
  <transmission name="right_front_wheel_trans">
    <type>transmission_interface/SimpleTransmission</type>
    <actuator name="right_front_wheel_motor">
      <mechanicalReduction>13</mechanicalReduction>
    </actuator>
    <joint name="right_front_wheel_joint">
      <hardwareInterface>hardware_interface/EffortJointInterface</hardwareInterface>
    </joint>
  </transmission>
  <transmission name="left_back_pivot_trans">
    <type>transmission_interface/SimpleTransmission</type>
    <actuator name="left_back_pivot_motor">
      <mechanicalReduction>-1</mechanicalReduction>
    </actuator>
    <joint name="left_back_pivot_joint">
      <offset>4.25117</offset>
      <hardwareInterface>hardware_interface/EffortJointInterface</hardwareInterface>
    </joint>
  </transmission>
  <transmission name="left_back_wheel_trans">
    <type>transmission_interface/SimpleTransmission</type>
    <actuator name="left_back_wheel_motor">
      <mechanicalReduction>13</mechanicalReduction>
    </actuator>
    <joint name="left_back_wheel_joint">
      <hardwareInterface>hardware_interface/EffortJointInterface</hardwareInterface>
    </joint>
  </transmission>
  <transmission name="right_back_pivot_trans">
    <type>transmission_interface/SimpleTransmission</type>
    <actuator name="right_back_pivot_motor">
      <mechanicalReduction>-1</mechanicalReduction>
    </actuator>
    <joint name="right_back_pivot_joint">
      <offset>0.80697</offset>
      <hardwareInterface>hardware_interface/EffortJointInterface</hardwareInterface>
    </joint>
  </transmission>
  <transmission name="right_back_wheel_trans">
    <type>transmission_interface/SimpleTransmission</type>
    <actuator name="right_back_wheel_motor">
      <mechanicalReduction>13</mechanicalReduction>
    </actuator>
    <joint name="right_back_wheel_joint">
      <hardwareInterface>hardware_interface/EffortJointInterface</hardwareInterface>
    </joint>
  </transmission>
  <!--  link  -->
  <link name="link1">
    <visual>
      <origin rpy="0 0 0" xyz="0 0 0"/>
      <geometry>
        <mesh filename="package://rm_description/meshes/engineer/link1.stl" scale="0.001 0.001 0.001"/>
      </geometry>
    </visual>
    <inertial>
      <mass value="17.258532"/>
      <origin xyz="-0.008463 -0.030206 0.449363"/>
      <inertia ixx="4.354e0" ixy="-4.478e-2" ixz="3.004e-1" iyy="4.265e0" iyz="3.485e-1" izz="6.554e-1"/>
    </inertial>
    <collision>
      <origin rpy="0. 0. 0." xyz="0 0.25 0.028"/>
      <geometry>
        <box size="0.334 0.06 0.056"/>
      </geometry>
    </collision>
    <collision>
      <origin rpy="0. 0. 0." xyz="0 -0.25 0.028"/>
      <geometry>
        <box size="0.334 0.06 0.056"/>
      </geometry>
    </collision>
  </link>
  <link name="link2">
    <visual>
      <origin rpy="0 0 0" xyz="0 0 0"/>
      <geometry>
        <mesh filename="package://rm_description/meshes/engineer/link2.stl" scale="0.001 0.001 0.001"/>
      </geometry>
    </visual>
    <inertial>
      <mass value="7.32303"/>
      <origin xyz="-0.034595 0. 0.267725"/>
      <inertia ixx="9.797e-1" ixy="9.433e-14" ixz="6.266e-2" iyy="6.589e-1" iyz="6.173e-17" izz="5.759e-1"/>
    </inertial>
    <collision>
      <origin rpy="0. 0. 0." xyz="0.1575 0.23 0.0245"/>
      <geometry>
        <box size="0.885 0.1 0.049"/>
      </geometry>
    </collision>
    <collision>
      <origin rpy="0. 0. 0." xyz="0.1575 -0.23 0.0245"/>
      <geometry>
        <box size="0.885 0.1 0.049"/>
      </geometry>
    </collision>
    <collision>
      <origin rpy="0. 0. 0." xyz="0.249 0.23 0.01"/>
      <geometry>
        <box size="0.046 0.43 0.02"/>
      </geometry>
    </collision>
  </link>
  <link name="link3">
    <visual>
      <origin rpy="0 0 0" xyz="0 0 0"/>
      <geometry>
        <mesh filename="package://rm_description/meshes/engineer/link3.stl" scale="0.001 0.001 0.001"/>
      </geometry>
    </visual>
    <inertial>
      <mass value="2.840864"/>
      <origin xyz="0.244633 0.013775 0.340425"/>
      <inertia ixx="3.971e-1" ixy="-5.987e-3" ixz="-2.364e-1" iyy="5.026e-1" iyz="-1.334e-2" izz="2.385e-1"/>
    </inertial>
    <collision>
      <origin rpy="0. 0. 0." xyz="0. 0. 0.019"/>
      <geometry>
        <box size="0.093 0.515 0.038"/>
      </geometry>
    </collision>
  </link>
  <link name="link4">
    <visual>
      <origin rpy="0 0 0" xyz="0 0 0"/>
      <geometry>
        <mesh filename="package://rm_description/meshes/engineer/link4.stl" scale="0.001 0.001 0.001"/>
      </geometry>
    </visual>
    <inertial>
      <mass value="0.07901"/>
      <origin xyz="-0.000833 0.020242 -0.00371"/>
      <inertia ixx="1.2e-4" ixy="1.90146e-7" ixz="-1.654e-6" iyy="3.797e-5" iyz="-8.45708e-7" izz="1.13e-4"/>
    </inertial>
    <collision>
      <origin rpy="0. 0. 0." xyz="0. 0.0405 -0.0103"/>
      <geometry>
        <box size="0.055 0.081 0.06875"/>
      </geometry>
    </collision>
  </link>
  <link name="link5">
    <visual>
      <origin rpy="0 0 0" xyz="0 0 0"/>
      <geometry>
        <mesh filename="package://rm_description/meshes/engineer/link5.stl" scale="0.001 0.001 0.001"/>
      </geometry>
    </visual>
    <inertial>
      <mass value="0.178017"/>
      <origin xyz="0.031645 -0.04201 -0.08290"/>
      <inertia ixx="2.936e-3" ixy="2.366e-4" ixz="-5.559e-4" iyy="2.88e-3" iyz="6.198e-4" izz="6.447e-4"/>
    </inertial>
    <collision>
      <origin rpy="0. 0. 0." xyz="0.04 0.00375 0."/>
      <geometry>
        <box size="0.0789 0.0795 0.068"/>
      </geometry>
    </collision>
    <collision>
      <origin rpy="0. 0. 0." xyz="0.018 0. 0.084"/>
      <geometry>
        <box size="0.04 0.04 0.2365"/>
      </geometry>
    </collision>
  </link>
  <link name="link6">
    <visual>
      <origin rpy="0 0 0" xyz="0 0 0"/>
      <geometry>
        <mesh filename="package://rm_description/meshes/engineer/link6.stl" scale="0.001 0.001 0.001"/>
      </geometry>
    </visual>
    <inertial>
      <mass value="0.242891"/>
      <origin xyz="0.034166 -0.041995 0.21611"/>
      <inertia ixx="1.225e-2" ixy="3.486e-4" ixz="-1.804e-3" iyy="1.224e-2" iyz="2.204e-3" izz="1.033e-3"/>
    </inertial>
    <collision>
      <origin rpy="0. 0. 0." xyz="0.007 0. -0.022"/>
      <geometry>
        <box size="0.062 0.067 0.12"/>
      </geometry>
    </collision>
    <collision>
      <origin rpy="0. 0. 0." xyz="0.087 0. 0.0305"/>
      <geometry>
        <box size="0.047 0.101 0.05"/>
      </geometry>
    </collision>
  </link>
  <joint name="joint1" type="prismatic">
    <parent link="base_link"/>
    <child link="link1"/>
    <origin rpy="0 0 0" xyz="0 0 0.21"/>
    <axis xyz="0 0 1"/>
    <limit effort="609.75" lower="-2" upper="2.32" velocity="1.2"/>
    <safety_controller k_position="6000." k_velocity="200." soft_lower_limit="-1.9999" soft_upper_limit="2.3198999999999996"/>
    <dynamics damping="0.0" friction="0.1"/>
  </joint>
  <joint name="joint2" type="prismatic">
    <parent link="link1"/>
    <child link="link2"/>
    <origin rpy="0 0 0" xyz="0 0. 0.056"/>
    <axis xyz="1 0 0"/>
    <limit effort="110.0" lower="-2.32" upper="2.32" velocity="1.9"/>
    <safety_controller k_position="50000." k_velocity="600." soft_lower_limit="-2.3169999999999997" soft_upper_limit="2.3169999999999997"/>
    <dynamics damping="0.0" friction="0.1"/>
  </joint>
  <joint name="joint3" type="prismatic">
    <parent link="link2"/>
    <child link="link3"/>
    <origin rpy="0 0 0" xyz="0.2595 0. 0.046"/>
    <axis xyz="0 1 0"/>
    <limit effort="85.47" lower="-2.12" upper="2.31" velocity="2.92"/>
    <safety_controller k_position="8000." k_velocity="400." soft_lower_limit="-2.115" soft_upper_limit="2.305"/>
    <dynamics damping="0.0" friction="0.1"/>
  </joint>
  <joint name="joint4" type="revolute">
    <parent link="link3"/>
    <child link="link4"/>
    <origin rpy="0 0 0" xyz="0. 0. 0.073"/>
    <axis xyz="0 1 0"/>
    <limit effort="13.3" lower="-2.31" upper="2.31" velocity="18.8"/>
    <safety_controller k_position="300." k_velocity="3." soft_lower_limit="-2.2600000000000002" soft_upper_limit="2.2600000000000002"/>
    <dynamics damping="0.0" friction="0.1"/>
  </joint>
  <joint name="joint5" type="revolute">
    <parent link="link4"/>
    <child link="link5"/>
    <origin rpy="0 0 0" xyz="0.07 0. 0."/>
    <axis xyz="1 0 0"/>
    <limit effort="13.3" lower="0" upper="13.8445" velocity="18.8"/>
    <safety_controller k_position="100." k_velocity="3." soft_lower_limit="0.01" soft_upper_limit="13.8345"/>
    <dynamics damping="0.0" friction="0.1"/>
  </joint>
  <joint name="joint6" type="revolute">
    <parent link="link5"/>
    <child link="link6"/>
    <origin rpy="0 0 0" xyz="-0.07 0 -0.2165"/>
    <axis xyz="0 0 1"/>
    <limit effort="5" lower="-0.9" upper="10.9" velocity="50"/>
    <safety_controller k_position="50." k_velocity="0.6" soft_lower_limit="-0.7" soft_upper_limit="10.700000000000001"/>
    <dynamics damping="0.0" friction="0.1"/>
  </joint>
  <!-- transmission -->
  <transmission name="trans_joint1">
    <type>transmission_interface/SimpleTransmission</type>
    <actuator name="joint1_motor">
      <mechanicalReduction>239.925</mechanicalReduction>
    </actuator>
    <joint name="joint1">
      <hardwareInterface>hardware_interface/EffortJointInterface</hardwareInterface>
      <offset>0.</offset>
    </joint>
  </transmission>
  <transmission name="trans_joint2">
    <type>transmission_interface/SimpleTransmission</type>
    <actuator name="joint2_motor">
      <mechanicalReduction>159.95</mechanicalReduction>
    </actuator>
    <joint name="joint2">
      <hardwareInterface>hardware_interface/EffortJointInterface</hardwareInterface>
      <offset>0.</offset>
    </joint>
  </transmission>
  <transmission name="trans_joint3">
    <type>transmission_interface/SimpleTransmission</type>
    <actuator name="joint3_motor">
      <mechanicalReduction>479.85</mechanicalReduction>
    </actuator>
    <joint name="joint3">
      <hardwareInterface>hardware_interface/EffortJointInterface</hardwareInterface>
      <offset>0.</offset>
    </joint>
  </transmission>
  <transmission name="trans_joint4">
    <type>transmission_interface/SimpleTransmission</type>
    <actuator name="joint4_motor">
      <mechanicalReduction>96.242</mechanicalReduction>
    </actuator>
    <joint name="joint4">
      <hardwareInterface>hardware_interface/EffortJointInterface</hardwareInterface>
      <offset>0</offset>
    </joint>
  </transmission>
  <transmission name="trans_joint5">
    <type>transmission_interface/SimpleTransmission</type>
    <actuator name="joint5_motor">
      <mechanicalReduction>96.242</mechanicalReduction>
    </actuator>
    <joint name="joint5">
      <hardwareInterface>hardware_interface/EffortJointInterface</hardwareInterface>
      <offset>0.</offset>
    </joint>
  </transmission>
  <transmission name="trans_joint6">
    <type>transmission_interface/SimpleTransmission</type>
    <actuator name="joint6_motor">
      <mechanicalReduction>96.242</mechanicalReduction>
    </actuator>
    <joint name="joint6">
      <hardwareInterface>hardware_interface/EffortJointInterface</hardwareInterface>
      <offset>0.</offset>
    </joint>
  </transmission>
  <gazebo>
    <plugin filename="librm_robot_hw_sim.so" name="rm_ros_control">
      <robotNamespace>/</robotNamespace>
      <robotSimType>rm_gazebo/RmRobotHWSim</robotSimType>
    </plugin>
  </gazebo>
</robot>
