<?xml version="1.0" ?>
<!-- =================================================================================== -->
<!-- |    This document was autogenerated by xacro from /home/cch/rm_ws/src/rm_description/urdf/engineer2/engineer2.urdf.xacro | -->
<!-- |    EDITING THIS FILE BY HAND IS NOT RECOMMENDED                                 | -->
<!-- =================================================================================== -->
<robot name="engineer2">
    <link name="base_link">
        <inertial>
            <mass value="15.736541" />
            <origin xyz="0.05048 0.003745 0.123835" rpy="0 0 0" />
            <inertia ixx="6.818e-1" ixy="-5.361e-3" ixz="-2.802e-2" iyy="6.637e-1" iyz="-1.676e-2" izz="9.575e-1" />
        </inertial>
        <visual>
            <origin rpy="0 0 0" xyz="0 0 0" />
            <geometry>
                <mesh filename="package://rm_description/meshes/engineer2/base_link.stl" />
            </geometry>
        </visual>
        <collision>
            <origin rpy="0 0 0" xyz="0 0 0" />
            <geometry>
                <mesh filename="package://rm_description/meshes/engineer2/base_link.stl" />
            </geometry>
        </collision>
    </link>
    <!--  link  -->
    <link name="left_front_wheel">
        <visual>
            <geometry>
                <mesh filename="package://rm_description/meshes/common/right_threaded_14roller_mecanum_wheel.stl" />
            </geometry>
        </visual>
        <inertial>
            <mass value="1.613177" />
            <inertia ixx="1.416e-3" ixy="0.0" ixz="0.0" iyy="2.749e-3" iyz="0.0" izz="1.416e-3" />
        </inertial>
    </link>
    <!--  joint  -->
    <joint name="left_front_wheel_joint" type="revolute">
        <axis xyz="0 1 0" />
        <origin rpy="0 0 0" xyz="0.213 0.1945 0.07" />
        <!--      limit not work while type="continuous"-->
        <limit effort="5" lower="-1e9" upper="1e9" velocity="50" />
        <dynamics damping="0.0" friction="0.05" />
        <parent link="base_link" />
        <child link="left_front_wheel" />
    </joint>
    <!--  link  -->
    <link name="left_front_roller_0">
        <collision>
            <!--  quat_xyzw dosen't work ?! covert to rpy-->
            <origin rpy="0.0                      -0.0                      -0.7853981633974484" xyz="0 0 0" />
            <geometry>
                <mesh filename="package://rm_description/meshes/common/roller.stl" scale="0.001 0.001 0.001" />
            </geometry>
        </collision>
        <inertial>
            <mass value="0.036" />
            <inertia ixx="3128e-9" ixy="0.0" ixz="0.0" iyy="3128e-9" iyz="0.0" izz="3128e-9" />
            <origin xyz="0 0 0" rpy="0 0 0" />
        </inertial>
    </link>
    <joint name="left_front_roller_0_joint" type="continuous">
        <origin rpy="0 0 0" xyz="3.7351727373994275e-18 0 -0.061000000000000006" />
        <axis xyz="0.7071067811865476 -0.7071067811865476 0.0" />
        <dynamics damping="0.0" friction="0.001" />
        <parent link="left_front_wheel" />
        <child link="left_front_roller_0" />
    </joint>
    <gazebo reference="left_front_roller_0">
        <mu1 value="2000.0" />
        <mu2 value="2000.0" />
        <kp value="1000000.0" />
        <kd value="100.0" />
        <material>Gazebo/Black</material>
        <plugin name="gazebo_ros_control">
            <robotNamespace>/</robotNamespace>
        </plugin>
    </gazebo>
    <!--  link  -->
    <link name="left_front_roller_1">
        <collision>
            <!--  quat_xyzw dosen't work ?! covert to rpy-->
            <origin rpy="0.1397561040427883                      -0.3119658732170331                      -0.8374943569350152" xyz="0 0 0" />
            <geometry>
                <mesh filename="package://rm_description/meshes/common/roller.stl" scale="0.001 0.001 0.001" />
            </geometry>
        </collision>
        <inertial>
            <mass value="0.036" />
            <inertia ixx="3128e-9" ixy="0.0" ixz="0.0" iyy="3128e-9" iyz="0.0" izz="3128e-9" />
            <origin xyz="0 0 0" rpy="0 0 0" />
        </inertial>
    </link>
    <joint name="left_front_roller_1_joint" type="continuous">
        <origin rpy="0 0 0" xyz="0.0264779570502484 0 -0.0549537786730376" />
        <axis xyz="0.6370195008447469 -0.7071067811865476 0.30693021282289823" />
        <dynamics damping="0.0" friction="0.001" />
        <parent link="left_front_wheel" />
        <child link="left_front_roller_1" />
    </joint>
    <gazebo reference="left_front_roller_1">
        <mu1 value="2000.0" />
        <mu2 value="2000.0" />
        <kp value="1000000.0" />
        <kd value="100.0" />
        <material>Gazebo/Black</material>
    </gazebo>
    <!--  link  -->
    <link name="left_front_roller_2">
        <collision>
            <!--  quat_xyzw dosen't work ?! covert to rpy-->
            <origin rpy="0.33184050390145986                      -0.5859793018876829                      -1.0135101754191935" xyz="0 0 0" />
            <geometry>
                <mesh filename="package://rm_description/meshes/common/roller.stl" scale="0.001 0.001 0.001" />
            </geometry>
        </collision>
        <inertial>
            <mass value="0.036" />
            <inertia ixx="3128e-9" ixy="0.0" ixz="0.0" iyy="3128e-9" iyz="0.0" izz="3128e-9" />
            <origin xyz="0 0 0" rpy="0 0 0" />
        </inertial>
    </link>
    <joint name="left_front_roller_2_joint" type="continuous">
        <origin rpy="0 0 0" xyz="0.04770700955585395 0 -0.03801369804738366" />
        <axis xyz="0.4406515355292263 -0.7071067811865476 0.55301557323075" />
        <dynamics damping="0.0" friction="0.001" />
        <parent link="left_front_wheel" />
        <child link="left_front_roller_2" />
    </joint>
    <gazebo reference="left_front_roller_2">
        <mu1 value="2000.0" />
        <mu2 value="2000.0" />
        <kp value="1000000.0" />
        <kd value="100.0" />
        <material>Gazebo/Black</material>
    </gazebo>
    <!--  link  -->
    <link name="left_front_roller_3">
        <collision>
            <!--  quat_xyzw dosen't work ?! covert to rpy-->
            <origin rpy="0.6209334157717955                      -0.760761096270827                      -1.352403136081973" xyz="0 0 0" />
            <geometry>
                <mesh filename="package://rm_description/meshes/common/roller.stl" scale="0.001 0.001 0.001" />
            </geometry>
        </collision>
        <inertial>
            <mass value="0.036" />
            <inertia ixx="3128e-9" ixy="0.0" ixz="0.0" iyy="3128e-9" iyz="0.0" izz="3128e-9" />
            <origin xyz="0 0 0" rpy="0 0 0" />
        </inertial>
    </link>
    <joint name="left_front_roller_3_joint" type="continuous">
        <origin rpy="0 0 0" xyz="0.05947877882794464 0 -0.013537904902031354" />
        <axis xyz="0.15693023539811435 -0.7071067811865476 0.6894729155071231" />
        <dynamics damping="0.0" friction="0.001" />
        <parent link="left_front_wheel" />
        <child link="left_front_roller_3" />
    </joint>
    <gazebo reference="left_front_roller_3">
        <mu1 value="2000.0" />
        <mu2 value="2000.0" />
        <kp value="1000000.0" />
        <kd value="100.0" />
        <material>Gazebo/Black</material>
    </gazebo>
    <!--  link  -->
    <link name="left_front_roller_4">
        <collision>
            <!--  quat_xyzw dosen't work ?! covert to rpy-->
            <origin rpy="0.9253265685651103                      -0.7604552807523317                      -1.7904967611333005" xyz="0 0 0" />
            <geometry>
                <mesh filename="package://rm_description/meshes/common/roller.stl" scale="0.001 0.001 0.001" />
            </geometry>
        </collision>
        <inertial>
            <mass value="0.036" />
            <inertia ixx="3128e-9" ixy="0.0" ixz="0.0" iyy="3128e-9" iyz="0.0" izz="3128e-9" />
            <origin xyz="0 0 0" rpy="0 0 0" />
        </inertial>
    </link>
    <joint name="left_front_roller_4_joint" type="continuous">
        <origin rpy="0 0 0" xyz="0.05945966740983209 0 0.013621598713519345" />
        <axis xyz="-0.15790040690051604 -0.7071067811865476 0.6892513775834267" />
        <dynamics damping="0.0" friction="0.001" />
        <parent link="left_front_wheel" />
        <child link="left_front_roller_4" />
    </joint>
    <gazebo reference="left_front_roller_4">
        <mu1 value="2000.0" />
        <mu2 value="2000.0" />
        <kp value="1000000.0" />
        <kd value="100.0" />
        <material>Gazebo/Black</material>
    </gazebo>
    <!--  link  -->
    <link name="left_front_roller_5">
        <collision>
            <!--  quat_xyzw dosen't work ?! covert to rpy-->
            <origin rpy="0.9952510398634623                      -0.5852345045480243                      -2.1288744267289648" xyz="0 0 0" />
            <geometry>
                <mesh filename="package://rm_description/meshes/common/roller.stl" scale="0.001 0.001 0.001" />
            </geometry>
        </collision>
        <inertial>
            <mass value="0.036" />
            <inertia ixx="3128e-9" ixy="0.0" ixz="0.0" iyy="3128e-9" iyz="0.0" izz="3128e-9" />
            <origin xyz="0 0 0" rpy="0 0 0" />
        </inertial>
    </link>
    <joint name="left_front_roller_5_joint" type="continuous">
        <origin rpy="0 0 0" xyz="0.047653463887214025 0 0.038080800668446955" />
        <axis xyz="-0.44142938337167287 -0.7071067811865476 0.5523948764209392" />
        <dynamics damping="0.0" friction="0.001" />
        <parent link="left_front_wheel" />
        <child link="left_front_roller_5" />
    </joint>
    <gazebo reference="left_front_roller_5">
        <mu1 value="2000.0" />
        <mu2 value="2000.0" />
        <kp value="1000000.0" />
        <kd value="100.0" />
        <material>Gazebo/Black</material>
    </gazebo>
    <!--  link  -->
    <link name="left_front_roller_6">
        <collision>
            <!--  quat_xyzw dosen't work ?! covert to rpy-->
            <origin rpy="0.6776460855750719                      -0.3110237228468675                      -2.3044349087240077" xyz="0 0 0" />
            <geometry>
                <mesh filename="package://rm_description/meshes/common/roller.stl" scale="0.001 0.001 0.001" />
            </geometry>
        </collision>
        <inertial>
            <mass value="0.036" />
            <inertia ixx="3128e-9" ixy="0.0" ixz="0.0" iyy="3128e-9" iyz="0.0" izz="3128e-9" />
            <origin xyz="0 0 0" rpy="0 0 0" />
        </inertial>
    </link>
    <joint name="left_front_roller_6_joint" type="continuous">
        <origin rpy="0 0 0" xyz="0.02640059185120231 0 0.054990987897165756" />
        <axis xyz="-0.6374508269874306 -0.7071067811865476 0.30603340205448304" />
        <dynamics damping="0.0" friction="0.001" />
        <parent link="left_front_wheel" />
        <child link="left_front_roller_6" />
    </joint>
    <gazebo reference="left_front_roller_6">
        <mu1 value="2000.0" />
        <mu2 value="2000.0" />
        <kp value="1000000.0" />
        <kd value="100.0" />
        <material>Gazebo/Black</material>
    </gazebo>
    <!--  link  -->
    <link name="left_front_roller_7">
        <collision>
            <!--  quat_xyzw dosen't work ?! covert to rpy-->
            <origin rpy="-0.002402487564129699                      0.0009951440258853248                      -2.356193995036202" xyz="0 0 0" />
            <geometry>
                <mesh filename="package://rm_description/meshes/common/roller.stl" scale="0.001 0.001 0.001" />
            </geometry>
        </collision>
        <inertial>
            <mass value="0.036" />
            <inertia ixx="3128e-9" ixy="0.0" ixz="0.0" iyy="3128e-9" iyz="0.0" izz="3128e-9" />
            <origin xyz="0 0 0" rpy="0 0 0" />
        </inertial>
    </link>
    <joint name="left_front_roller_7_joint" type="continuous">
        <origin rpy="0 0 0" xyz="-8.584810268382325e-05 0 0.06099993959098047" />
        <axis xyz="-0.7071060809303613 -0.7071067811865476 -0.0009951438616348823" />
        <dynamics damping="0.0" friction="0.001" />
        <parent link="left_front_wheel" />
        <child link="left_front_roller_7" />
    </joint>
    <gazebo reference="left_front_roller_7">
        <mu1 value="2000.0" />
        <mu2 value="2000.0" />
        <kp value="1000000.0" />
        <kd value="100.0" />
        <material>Gazebo/Black</material>
    </gazebo>
    <!--  link  -->
    <link name="left_front_roller_8">
        <collision>
            <!--  quat_xyzw dosen't work ?! covert to rpy-->
            <origin rpy="-0.6809319806086911                      0.3129076709989273                      -2.303760494768245" xyz="0 0 0" />
            <geometry>
                <mesh filename="package://rm_description/meshes/common/roller.stl" scale="0.001 0.001 0.001" />
            </geometry>
        </collision>
        <inertial>
            <mass value="0.036" />
            <inertia ixx="3128e-9" ixy="0.0" ixz="0.0" iyy="3128e-9" iyz="0.0" izz="3128e-9" />
            <origin xyz="0 0 0" rpy="0 0 0" />
        </inertial>
    </link>
    <joint name="left_front_roller_8_joint" type="continuous">
        <origin rpy="0 0 0" xyz="-0.026555269806428094 0 0.054916460606158964" />
        <axis xyz="-0.6365869130062115 -0.7071067811865476 -0.3078264156780931" />
        <dynamics damping="0.0" friction="0.001" />
        <parent link="left_front_wheel" />
        <child link="left_front_roller_8" />
    </joint>
    <gazebo reference="left_front_roller_8">
        <mu1 value="2000.0" />
        <mu2 value="2000.0" />
        <kp value="1000000.0" />
        <kd value="100.0" />
        <material>Gazebo/Black</material>
    </gazebo>
    <!--  link  -->
    <link name="left_front_roller_9">
        <collision>
            <!--  quat_xyzw dosen't work ?! covert to rpy-->
            <origin rpy="-0.9959421340702964                      0.5867231523205594                      -2.127288857247016" xyz="0 0 0" />
            <geometry>
                <mesh filename="package://rm_description/meshes/common/roller.stl" scale="0.001 0.001 0.001" />
            </geometry>
        </collision>
        <inertial>
            <mass value="0.036" />
            <inertia ixx="3128e-9" ixy="0.0" ixz="0.0" iyy="3128e-9" iyz="0.0" izz="3128e-9" />
            <origin xyz="0 0 0" rpy="0 0 0" />
        </inertial>
    </link>
    <joint name="left_front_roller_9_joint" type="continuous">
        <origin rpy="0 0 0" xyz="-0.04776046073486529 0 0.03794652013549321" />
        <axis xyz="-0.43987281492195274 -0.7071067811865476 -0.5536351747248702" />
        <dynamics damping="0.0" friction="0.001" />
        <parent link="left_front_wheel" />
        <child link="left_front_roller_9" />
    </joint>
    <gazebo reference="left_front_roller_9">
        <mu1 value="2000.0" />
        <mu2 value="2000.0" />
        <kp value="1000000.0" />
        <kd value="100.0" />
        <material>Gazebo/Black</material>
    </gazebo>
    <!--  link  -->
    <link name="left_front_roller_10">
        <collision>
            <!--  quat_xyzw dosen't work ?! covert to rpy-->
            <origin rpy="-0.9238936146297452                      0.7610651149346043                      -1.7878810957525777" xyz="0 0 0" />
            <geometry>
                <mesh filename="package://rm_description/meshes/common/roller.stl" scale="0.001 0.001 0.001" />
            </geometry>
        </collision>
        <inertial>
            <mass value="0.036" />
            <inertia ixx="3128e-9" ixy="0.0" ixz="0.0" iyy="3128e-9" iyz="0.0" izz="3128e-9" />
            <origin xyz="0 0 0" rpy="0 0 0" />
        </inertial>
    </link>
    <joint name="left_front_roller_10_joint" type="continuous">
        <origin rpy="0 0 0" xyz="-0.05949777244098466 0 0.013454184277049528" />
        <axis xyz="-0.15595975307598609 -0.7071067811865476 -0.6896930878444973" />
        <dynamics damping="0.0" friction="0.001" />
        <parent link="left_front_wheel" />
        <child link="left_front_roller_10" />
    </joint>
    <gazebo reference="left_front_roller_10">
        <mu1 value="2000.0" />
        <mu2 value="2000.0" />
        <kp value="1000000.0" />
        <kd value="100.0" />
        <material>Gazebo/Black</material>
    </gazebo>
    <!--  link  -->
    <link name="left_front_roller_11">
        <collision>
            <!--  quat_xyzw dosen't work ?! covert to rpy-->
            <origin rpy="-0.6188607822812026                      0.7601476705240283                      -1.3497898326199715" xyz="0 0 0" />
            <geometry>
                <mesh filename="package://rm_description/meshes/common/roller.stl" scale="0.001 0.001 0.001" />
            </geometry>
        </collision>
        <inertial>
            <mass value="0.036" />
            <inertia ixx="3128e-9" ixy="0.0" ixz="0.0" iyy="3128e-9" iyz="0.0" izz="3128e-9" />
            <origin xyz="0 0 0" rpy="0 0 0" />
        </inertial>
    </link>
    <joint name="left_front_roller_11_joint" type="continuous">
        <origin rpy="0 0 0" xyz="-0.059440438224499535 0 -0.013705265545747565" />
        <axis xyz="0.15887026566164672 -0.7071067811865476 -0.6890284745121915" />
        <dynamics damping="0.0" friction="0.001" />
        <parent link="left_front_wheel" />
        <child link="left_front_roller_11" />
    </joint>
    <gazebo reference="left_front_roller_11">
        <mu1 value="2000.0" />
        <mu2 value="2000.0" />
        <kp value="1000000.0" />
        <kd value="100.0" />
        <material>Gazebo/Black</material>
    </gazebo>
    <!--  link  -->
    <link name="left_front_roller_12">
        <collision>
            <!--  quat_xyzw dosen't work ?! covert to rpy-->
            <origin rpy="-0.33035697597807884                      0.5844887627649618                      -1.0119279494343745" xyz="0 0 0" />
            <geometry>
                <mesh filename="package://rm_description/meshes/common/roller.stl" scale="0.001 0.001 0.001" />
            </geometry>
        </collision>
        <inertial>
            <mass value="0.036" />
            <inertia ixx="3128e-9" ixy="0.0" ixz="0.0" iyy="3128e-9" iyz="0.0" izz="3128e-9" />
            <origin xyz="0 0 0" rpy="0 0 0" />
        </inertial>
    </link>
    <joint name="left_front_roller_12_joint" type="continuous">
        <origin rpy="0 0 0" xyz="-0.04759982383499931 0 -0.03814782786577804" />
        <axis xyz="0.4422063569086687 -0.7071067811865476 -0.5517730855248045" />
        <dynamics damping="0.0" friction="0.001" />
        <parent link="left_front_wheel" />
        <child link="left_front_roller_12" />
    </joint>
    <gazebo reference="left_front_roller_12">
        <mu1 value="2000.0" />
        <mu2 value="2000.0" />
        <kp value="1000000.0" />
        <kd value="100.0" />
        <material>Gazebo/Black</material>
    </gazebo>
    <!--  link  -->
    <link name="left_front_roller_13">
        <collision>
            <!--  quat_xyzw dosen't work ?! covert to rpy-->
            <origin rpy="-0.13877562966172519                      0.3100812212384385                      -0.8368223213782329" xyz="0 0 0" />
            <geometry>
                <mesh filename="package://rm_description/meshes/common/roller.stl" scale="0.001 0.001 0.001" />
            </geometry>
        </collision>
        <inertial>
            <mass value="0.036" />
            <inertia ixx="3128e-9" ixy="0.0" ixz="0.0" iyy="3128e-9" iyz="0.0" izz="3128e-9" />
            <origin xyz="0 0 0" rpy="0 0 0" />
        </inertial>
    </link>
    <joint name="left_front_roller_13_joint" type="continuous">
        <origin rpy="0 0 0" xyz="-0.0263231743625212 0 -0.05502808820484596" />
        <axis xyz="0.637880890579968 -0.7071067811865476 -0.30513598514909207" />
        <dynamics damping="0.0" friction="0.001" />
        <parent link="left_front_wheel" />
        <child link="left_front_roller_13" />
    </joint>
    <gazebo reference="left_front_roller_13">
        <mu1 value="2000.0" />
        <mu2 value="2000.0" />
        <kp value="1000000.0" />
        <kd value="100.0" />
        <material>Gazebo/Black</material>
    </gazebo>
    <!--  link  -->
    <link name="right_front_wheel">
        <visual>
            <geometry>
                <mesh filename="package://rm_description/meshes/common/left_threaded_14roller_mecanum_wheel.stl" />
            </geometry>
        </visual>
        <inertial>
            <mass value="1.613177" />
            <inertia ixx="1.416e-3" ixy="0.0" ixz="0.0" iyy="2.749e-3" iyz="0.0" izz="1.416e-3" />
        </inertial>
    </link>
    <!--  joint  -->
    <joint name="right_front_wheel_joint" type="revolute">
        <axis xyz="0 1 0" />
        <origin rpy="0 0 0" xyz="0.213 -0.1945 0.07" />
        <!--      limit not work while type="continuous"-->
        <limit effort="5" lower="-1e9" upper="1e9" velocity="50" />
        <dynamics damping="0.0" friction="0.05" />
        <parent link="base_link" />
        <child link="right_front_wheel" />
    </joint>
    <!--  link  -->
    <link name="right_front_roller_0">
        <collision>
            <!--  quat_xyzw dosen't work ?! covert to rpy-->
            <origin rpy="-0.0                      0.0                      0.7853981633974484" xyz="0 0 0" />
            <geometry>
                <mesh filename="package://rm_description/meshes/common/roller.stl" scale="0.001 0.001 0.001" />
            </geometry>
        </collision>
        <inertial>
            <mass value="0.036" />
            <inertia ixx="3128e-9" ixy="0.0" ixz="0.0" iyy="3128e-9" iyz="0.0" izz="3128e-9" />
            <origin xyz="0 0 0" rpy="0 0 0" />
        </inertial>
    </link>
    <joint name="right_front_roller_0_joint" type="continuous">
        <origin rpy="0 0 0" xyz="3.7351727373994275e-18 0 -0.061000000000000006" />
        <axis xyz="0.7071067811865476 0.7071067811865476 0.0" />
        <dynamics damping="0.0" friction="0.001" />
        <parent link="right_front_wheel" />
        <child link="right_front_roller_0" />
    </joint>
    <gazebo reference="right_front_roller_0">
        <mu1 value="2000.0" />
        <mu2 value="2000.0" />
        <kp value="1000000.0" />
        <kd value="100.0" />
        <material>Gazebo/Black</material>
    </gazebo>
    <!--  link  -->
    <link name="right_front_roller_1">
        <collision>
            <!--  quat_xyzw dosen't work ?! covert to rpy-->
            <origin rpy="-0.1397561040427883                      -0.3119658732170331                      0.8374943569350152" xyz="0 0 0" />
            <geometry>
                <mesh filename="package://rm_description/meshes/common/roller.stl" scale="0.001 0.001 0.001" />
            </geometry>
        </collision>
        <inertial>
            <mass value="0.036" />
            <inertia ixx="3128e-9" ixy="0.0" ixz="0.0" iyy="3128e-9" iyz="0.0" izz="3128e-9" />
            <origin xyz="0 0 0" rpy="0 0 0" />
        </inertial>
    </link>
    <joint name="right_front_roller_1_joint" type="continuous">
        <origin rpy="0 0 0" xyz="0.0264779570502484 0 -0.0549537786730376" />
        <axis xyz="0.6370195008447469 0.7071067811865476 0.30693021282289823" />
        <dynamics damping="0.0" friction="0.001" />
        <parent link="right_front_wheel" />
        <child link="right_front_roller_1" />
    </joint>
    <gazebo reference="right_front_roller_1">
        <mu1 value="2000.0" />
        <mu2 value="2000.0" />
        <kp value="1000000.0" />
        <kd value="100.0" />
        <material>Gazebo/Black</material>
    </gazebo>
    <!--  link  -->
    <link name="right_front_roller_2">
        <collision>
            <!--  quat_xyzw dosen't work ?! covert to rpy-->
            <origin rpy="-0.33184050390145986                      -0.5859793018876829                      1.0135101754191935" xyz="0 0 0" />
            <geometry>
                <mesh filename="package://rm_description/meshes/common/roller.stl" scale="0.001 0.001 0.001" />
            </geometry>
        </collision>
        <inertial>
            <mass value="0.036" />
            <inertia ixx="3128e-9" ixy="0.0" ixz="0.0" iyy="3128e-9" iyz="0.0" izz="3128e-9" />
            <origin xyz="0 0 0" rpy="0 0 0" />
        </inertial>
    </link>
    <joint name="right_front_roller_2_joint" type="continuous">
        <origin rpy="0 0 0" xyz="0.04770700955585395 0 -0.03801369804738366" />
        <axis xyz="0.4406515355292263 0.7071067811865476 0.55301557323075" />
        <dynamics damping="0.0" friction="0.001" />
        <parent link="right_front_wheel" />
        <child link="right_front_roller_2" />
    </joint>
    <gazebo reference="right_front_roller_2">
        <mu1 value="2000.0" />
        <mu2 value="2000.0" />
        <kp value="1000000.0" />
        <kd value="100.0" />
        <material>Gazebo/Black</material>
    </gazebo>
    <!--  link  -->
    <link name="right_front_roller_3">
        <collision>
            <!--  quat_xyzw dosen't work ?! covert to rpy-->
            <origin rpy="-0.6209334157717955                      -0.760761096270827                      1.352403136081973" xyz="0 0 0" />
            <geometry>
                <mesh filename="package://rm_description/meshes/common/roller.stl" scale="0.001 0.001 0.001" />
            </geometry>
        </collision>
        <inertial>
            <mass value="0.036" />
            <inertia ixx="3128e-9" ixy="0.0" ixz="0.0" iyy="3128e-9" iyz="0.0" izz="3128e-9" />
            <origin xyz="0 0 0" rpy="0 0 0" />
        </inertial>
    </link>
    <joint name="right_front_roller_3_joint" type="continuous">
        <origin rpy="0 0 0" xyz="0.05947877882794464 0 -0.013537904902031354" />
        <axis xyz="0.15693023539811435 0.7071067811865476 0.6894729155071231" />
        <dynamics damping="0.0" friction="0.001" />
        <parent link="right_front_wheel" />
        <child link="right_front_roller_3" />
    </joint>
    <gazebo reference="right_front_roller_3">
        <mu1 value="2000.0" />
        <mu2 value="2000.0" />
        <kp value="1000000.0" />
        <kd value="100.0" />
        <material>Gazebo/Black</material>
    </gazebo>
    <!--  link  -->
    <link name="right_front_roller_4">
        <collision>
            <!--  quat_xyzw dosen't work ?! covert to rpy-->
            <origin rpy="-0.9253265685651103                      -0.7604552807523317                      1.7904967611333005" xyz="0 0 0" />
            <geometry>
                <mesh filename="package://rm_description/meshes/common/roller.stl" scale="0.001 0.001 0.001" />
            </geometry>
        </collision>
        <inertial>
            <mass value="0.036" />
            <inertia ixx="3128e-9" ixy="0.0" ixz="0.0" iyy="3128e-9" iyz="0.0" izz="3128e-9" />
            <origin xyz="0 0 0" rpy="0 0 0" />
        </inertial>
    </link>
    <joint name="right_front_roller_4_joint" type="continuous">
        <origin rpy="0 0 0" xyz="0.05945966740983209 0 0.013621598713519345" />
        <axis xyz="-0.15790040690051604 0.7071067811865476 0.6892513775834267" />
        <dynamics damping="0.0" friction="0.001" />
        <parent link="right_front_wheel" />
        <child link="right_front_roller_4" />
    </joint>
    <gazebo reference="right_front_roller_4">
        <mu1 value="2000.0" />
        <mu2 value="2000.0" />
        <kp value="1000000.0" />
        <kd value="100.0" />
        <material>Gazebo/Black</material>
    </gazebo>
    <!--  link  -->
    <link name="right_front_roller_5">
        <collision>
            <!--  quat_xyzw dosen't work ?! covert to rpy-->
            <origin rpy="-0.9952510398634623                      -0.5852345045480243                      2.1288744267289648" xyz="0 0 0" />
            <geometry>
                <mesh filename="package://rm_description/meshes/common/roller.stl" scale="0.001 0.001 0.001" />
            </geometry>
        </collision>
        <inertial>
            <mass value="0.036" />
            <inertia ixx="3128e-9" ixy="0.0" ixz="0.0" iyy="3128e-9" iyz="0.0" izz="3128e-9" />
            <origin xyz="0 0 0" rpy="0 0 0" />
        </inertial>
    </link>
    <joint name="right_front_roller_5_joint" type="continuous">
        <origin rpy="0 0 0" xyz="0.047653463887214025 0 0.038080800668446955" />
        <axis xyz="-0.44142938337167287 0.7071067811865476 0.5523948764209392" />
        <dynamics damping="0.0" friction="0.001" />
        <parent link="right_front_wheel" />
        <child link="right_front_roller_5" />
    </joint>
    <gazebo reference="right_front_roller_5">
        <mu1 value="2000.0" />
        <mu2 value="2000.0" />
        <kp value="1000000.0" />
        <kd value="100.0" />
        <material>Gazebo/Black</material>
    </gazebo>
    <!--  link  -->
    <link name="right_front_roller_6">
        <collision>
            <!--  quat_xyzw dosen't work ?! covert to rpy-->
            <origin rpy="-0.6776460855750719                      -0.3110237228468675                      2.3044349087240077" xyz="0 0 0" />
            <geometry>
                <mesh filename="package://rm_description/meshes/common/roller.stl" scale="0.001 0.001 0.001" />
            </geometry>
        </collision>
        <inertial>
            <mass value="0.036" />
            <inertia ixx="3128e-9" ixy="0.0" ixz="0.0" iyy="3128e-9" iyz="0.0" izz="3128e-9" />
            <origin xyz="0 0 0" rpy="0 0 0" />
        </inertial>
    </link>
    <joint name="right_front_roller_6_joint" type="continuous">
        <origin rpy="0 0 0" xyz="0.02640059185120231 0 0.054990987897165756" />
        <axis xyz="-0.6374508269874306 0.7071067811865476 0.30603340205448304" />
        <dynamics damping="0.0" friction="0.001" />
        <parent link="right_front_wheel" />
        <child link="right_front_roller_6" />
    </joint>
    <gazebo reference="right_front_roller_6">
        <mu1 value="2000.0" />
        <mu2 value="2000.0" />
        <kp value="1000000.0" />
        <kd value="100.0" />
        <material>Gazebo/Black</material>
    </gazebo>
    <!--  link  -->
    <link name="right_front_roller_7">
        <collision>
            <!--  quat_xyzw dosen't work ?! covert to rpy-->
            <origin rpy="0.002402487564129699                      0.0009951440258853248                      2.356193995036202" xyz="0 0 0" />
            <geometry>
                <mesh filename="package://rm_description/meshes/common/roller.stl" scale="0.001 0.001 0.001" />
            </geometry>
        </collision>
        <inertial>
            <mass value="0.036" />
            <inertia ixx="3128e-9" ixy="0.0" ixz="0.0" iyy="3128e-9" iyz="0.0" izz="3128e-9" />
            <origin xyz="0 0 0" rpy="0 0 0" />
        </inertial>
    </link>
    <joint name="right_front_roller_7_joint" type="continuous">
        <origin rpy="0 0 0" xyz="-8.584810268382325e-05 0 0.06099993959098047" />
        <axis xyz="-0.7071060809303613 0.7071067811865476 -0.0009951438616348823" />
        <dynamics damping="0.0" friction="0.001" />
        <parent link="right_front_wheel" />
        <child link="right_front_roller_7" />
    </joint>
    <gazebo reference="right_front_roller_7">
        <mu1 value="2000.0" />
        <mu2 value="2000.0" />
        <kp value="1000000.0" />
        <kd value="100.0" />
        <material>Gazebo/Black</material>
    </gazebo>
    <!--  link  -->
    <link name="right_front_roller_8">
        <collision>
            <!--  quat_xyzw dosen't work ?! covert to rpy-->
            <origin rpy="0.6809319806086911                      0.3129076709989273                      2.303760494768245" xyz="0 0 0" />
            <geometry>
                <mesh filename="package://rm_description/meshes/common/roller.stl" scale="0.001 0.001 0.001" />
            </geometry>
        </collision>
        <inertial>
            <mass value="0.036" />
            <inertia ixx="3128e-9" ixy="0.0" ixz="0.0" iyy="3128e-9" iyz="0.0" izz="3128e-9" />
            <origin xyz="0 0 0" rpy="0 0 0" />
        </inertial>
    </link>
    <joint name="right_front_roller_8_joint" type="continuous">
        <origin rpy="0 0 0" xyz="-0.026555269806428094 0 0.054916460606158964" />
        <axis xyz="-0.6365869130062115 0.7071067811865476 -0.3078264156780931" />
        <dynamics damping="0.0" friction="0.001" />
        <parent link="right_front_wheel" />
        <child link="right_front_roller_8" />
    </joint>
    <gazebo reference="right_front_roller_8">
        <mu1 value="2000.0" />
        <mu2 value="2000.0" />
        <kp value="1000000.0" />
        <kd value="100.0" />
        <material>Gazebo/Black</material>
    </gazebo>
    <!--  link  -->
    <link name="right_front_roller_9">
        <collision>
            <!--  quat_xyzw dosen't work ?! covert to rpy-->
            <origin rpy="0.9959421340702964                      0.5867231523205594                      2.127288857247016" xyz="0 0 0" />
            <geometry>
                <mesh filename="package://rm_description/meshes/common/roller.stl" scale="0.001 0.001 0.001" />
            </geometry>
        </collision>
        <inertial>
            <mass value="0.036" />
            <inertia ixx="3128e-9" ixy="0.0" ixz="0.0" iyy="3128e-9" iyz="0.0" izz="3128e-9" />
            <origin xyz="0 0 0" rpy="0 0 0" />
        </inertial>
    </link>
    <joint name="right_front_roller_9_joint" type="continuous">
        <origin rpy="0 0 0" xyz="-0.04776046073486529 0 0.03794652013549321" />
        <axis xyz="-0.43987281492195274 0.7071067811865476 -0.5536351747248702" />
        <dynamics damping="0.0" friction="0.001" />
        <parent link="right_front_wheel" />
        <child link="right_front_roller_9" />
    </joint>
    <gazebo reference="right_front_roller_9">
        <mu1 value="2000.0" />
        <mu2 value="2000.0" />
        <kp value="1000000.0" />
        <kd value="100.0" />
        <material>Gazebo/Black</material>
    </gazebo>
    <!--  link  -->
    <link name="right_front_roller_10">
        <collision>
            <!--  quat_xyzw dosen't work ?! covert to rpy-->
            <origin rpy="0.9238936146297452                      0.7610651149346043                      1.7878810957525777" xyz="0 0 0" />
            <geometry>
                <mesh filename="package://rm_description/meshes/common/roller.stl" scale="0.001 0.001 0.001" />
            </geometry>
        </collision>
        <inertial>
            <mass value="0.036" />
            <inertia ixx="3128e-9" ixy="0.0" ixz="0.0" iyy="3128e-9" iyz="0.0" izz="3128e-9" />
            <origin xyz="0 0 0" rpy="0 0 0" />
        </inertial>
    </link>
    <joint name="right_front_roller_10_joint" type="continuous">
        <origin rpy="0 0 0" xyz="-0.05949777244098466 0 0.013454184277049528" />
        <axis xyz="-0.15595975307598609 0.7071067811865476 -0.6896930878444973" />
        <dynamics damping="0.0" friction="0.001" />
        <parent link="right_front_wheel" />
        <child link="right_front_roller_10" />
    </joint>
    <gazebo reference="right_front_roller_10">
        <mu1 value="2000.0" />
        <mu2 value="2000.0" />
        <kp value="1000000.0" />
        <kd value="100.0" />
        <material>Gazebo/Black</material>
    </gazebo>
    <!--  link  -->
    <link name="right_front_roller_11">
        <collision>
            <!--  quat_xyzw dosen't work ?! covert to rpy-->
            <origin rpy="0.6188607822812026                      0.7601476705240283                      1.3497898326199715" xyz="0 0 0" />
            <geometry>
                <mesh filename="package://rm_description/meshes/common/roller.stl" scale="0.001 0.001 0.001" />
            </geometry>
        </collision>
        <inertial>
            <mass value="0.036" />
            <inertia ixx="3128e-9" ixy="0.0" ixz="0.0" iyy="3128e-9" iyz="0.0" izz="3128e-9" />
            <origin xyz="0 0 0" rpy="0 0 0" />
        </inertial>
    </link>
    <joint name="right_front_roller_11_joint" type="continuous">
        <origin rpy="0 0 0" xyz="-0.059440438224499535 0 -0.013705265545747565" />
        <axis xyz="0.15887026566164672 0.7071067811865476 -0.6890284745121915" />
        <dynamics damping="0.0" friction="0.001" />
        <parent link="right_front_wheel" />
        <child link="right_front_roller_11" />
    </joint>
    <gazebo reference="right_front_roller_11">
        <mu1 value="2000.0" />
        <mu2 value="2000.0" />
        <kp value="1000000.0" />
        <kd value="100.0" />
        <material>Gazebo/Black</material>
    </gazebo>
    <!--  link  -->
    <link name="right_front_roller_12">
        <collision>
            <!--  quat_xyzw dosen't work ?! covert to rpy-->
            <origin rpy="0.33035697597807884                      0.5844887627649618                      1.0119279494343745" xyz="0 0 0" />
            <geometry>
                <mesh filename="package://rm_description/meshes/common/roller.stl" scale="0.001 0.001 0.001" />
            </geometry>
        </collision>
        <inertial>
            <mass value="0.036" />
            <inertia ixx="3128e-9" ixy="0.0" ixz="0.0" iyy="3128e-9" iyz="0.0" izz="3128e-9" />
            <origin xyz="0 0 0" rpy="0 0 0" />
        </inertial>
    </link>
    <joint name="right_front_roller_12_joint" type="continuous">
        <origin rpy="0 0 0" xyz="-0.04759982383499931 0 -0.03814782786577804" />
        <axis xyz="0.4422063569086687 0.7071067811865476 -0.5517730855248045" />
        <dynamics damping="0.0" friction="0.001" />
        <parent link="right_front_wheel" />
        <child link="right_front_roller_12" />
    </joint>
    <gazebo reference="right_front_roller_12">
        <mu1 value="2000.0" />
        <mu2 value="2000.0" />
        <kp value="1000000.0" />
        <kd value="100.0" />
        <material>Gazebo/Black</material>
    </gazebo>
    <!--  link  -->
    <link name="right_front_roller_13">
        <collision>
            <!--  quat_xyzw dosen't work ?! covert to rpy-->
            <origin rpy="0.13877562966172519                      0.3100812212384385                      0.8368223213782329" xyz="0 0 0" />
            <geometry>
                <mesh filename="package://rm_description/meshes/common/roller.stl" scale="0.001 0.001 0.001" />
            </geometry>
        </collision>
        <inertial>
            <mass value="0.036" />
            <inertia ixx="3128e-9" ixy="0.0" ixz="0.0" iyy="3128e-9" iyz="0.0" izz="3128e-9" />
            <origin xyz="0 0 0" rpy="0 0 0" />
        </inertial>
    </link>
    <joint name="right_front_roller_13_joint" type="continuous">
        <origin rpy="0 0 0" xyz="-0.0263231743625212 0 -0.05502808820484596" />
        <axis xyz="0.637880890579968 0.7071067811865476 -0.30513598514909207" />
        <dynamics damping="0.0" friction="0.001" />
        <parent link="right_front_wheel" />
        <child link="right_front_roller_13" />
    </joint>
    <gazebo reference="right_front_roller_13">
        <mu1 value="2000.0" />
        <mu2 value="2000.0" />
        <kp value="1000000.0" />
        <kd value="100.0" />
        <material>Gazebo/Black</material>
    </gazebo>
    <!--  link  -->
    <link name="left_back_wheel">
        <visual>
            <geometry>
                <mesh filename="package://rm_description/meshes/common/left_threaded_14roller_mecanum_wheel.stl" />
            </geometry>
        </visual>
        <inertial>
            <mass value="1.613177" />
            <inertia ixx="1.416e-3" ixy="0.0" ixz="0.0" iyy="2.749e-3" iyz="0.0" izz="1.416e-3" />
        </inertial>
    </link>
    <!--  joint  -->
    <joint name="left_back_wheel_joint" type="revolute">
        <axis xyz="0 1 0" />
        <origin rpy="0 0 0" xyz="-0.213 0.1945 0.07" />
        <!--      limit not work while type="continuous"-->
        <limit effort="5" lower="-1e9" upper="1e9" velocity="50" />
        <dynamics damping="0.0" friction="0.05" />
        <parent link="base_link" />
        <child link="left_back_wheel" />
    </joint>
    <!--  link  -->
    <link name="left_back_roller_0">
        <collision>
            <!--  quat_xyzw dosen't work ?! covert to rpy-->
            <origin rpy="-0.0                      0.0                      0.7853981633974484" xyz="0 0 0" />
            <geometry>
                <mesh filename="package://rm_description/meshes/common/roller.stl" scale="0.001 0.001 0.001" />
            </geometry>
        </collision>
        <inertial>
            <mass value="0.036" />
            <inertia ixx="3128e-9" ixy="0.0" ixz="0.0" iyy="3128e-9" iyz="0.0" izz="3128e-9" />
            <origin xyz="0 0 0" rpy="0 0 0" />
        </inertial>
    </link>
    <joint name="left_back_roller_0_joint" type="continuous">
        <origin rpy="0 0 0" xyz="3.7351727373994275e-18 0 -0.061000000000000006" />
        <axis xyz="0.7071067811865476 0.7071067811865476 0.0" />
        <dynamics damping="0.0" friction="0.001" />
        <parent link="left_back_wheel" />
        <child link="left_back_roller_0" />
    </joint>
    <gazebo reference="left_back_roller_0">
        <mu1 value="2000.0" />
        <mu2 value="2000.0" />
        <kp value="1000000.0" />
        <kd value="100.0" />
        <material>Gazebo/Black</material>
    </gazebo>
    <!--  link  -->
    <link name="left_back_roller_1">
        <collision>
            <!--  quat_xyzw dosen't work ?! covert to rpy-->
            <origin rpy="-0.1397561040427883                      -0.3119658732170331                      0.8374943569350152" xyz="0 0 0" />
            <geometry>
                <mesh filename="package://rm_description/meshes/common/roller.stl" scale="0.001 0.001 0.001" />
            </geometry>
        </collision>
        <inertial>
            <mass value="0.036" />
            <inertia ixx="3128e-9" ixy="0.0" ixz="0.0" iyy="3128e-9" iyz="0.0" izz="3128e-9" />
            <origin xyz="0 0 0" rpy="0 0 0" />
        </inertial>
    </link>
    <joint name="left_back_roller_1_joint" type="continuous">
        <origin rpy="0 0 0" xyz="0.0264779570502484 0 -0.0549537786730376" />
        <axis xyz="0.6370195008447469 0.7071067811865476 0.30693021282289823" />
        <dynamics damping="0.0" friction="0.001" />
        <parent link="left_back_wheel" />
        <child link="left_back_roller_1" />
    </joint>
    <gazebo reference="left_back_roller_1">
        <mu1 value="2000.0" />
        <mu2 value="2000.0" />
        <kp value="1000000.0" />
        <kd value="100.0" />
        <material>Gazebo/Black</material>
    </gazebo>
    <!--  link  -->
    <link name="left_back_roller_2">
        <collision>
            <!--  quat_xyzw dosen't work ?! covert to rpy-->
            <origin rpy="-0.33184050390145986                      -0.5859793018876829                      1.0135101754191935" xyz="0 0 0" />
            <geometry>
                <mesh filename="package://rm_description/meshes/common/roller.stl" scale="0.001 0.001 0.001" />
            </geometry>
        </collision>
        <inertial>
            <mass value="0.036" />
            <inertia ixx="3128e-9" ixy="0.0" ixz="0.0" iyy="3128e-9" iyz="0.0" izz="3128e-9" />
            <origin xyz="0 0 0" rpy="0 0 0" />
        </inertial>
    </link>
    <joint name="left_back_roller_2_joint" type="continuous">
        <origin rpy="0 0 0" xyz="0.04770700955585395 0 -0.03801369804738366" />
        <axis xyz="0.4406515355292263 0.7071067811865476 0.55301557323075" />
        <dynamics damping="0.0" friction="0.001" />
        <parent link="left_back_wheel" />
        <child link="left_back_roller_2" />
    </joint>
    <gazebo reference="left_back_roller_2">
        <mu1 value="2000.0" />
        <mu2 value="2000.0" />
        <kp value="1000000.0" />
        <kd value="100.0" />
        <material>Gazebo/Black</material>
    </gazebo>
    <!--  link  -->
    <link name="left_back_roller_3">
        <collision>
            <!--  quat_xyzw dosen't work ?! covert to rpy-->
            <origin rpy="-0.6209334157717955                      -0.760761096270827                      1.352403136081973" xyz="0 0 0" />
            <geometry>
                <mesh filename="package://rm_description/meshes/common/roller.stl" scale="0.001 0.001 0.001" />
            </geometry>
        </collision>
        <inertial>
            <mass value="0.036" />
            <inertia ixx="3128e-9" ixy="0.0" ixz="0.0" iyy="3128e-9" iyz="0.0" izz="3128e-9" />
            <origin xyz="0 0 0" rpy="0 0 0" />
        </inertial>
    </link>
    <joint name="left_back_roller_3_joint" type="continuous">
        <origin rpy="0 0 0" xyz="0.05947877882794464 0 -0.013537904902031354" />
        <axis xyz="0.15693023539811435 0.7071067811865476 0.6894729155071231" />
        <dynamics damping="0.0" friction="0.001" />
        <parent link="left_back_wheel" />
        <child link="left_back_roller_3" />
    </joint>
    <gazebo reference="left_back_roller_3">
        <mu1 value="2000.0" />
        <mu2 value="2000.0" />
        <kp value="1000000.0" />
        <kd value="100.0" />
        <material>Gazebo/Black</material>
    </gazebo>
    <!--  link  -->
    <link name="left_back_roller_4">
        <collision>
            <!--  quat_xyzw dosen't work ?! covert to rpy-->
            <origin rpy="-0.9253265685651103                      -0.7604552807523317                      1.7904967611333005" xyz="0 0 0" />
            <geometry>
                <mesh filename="package://rm_description/meshes/common/roller.stl" scale="0.001 0.001 0.001" />
            </geometry>
        </collision>
        <inertial>
            <mass value="0.036" />
            <inertia ixx="3128e-9" ixy="0.0" ixz="0.0" iyy="3128e-9" iyz="0.0" izz="3128e-9" />
            <origin xyz="0 0 0" rpy="0 0 0" />
        </inertial>
    </link>
    <joint name="left_back_roller_4_joint" type="continuous">
        <origin rpy="0 0 0" xyz="0.05945966740983209 0 0.013621598713519345" />
        <axis xyz="-0.15790040690051604 0.7071067811865476 0.6892513775834267" />
        <dynamics damping="0.0" friction="0.001" />
        <parent link="left_back_wheel" />
        <child link="left_back_roller_4" />
    </joint>
    <gazebo reference="left_back_roller_4">
        <mu1 value="2000.0" />
        <mu2 value="2000.0" />
        <kp value="1000000.0" />
        <kd value="100.0" />
        <material>Gazebo/Black</material>
    </gazebo>
    <!--  link  -->
    <link name="left_back_roller_5">
        <collision>
            <!--  quat_xyzw dosen't work ?! covert to rpy-->
            <origin rpy="-0.9952510398634623                      -0.5852345045480243                      2.1288744267289648" xyz="0 0 0" />
            <geometry>
                <mesh filename="package://rm_description/meshes/common/roller.stl" scale="0.001 0.001 0.001" />
            </geometry>
        </collision>
        <inertial>
            <mass value="0.036" />
            <inertia ixx="3128e-9" ixy="0.0" ixz="0.0" iyy="3128e-9" iyz="0.0" izz="3128e-9" />
            <origin xyz="0 0 0" rpy="0 0 0" />
        </inertial>
    </link>
    <joint name="left_back_roller_5_joint" type="continuous">
        <origin rpy="0 0 0" xyz="0.047653463887214025 0 0.038080800668446955" />
        <axis xyz="-0.44142938337167287 0.7071067811865476 0.5523948764209392" />
        <dynamics damping="0.0" friction="0.001" />
        <parent link="left_back_wheel" />
        <child link="left_back_roller_5" />
    </joint>
    <gazebo reference="left_back_roller_5">
        <mu1 value="2000.0" />
        <mu2 value="2000.0" />
        <kp value="1000000.0" />
        <kd value="100.0" />
        <material>Gazebo/Black</material>
    </gazebo>
    <!--  link  -->
    <link name="left_back_roller_6">
        <collision>
            <!--  quat_xyzw dosen't work ?! covert to rpy-->
            <origin rpy="-0.6776460855750719                      -0.3110237228468675                      2.3044349087240077" xyz="0 0 0" />
            <geometry>
                <mesh filename="package://rm_description/meshes/common/roller.stl" scale="0.001 0.001 0.001" />
            </geometry>
        </collision>
        <inertial>
            <mass value="0.036" />
            <inertia ixx="3128e-9" ixy="0.0" ixz="0.0" iyy="3128e-9" iyz="0.0" izz="3128e-9" />
            <origin xyz="0 0 0" rpy="0 0 0" />
        </inertial>
    </link>
    <joint name="left_back_roller_6_joint" type="continuous">
        <origin rpy="0 0 0" xyz="0.02640059185120231 0 0.054990987897165756" />
        <axis xyz="-0.6374508269874306 0.7071067811865476 0.30603340205448304" />
        <dynamics damping="0.0" friction="0.001" />
        <parent link="left_back_wheel" />
        <child link="left_back_roller_6" />
    </joint>
    <gazebo reference="left_back_roller_6">
        <mu1 value="2000.0" />
        <mu2 value="2000.0" />
        <kp value="1000000.0" />
        <kd value="100.0" />
        <material>Gazebo/Black</material>
    </gazebo>
    <!--  link  -->
    <link name="left_back_roller_7">
        <collision>
            <!--  quat_xyzw dosen't work ?! covert to rpy-->
            <origin rpy="0.002402487564129699                      0.0009951440258853248                      2.356193995036202" xyz="0 0 0" />
            <geometry>
                <mesh filename="package://rm_description/meshes/common/roller.stl" scale="0.001 0.001 0.001" />
            </geometry>
        </collision>
        <inertial>
            <mass value="0.036" />
            <inertia ixx="3128e-9" ixy="0.0" ixz="0.0" iyy="3128e-9" iyz="0.0" izz="3128e-9" />
            <origin xyz="0 0 0" rpy="0 0 0" />
        </inertial>
    </link>
    <joint name="left_back_roller_7_joint" type="continuous">
        <origin rpy="0 0 0" xyz="-8.584810268382325e-05 0 0.06099993959098047" />
        <axis xyz="-0.7071060809303613 0.7071067811865476 -0.0009951438616348823" />
        <dynamics damping="0.0" friction="0.001" />
        <parent link="left_back_wheel" />
        <child link="left_back_roller_7" />
    </joint>
    <gazebo reference="left_back_roller_7">
        <mu1 value="2000.0" />
        <mu2 value="2000.0" />
        <kp value="1000000.0" />
        <kd value="100.0" />
        <material>Gazebo/Black</material>
    </gazebo>
    <!--  link  -->
    <link name="left_back_roller_8">
        <collision>
            <!--  quat_xyzw dosen't work ?! covert to rpy-->
            <origin rpy="0.6809319806086911                      0.3129076709989273                      2.303760494768245" xyz="0 0 0" />
            <geometry>
                <mesh filename="package://rm_description/meshes/common/roller.stl" scale="0.001 0.001 0.001" />
            </geometry>
        </collision>
        <inertial>
            <mass value="0.036" />
            <inertia ixx="3128e-9" ixy="0.0" ixz="0.0" iyy="3128e-9" iyz="0.0" izz="3128e-9" />
            <origin xyz="0 0 0" rpy="0 0 0" />
        </inertial>
    </link>
    <joint name="left_back_roller_8_joint" type="continuous">
        <origin rpy="0 0 0" xyz="-0.026555269806428094 0 0.054916460606158964" />
        <axis xyz="-0.6365869130062115 0.7071067811865476 -0.3078264156780931" />
        <dynamics damping="0.0" friction="0.001" />
        <parent link="left_back_wheel" />
        <child link="left_back_roller_8" />
    </joint>
    <gazebo reference="left_back_roller_8">
        <mu1 value="2000.0" />
        <mu2 value="2000.0" />
        <kp value="1000000.0" />
        <kd value="100.0" />
        <material>Gazebo/Black</material>
    </gazebo>
    <!--  link  -->
    <link name="left_back_roller_9">
        <collision>
            <!--  quat_xyzw dosen't work ?! covert to rpy-->
            <origin rpy="0.9959421340702964                      0.5867231523205594                      2.127288857247016" xyz="0 0 0" />
            <geometry>
                <mesh filename="package://rm_description/meshes/common/roller.stl" scale="0.001 0.001 0.001" />
            </geometry>
        </collision>
        <inertial>
            <mass value="0.036" />
            <inertia ixx="3128e-9" ixy="0.0" ixz="0.0" iyy="3128e-9" iyz="0.0" izz="3128e-9" />
            <origin xyz="0 0 0" rpy="0 0 0" />
        </inertial>
    </link>
    <joint name="left_back_roller_9_joint" type="continuous">
        <origin rpy="0 0 0" xyz="-0.04776046073486529 0 0.03794652013549321" />
        <axis xyz="-0.43987281492195274 0.7071067811865476 -0.5536351747248702" />
        <dynamics damping="0.0" friction="0.001" />
        <parent link="left_back_wheel" />
        <child link="left_back_roller_9" />
    </joint>
    <gazebo reference="left_back_roller_9">
        <mu1 value="2000.0" />
        <mu2 value="2000.0" />
        <kp value="1000000.0" />
        <kd value="100.0" />
        <material>Gazebo/Black</material>
    </gazebo>
    <!--  link  -->
    <link name="left_back_roller_10">
        <collision>
            <!--  quat_xyzw dosen't work ?! covert to rpy-->
            <origin rpy="0.9238936146297452                      0.7610651149346043                      1.7878810957525777" xyz="0 0 0" />
            <geometry>
                <mesh filename="package://rm_description/meshes/common/roller.stl" scale="0.001 0.001 0.001" />
            </geometry>
        </collision>
        <inertial>
            <mass value="0.036" />
            <inertia ixx="3128e-9" ixy="0.0" ixz="0.0" iyy="3128e-9" iyz="0.0" izz="3128e-9" />
            <origin xyz="0 0 0" rpy="0 0 0" />
        </inertial>
    </link>
    <joint name="left_back_roller_10_joint" type="continuous">
        <origin rpy="0 0 0" xyz="-0.05949777244098466 0 0.013454184277049528" />
        <axis xyz="-0.15595975307598609 0.7071067811865476 -0.6896930878444973" />
        <dynamics damping="0.0" friction="0.001" />
        <parent link="left_back_wheel" />
        <child link="left_back_roller_10" />
    </joint>
    <gazebo reference="left_back_roller_10">
        <mu1 value="2000.0" />
        <mu2 value="2000.0" />
        <kp value="1000000.0" />
        <kd value="100.0" />
        <material>Gazebo/Black</material>
    </gazebo>
    <!--  link  -->
    <link name="left_back_roller_11">
        <collision>
            <!--  quat_xyzw dosen't work ?! covert to rpy-->
            <origin rpy="0.6188607822812026                      0.7601476705240283                      1.3497898326199715" xyz="0 0 0" />
            <geometry>
                <mesh filename="package://rm_description/meshes/common/roller.stl" scale="0.001 0.001 0.001" />
            </geometry>
        </collision>
        <inertial>
            <mass value="0.036" />
            <inertia ixx="3128e-9" ixy="0.0" ixz="0.0" iyy="3128e-9" iyz="0.0" izz="3128e-9" />
            <origin xyz="0 0 0" rpy="0 0 0" />
        </inertial>
    </link>
    <joint name="left_back_roller_11_joint" type="continuous">
        <origin rpy="0 0 0" xyz="-0.059440438224499535 0 -0.013705265545747565" />
        <axis xyz="0.15887026566164672 0.7071067811865476 -0.6890284745121915" />
        <dynamics damping="0.0" friction="0.001" />
        <parent link="left_back_wheel" />
        <child link="left_back_roller_11" />
    </joint>
    <gazebo reference="left_back_roller_11">
        <mu1 value="2000.0" />
        <mu2 value="2000.0" />
        <kp value="1000000.0" />
        <kd value="100.0" />
        <material>Gazebo/Black</material>
    </gazebo>
    <!--  link  -->
    <link name="left_back_roller_12">
        <collision>
            <!--  quat_xyzw dosen't work ?! covert to rpy-->
            <origin rpy="0.33035697597807884                      0.5844887627649618                      1.0119279494343745" xyz="0 0 0" />
            <geometry>
                <mesh filename="package://rm_description/meshes/common/roller.stl" scale="0.001 0.001 0.001" />
            </geometry>
        </collision>
        <inertial>
            <mass value="0.036" />
            <inertia ixx="3128e-9" ixy="0.0" ixz="0.0" iyy="3128e-9" iyz="0.0" izz="3128e-9" />
            <origin xyz="0 0 0" rpy="0 0 0" />
        </inertial>
    </link>
    <joint name="left_back_roller_12_joint" type="continuous">
        <origin rpy="0 0 0" xyz="-0.04759982383499931 0 -0.03814782786577804" />
        <axis xyz="0.4422063569086687 0.7071067811865476 -0.5517730855248045" />
        <dynamics damping="0.0" friction="0.001" />
        <parent link="left_back_wheel" />
        <child link="left_back_roller_12" />
    </joint>
    <gazebo reference="left_back_roller_12">
        <mu1 value="2000.0" />
        <mu2 value="2000.0" />
        <kp value="1000000.0" />
        <kd value="100.0" />
        <material>Gazebo/Black</material>
    </gazebo>
    <!--  link  -->
    <link name="left_back_roller_13">
        <collision>
            <!--  quat_xyzw dosen't work ?! covert to rpy-->
            <origin rpy="0.13877562966172519                      0.3100812212384385                      0.8368223213782329" xyz="0 0 0" />
            <geometry>
                <mesh filename="package://rm_description/meshes/common/roller.stl" scale="0.001 0.001 0.001" />
            </geometry>
        </collision>
        <inertial>
            <mass value="0.036" />
            <inertia ixx="3128e-9" ixy="0.0" ixz="0.0" iyy="3128e-9" iyz="0.0" izz="3128e-9" />
            <origin xyz="0 0 0" rpy="0 0 0" />
        </inertial>
    </link>
    <joint name="left_back_roller_13_joint" type="continuous">
        <origin rpy="0 0 0" xyz="-0.0263231743625212 0 -0.05502808820484596" />
        <axis xyz="0.637880890579968 0.7071067811865476 -0.30513598514909207" />
        <dynamics damping="0.0" friction="0.001" />
        <parent link="left_back_wheel" />
        <child link="left_back_roller_13" />
    </joint>
    <gazebo reference="left_back_roller_13">
        <mu1 value="2000.0" />
        <mu2 value="2000.0" />
        <kp value="1000000.0" />
        <kd value="100.0" />
        <material>Gazebo/Black</material>
    </gazebo>
    <!--  link  -->
    <link name="right_back_wheel">
        <visual>
            <geometry>
                <mesh filename="package://rm_description/meshes/common/right_threaded_14roller_mecanum_wheel.stl" />
            </geometry>
        </visual>
        <inertial>
            <mass value="1.613177" />
            <inertia ixx="1.416e-3" ixy="0.0" ixz="0.0" iyy="2.749e-3" iyz="0.0" izz="1.416e-3" />
        </inertial>
    </link>
    <!--  joint  -->
    <joint name="right_back_wheel_joint" type="revolute">
        <axis xyz="0 1 0" />
        <origin rpy="0 0 0" xyz="-0.213 -0.1945 0.07" />
        <!--      limit not work while type="continuous"-->
        <limit effort="5" lower="-1e9" upper="1e9" velocity="50" />
        <dynamics damping="0.0" friction="0.05" />
        <parent link="base_link" />
        <child link="right_back_wheel" />
    </joint>
    <!--  link  -->
    <link name="right_back_roller_0">
        <collision>
            <!--  quat_xyzw dosen't work ?! covert to rpy-->
            <origin rpy="0.0                      -0.0                      -0.7853981633974484" xyz="0 0 0" />
            <geometry>
                <mesh filename="package://rm_description/meshes/common/roller.stl" scale="0.001 0.001 0.001" />
            </geometry>
        </collision>
        <inertial>
            <mass value="0.036" />
            <inertia ixx="3128e-9" ixy="0.0" ixz="0.0" iyy="3128e-9" iyz="0.0" izz="3128e-9" />
            <origin xyz="0 0 0" rpy="0 0 0" />
        </inertial>
    </link>
    <joint name="right_back_roller_0_joint" type="continuous">
        <origin rpy="0 0 0" xyz="3.7351727373994275e-18 0 -0.061000000000000006" />
        <axis xyz="0.7071067811865476 -0.7071067811865476 0.0" />
        <dynamics damping="0.0" friction="0.001" />
        <parent link="right_back_wheel" />
        <child link="right_back_roller_0" />
    </joint>
    <gazebo reference="right_back_roller_0">
        <mu1 value="2000.0" />
        <mu2 value="2000.0" />
        <kp value="1000000.0" />
        <kd value="100.0" />
        <material>Gazebo/Black</material>
    </gazebo>
    <!--  link  -->
    <link name="right_back_roller_1">
        <collision>
            <!--  quat_xyzw dosen't work ?! covert to rpy-->
            <origin rpy="0.1397561040427883                      -0.3119658732170331                      -0.8374943569350152" xyz="0 0 0" />
            <geometry>
                <mesh filename="package://rm_description/meshes/common/roller.stl" scale="0.001 0.001 0.001" />
            </geometry>
        </collision>
        <inertial>
            <mass value="0.036" />
            <inertia ixx="3128e-9" ixy="0.0" ixz="0.0" iyy="3128e-9" iyz="0.0" izz="3128e-9" />
            <origin xyz="0 0 0" rpy="0 0 0" />
        </inertial>
    </link>
    <joint name="right_back_roller_1_joint" type="continuous">
        <origin rpy="0 0 0" xyz="0.0264779570502484 0 -0.0549537786730376" />
        <axis xyz="0.6370195008447469 -0.7071067811865476 0.30693021282289823" />
        <dynamics damping="0.0" friction="0.001" />
        <parent link="right_back_wheel" />
        <child link="right_back_roller_1" />
    </joint>
    <gazebo reference="right_back_roller_1">
        <mu1 value="2000.0" />
        <mu2 value="2000.0" />
        <kp value="1000000.0" />
        <kd value="100.0" />
        <material>Gazebo/Black</material>
    </gazebo>
    <!--  link  -->
    <link name="right_back_roller_2">
        <collision>
            <!--  quat_xyzw dosen't work ?! covert to rpy-->
            <origin rpy="0.33184050390145986                      -0.5859793018876829                      -1.0135101754191935" xyz="0 0 0" />
            <geometry>
                <mesh filename="package://rm_description/meshes/common/roller.stl" scale="0.001 0.001 0.001" />
            </geometry>
        </collision>
        <inertial>
            <mass value="0.036" />
            <inertia ixx="3128e-9" ixy="0.0" ixz="0.0" iyy="3128e-9" iyz="0.0" izz="3128e-9" />
            <origin xyz="0 0 0" rpy="0 0 0" />
        </inertial>
    </link>
    <joint name="right_back_roller_2_joint" type="continuous">
        <origin rpy="0 0 0" xyz="0.04770700955585395 0 -0.03801369804738366" />
        <axis xyz="0.4406515355292263 -0.7071067811865476 0.55301557323075" />
        <dynamics damping="0.0" friction="0.001" />
        <parent link="right_back_wheel" />
        <child link="right_back_roller_2" />
    </joint>
    <gazebo reference="right_back_roller_2">
        <mu1 value="2000.0" />
        <mu2 value="2000.0" />
        <kp value="1000000.0" />
        <kd value="100.0" />
        <material>Gazebo/Black</material>
    </gazebo>
    <!--  link  -->
    <link name="right_back_roller_3">
        <collision>
            <!--  quat_xyzw dosen't work ?! covert to rpy-->
            <origin rpy="0.6209334157717955                      -0.760761096270827                      -1.352403136081973" xyz="0 0 0" />
            <geometry>
                <mesh filename="package://rm_description/meshes/common/roller.stl" scale="0.001 0.001 0.001" />
            </geometry>
        </collision>
        <inertial>
            <mass value="0.036" />
            <inertia ixx="3128e-9" ixy="0.0" ixz="0.0" iyy="3128e-9" iyz="0.0" izz="3128e-9" />
            <origin xyz="0 0 0" rpy="0 0 0" />
        </inertial>
    </link>
    <joint name="right_back_roller_3_joint" type="continuous">
        <origin rpy="0 0 0" xyz="0.05947877882794464 0 -0.013537904902031354" />
        <axis xyz="0.15693023539811435 -0.7071067811865476 0.6894729155071231" />
        <dynamics damping="0.0" friction="0.001" />
        <parent link="right_back_wheel" />
        <child link="right_back_roller_3" />
    </joint>
    <gazebo reference="right_back_roller_3">
        <mu1 value="2000.0" />
        <mu2 value="2000.0" />
        <kp value="1000000.0" />
        <kd value="100.0" />
        <material>Gazebo/Black</material>
    </gazebo>
    <!--  link  -->
    <link name="right_back_roller_4">
        <collision>
            <!--  quat_xyzw dosen't work ?! covert to rpy-->
            <origin rpy="0.9253265685651103                      -0.7604552807523317                      -1.7904967611333005" xyz="0 0 0" />
            <geometry>
                <mesh filename="package://rm_description/meshes/common/roller.stl" scale="0.001 0.001 0.001" />
            </geometry>
        </collision>
        <inertial>
            <mass value="0.036" />
            <inertia ixx="3128e-9" ixy="0.0" ixz="0.0" iyy="3128e-9" iyz="0.0" izz="3128e-9" />
            <origin xyz="0 0 0" rpy="0 0 0" />
        </inertial>
    </link>
    <joint name="right_back_roller_4_joint" type="continuous">
        <origin rpy="0 0 0" xyz="0.05945966740983209 0 0.013621598713519345" />
        <axis xyz="-0.15790040690051604 -0.7071067811865476 0.6892513775834267" />
        <dynamics damping="0.0" friction="0.001" />
        <parent link="right_back_wheel" />
        <child link="right_back_roller_4" />
    </joint>
    <gazebo reference="right_back_roller_4">
        <mu1 value="2000.0" />
        <mu2 value="2000.0" />
        <kp value="1000000.0" />
        <kd value="100.0" />
        <material>Gazebo/Black</material>
    </gazebo>
    <!--  link  -->
    <link name="right_back_roller_5">
        <collision>
            <!--  quat_xyzw dosen't work ?! covert to rpy-->
            <origin rpy="0.9952510398634623                      -0.5852345045480243                      -2.1288744267289648" xyz="0 0 0" />
            <geometry>
                <mesh filename="package://rm_description/meshes/common/roller.stl" scale="0.001 0.001 0.001" />
            </geometry>
        </collision>
        <inertial>
            <mass value="0.036" />
            <inertia ixx="3128e-9" ixy="0.0" ixz="0.0" iyy="3128e-9" iyz="0.0" izz="3128e-9" />
            <origin xyz="0 0 0" rpy="0 0 0" />
        </inertial>
    </link>
    <joint name="right_back_roller_5_joint" type="continuous">
        <origin rpy="0 0 0" xyz="0.047653463887214025 0 0.038080800668446955" />
        <axis xyz="-0.44142938337167287 -0.7071067811865476 0.5523948764209392" />
        <dynamics damping="0.0" friction="0.001" />
        <parent link="right_back_wheel" />
        <child link="right_back_roller_5" />
    </joint>
    <gazebo reference="right_back_roller_5">
        <mu1 value="2000.0" />
        <mu2 value="2000.0" />
        <kp value="1000000.0" />
        <kd value="100.0" />
        <material>Gazebo/Black</material>
    </gazebo>
    <!--  link  -->
    <link name="right_back_roller_6">
        <collision>
            <!--  quat_xyzw dosen't work ?! covert to rpy-->
            <origin rpy="0.6776460855750719                      -0.3110237228468675                      -2.3044349087240077" xyz="0 0 0" />
            <geometry>
                <mesh filename="package://rm_description/meshes/common/roller.stl" scale="0.001 0.001 0.001" />
            </geometry>
        </collision>
        <inertial>
            <mass value="0.036" />
            <inertia ixx="3128e-9" ixy="0.0" ixz="0.0" iyy="3128e-9" iyz="0.0" izz="3128e-9" />
            <origin xyz="0 0 0" rpy="0 0 0" />
        </inertial>
    </link>
    <joint name="right_back_roller_6_joint" type="continuous">
        <origin rpy="0 0 0" xyz="0.02640059185120231 0 0.054990987897165756" />
        <axis xyz="-0.6374508269874306 -0.7071067811865476 0.30603340205448304" />
        <dynamics damping="0.0" friction="0.001" />
        <parent link="right_back_wheel" />
        <child link="right_back_roller_6" />
    </joint>
    <gazebo reference="right_back_roller_6">
        <mu1 value="2000.0" />
        <mu2 value="2000.0" />
        <kp value="1000000.0" />
        <kd value="100.0" />
        <material>Gazebo/Black</material>
    </gazebo>
    <!--  link  -->
    <link name="right_back_roller_7">
        <collision>
            <!--  quat_xyzw dosen't work ?! covert to rpy-->
            <origin rpy="-0.002402487564129699                      0.0009951440258853248                      -2.356193995036202" xyz="0 0 0" />
            <geometry>
                <mesh filename="package://rm_description/meshes/common/roller.stl" scale="0.001 0.001 0.001" />
            </geometry>
        </collision>
        <inertial>
            <mass value="0.036" />
            <inertia ixx="3128e-9" ixy="0.0" ixz="0.0" iyy="3128e-9" iyz="0.0" izz="3128e-9" />
            <origin xyz="0 0 0" rpy="0 0 0" />
        </inertial>
    </link>
    <joint name="right_back_roller_7_joint" type="continuous">
        <origin rpy="0 0 0" xyz="-8.584810268382325e-05 0 0.06099993959098047" />
        <axis xyz="-0.7071060809303613 -0.7071067811865476 -0.0009951438616348823" />
        <dynamics damping="0.0" friction="0.001" />
        <parent link="right_back_wheel" />
        <child link="right_back_roller_7" />
    </joint>
    <gazebo reference="right_back_roller_7">
        <mu1 value="2000.0" />
        <mu2 value="2000.0" />
        <kp value="1000000.0" />
        <kd value="100.0" />
        <material>Gazebo/Black</material>
    </gazebo>
    <!--  link  -->
    <link name="right_back_roller_8">
        <collision>
            <!--  quat_xyzw dosen't work ?! covert to rpy-->
            <origin rpy="-0.6809319806086911                      0.3129076709989273                      -2.303760494768245" xyz="0 0 0" />
            <geometry>
                <mesh filename="package://rm_description/meshes/common/roller.stl" scale="0.001 0.001 0.001" />
            </geometry>
        </collision>
        <inertial>
            <mass value="0.036" />
            <inertia ixx="3128e-9" ixy="0.0" ixz="0.0" iyy="3128e-9" iyz="0.0" izz="3128e-9" />
            <origin xyz="0 0 0" rpy="0 0 0" />
        </inertial>
    </link>
    <joint name="right_back_roller_8_joint" type="continuous">
        <origin rpy="0 0 0" xyz="-0.026555269806428094 0 0.054916460606158964" />
        <axis xyz="-0.6365869130062115 -0.7071067811865476 -0.3078264156780931" />
        <dynamics damping="0.0" friction="0.001" />
        <parent link="right_back_wheel" />
        <child link="right_back_roller_8" />
    </joint>
    <gazebo reference="right_back_roller_8">
        <mu1 value="2000.0" />
        <mu2 value="2000.0" />
        <kp value="1000000.0" />
        <kd value="100.0" />
        <material>Gazebo/Black</material>
    </gazebo>
    <!--  link  -->
    <link name="right_back_roller_9">
        <collision>
            <!--  quat_xyzw dosen't work ?! covert to rpy-->
            <origin rpy="-0.9959421340702964                      0.5867231523205594                      -2.127288857247016" xyz="0 0 0" />
            <geometry>
                <mesh filename="package://rm_description/meshes/common/roller.stl" scale="0.001 0.001 0.001" />
            </geometry>
        </collision>
        <inertial>
            <mass value="0.036" />
            <inertia ixx="3128e-9" ixy="0.0" ixz="0.0" iyy="3128e-9" iyz="0.0" izz="3128e-9" />
            <origin xyz="0 0 0" rpy="0 0 0" />
        </inertial>
    </link>
    <joint name="right_back_roller_9_joint" type="continuous">
        <origin rpy="0 0 0" xyz="-0.04776046073486529 0 0.03794652013549321" />
        <axis xyz="-0.43987281492195274 -0.7071067811865476 -0.5536351747248702" />
        <dynamics damping="0.0" friction="0.001" />
        <parent link="right_back_wheel" />
        <child link="right_back_roller_9" />
    </joint>
    <gazebo reference="right_back_roller_9">
        <mu1 value="2000.0" />
        <mu2 value="2000.0" />
        <kp value="1000000.0" />
        <kd value="100.0" />
        <material>Gazebo/Black</material>
    </gazebo>
    <!--  link  -->
    <link name="right_back_roller_10">
        <collision>
            <!--  quat_xyzw dosen't work ?! covert to rpy-->
            <origin rpy="-0.9238936146297452                      0.7610651149346043                      -1.7878810957525777" xyz="0 0 0" />
            <geometry>
                <mesh filename="package://rm_description/meshes/common/roller.stl" scale="0.001 0.001 0.001" />
            </geometry>
        </collision>
        <inertial>
            <mass value="0.036" />
            <inertia ixx="3128e-9" ixy="0.0" ixz="0.0" iyy="3128e-9" iyz="0.0" izz="3128e-9" />
            <origin xyz="0 0 0" rpy="0 0 0" />
        </inertial>
    </link>
    <joint name="right_back_roller_10_joint" type="continuous">
        <origin rpy="0 0 0" xyz="-0.05949777244098466 0 0.013454184277049528" />
        <axis xyz="-0.15595975307598609 -0.7071067811865476 -0.6896930878444973" />
        <dynamics damping="0.0" friction="0.001" />
        <parent link="right_back_wheel" />
        <child link="right_back_roller_10" />
    </joint>
    <gazebo reference="right_back_roller_10">
        <mu1 value="2000.0" />
        <mu2 value="2000.0" />
        <kp value="1000000.0" />
        <kd value="100.0" />
        <material>Gazebo/Black</material>
    </gazebo>
    <!--  link  -->
    <link name="right_back_roller_11">
        <collision>
            <!--  quat_xyzw dosen't work ?! covert to rpy-->
            <origin rpy="-0.6188607822812026                      0.7601476705240283                      -1.3497898326199715" xyz="0 0 0" />
            <geometry>
                <mesh filename="package://rm_description/meshes/common/roller.stl" scale="0.001 0.001 0.001" />
            </geometry>
        </collision>
        <inertial>
            <mass value="0.036" />
            <inertia ixx="3128e-9" ixy="0.0" ixz="0.0" iyy="3128e-9" iyz="0.0" izz="3128e-9" />
            <origin xyz="0 0 0" rpy="0 0 0" />
        </inertial>
    </link>
    <joint name="right_back_roller_11_joint" type="continuous">
        <origin rpy="0 0 0" xyz="-0.059440438224499535 0 -0.013705265545747565" />
        <axis xyz="0.15887026566164672 -0.7071067811865476 -0.6890284745121915" />
        <dynamics damping="0.0" friction="0.001" />
        <parent link="right_back_wheel" />
        <child link="right_back_roller_11" />
    </joint>
    <gazebo reference="right_back_roller_11">
        <mu1 value="2000.0" />
        <mu2 value="2000.0" />
        <kp value="1000000.0" />
        <kd value="100.0" />
        <material>Gazebo/Black</material>
    </gazebo>
    <!--  link  -->
    <link name="right_back_roller_12">
        <collision>
            <!--  quat_xyzw dosen't work ?! covert to rpy-->
            <origin rpy="-0.33035697597807884                      0.5844887627649618                      -1.0119279494343745" xyz="0 0 0" />
            <geometry>
                <mesh filename="package://rm_description/meshes/common/roller.stl" scale="0.001 0.001 0.001" />
            </geometry>
        </collision>
        <inertial>
            <mass value="0.036" />
            <inertia ixx="3128e-9" ixy="0.0" ixz="0.0" iyy="3128e-9" iyz="0.0" izz="3128e-9" />
            <origin xyz="0 0 0" rpy="0 0 0" />
        </inertial>
    </link>
    <joint name="right_back_roller_12_joint" type="continuous">
        <origin rpy="0 0 0" xyz="-0.04759982383499931 0 -0.03814782786577804" />
        <axis xyz="0.4422063569086687 -0.7071067811865476 -0.5517730855248045" />
        <dynamics damping="0.0" friction="0.001" />
        <parent link="right_back_wheel" />
        <child link="right_back_roller_12" />
    </joint>
    <gazebo reference="right_back_roller_12">
        <mu1 value="2000.0" />
        <mu2 value="2000.0" />
        <kp value="1000000.0" />
        <kd value="100.0" />
        <material>Gazebo/Black</material>
    </gazebo>
    <!--  link  -->
    <link name="right_back_roller_13">
        <collision>
            <!--  quat_xyzw dosen't work ?! covert to rpy-->
            <origin rpy="-0.13877562966172519                      0.3100812212384385                      -0.8368223213782329" xyz="0 0 0" />
            <geometry>
                <mesh filename="package://rm_description/meshes/common/roller.stl" scale="0.001 0.001 0.001" />
            </geometry>
        </collision>
        <inertial>
            <mass value="0.036" />
            <inertia ixx="3128e-9" ixy="0.0" ixz="0.0" iyy="3128e-9" iyz="0.0" izz="3128e-9" />
            <origin xyz="0 0 0" rpy="0 0 0" />
        </inertial>
    </link>
    <joint name="right_back_roller_13_joint" type="continuous">
        <origin rpy="0 0 0" xyz="-0.0263231743625212 0 -0.05502808820484596" />
        <axis xyz="0.637880890579968 -0.7071067811865476 -0.30513598514909207" />
        <dynamics damping="0.0" friction="0.001" />
        <parent link="right_back_wheel" />
        <child link="right_back_roller_13" />
    </joint>
    <gazebo reference="right_back_roller_13">
        <mu1 value="2000.0" />
        <mu2 value="2000.0" />
        <kp value="1000000.0" />
        <kd value="100.0" />
        <material>Gazebo/Black</material>
    </gazebo>
    <transmission name="left_front_wheel_trans">
        <type>transmission_interface/SimpleTransmission</type>
        <actuator name="left_front_wheel_motor">
            <hardwareInterface>hardware_interface/EffortJointInterface</hardwareInterface>
            <mechanicalReduction>19.2032</mechanicalReduction>
        </actuator>
        <joint name="left_front_wheel_joint">
            <hardwareInterface>hardware_interface/EffortJointInterface</hardwareInterface>
        </joint>
    </transmission>
    <transmission name="right_front_wheel_trans">
        <type>transmission_interface/SimpleTransmission</type>
        <actuator name="right_front_wheel_motor">
            <hardwareInterface>hardware_interface/EffortJointInterface</hardwareInterface>
            <mechanicalReduction>-19.2032</mechanicalReduction>
        </actuator>
        <joint name="right_front_wheel_joint">
            <hardwareInterface>hardware_interface/EffortJointInterface</hardwareInterface>
        </joint>
    </transmission>
    <transmission name="left_back_wheel_trans">
        <type>transmission_interface/SimpleTransmission</type>
        <actuator name="left_back_wheel_motor">
            <hardwareInterface>hardware_interface/EffortJointInterface</hardwareInterface>
            <mechanicalReduction>19.2032</mechanicalReduction>
        </actuator>
        <joint name="left_back_wheel_joint">
            <hardwareInterface>hardware_interface/EffortJointInterface</hardwareInterface>
        </joint>
    </transmission>
    <transmission name="right_back_wheel_trans">
        <type>transmission_interface/SimpleTransmission</type>
        <actuator name="right_back_wheel_motor">
            <hardwareInterface>hardware_interface/EffortJointInterface</hardwareInterface>
            <mechanicalReduction>-19.2032</mechanicalReduction>
        </actuator>
        <joint name="right_back_wheel_joint">
            <hardwareInterface>hardware_interface/EffortJointInterface</hardwareInterface>
        </joint>
    </transmission>
    <!--  link  -->
    <link name="link1">
        <visual>
            <origin rpy="0 0 0" xyz="0 0 0" />
            <geometry>
                <mesh filename="package://rm_description/meshes/engineer2/link1.stl" />
            </geometry>
        </visual>
        <inertial>
            <mass value="2.49351" />
            <origin xyz="0.046738  -0.154238  0.018292 " rpy="0 0 0" />
            <inertia ixx="2.140e-2" ixy="3.902e-3" ixz="7.061e-4" iyy="7.823e-3" iyz="3.525e-4" izz="2.238e-2" />
        </inertial>
        <collision>
            <geometry>
                <mesh filename="package://rm_description/meshes/engineer2/link1.stl" />
            </geometry>
        </collision>
    </link>
    <link name="link2">
        <visual>
            <origin rpy="0 0 0" xyz="0 0 0" />
            <geometry>
                <mesh filename="package://rm_description/meshes/engineer2/link2.stl" />
            </geometry>
        </visual>
        <inertial>
            <mass value="0.601539" />
            <origin xyz="0.225614  -0.000046  0.016881 " rpy="0 0 0" />
            <inertia ixx="3.293e-4" ixy="1.357375e-6" ixz="1.603e-4" iyy="5.129e-3" iyz="-0.773379e-6" izz="5.089e-3" />
        </inertial>
        <collision>
            <geometry>
                <mesh filename="package://rm_description/meshes/engineer2/link2.stl" />
            </geometry>
        </collision>
    </link>
    <link name="link3">
        <visual>
            <origin rpy="0 0 0" xyz="0 0 0.0" />
            <geometry>
                <mesh filename="package://rm_description/meshes/engineer2/link3.stl" />
            </geometry>
        </visual>
        <inertial>
            <mass value="1.031279" />
            <origin xyz="0.097823  0.01004 0.063108 " rpy="0 0 0" />
            <origin xyz="0. 0. 0." />
            <inertia ixx="7.709e-4" ixy="-2.296e-4" ixz="-2.126e-4" iyy="1.409e-3" iyz="-5.6694522e-5" izz="1.598e-3" />
        </inertial>
        <collision>
            <origin rpy="0. 0. 0." xyz="0. 0. 0." />
            <geometry>
                <mesh filename="package://rm_description/meshes/engineer2/link3.stl" />
            </geometry>
        </collision>
    </link>
    <link name="link4">
        <visual>
            <origin rpy="0 0 0" xyz="0 0 0" />
            <geometry>
                <mesh filename="package://rm_description/meshes/engineer2/link4.stl" />
            </geometry>
        </visual>
        <inertial>
            <mass value="0.874408" />
            <origin xyz="0.047821  0.00001  0.000115" rpy="0 0 0" />
            <inertia ixx="1.089e-3" ixy="0.335543e-6" ixz="-3.021042e-6" iyy="7.983e-4" iyz="5.1665e-8" izz="1.568e-3" />
        </inertial>
        <collision>
            <origin rpy="0. 0. 0." xyz="0. 0. 0" />
            <geometry>
                <mesh filename="package://rm_description/meshes/engineer2/link4.stl" />
            </geometry>
        </collision>
    </link>
    <link name="link5">
        <visual>
            <origin rpy="0 0 0" xyz="0. 0. 0." />
            <geometry>
                <mesh filename="package://rm_description/meshes/engineer2/link5.stl" />
            </geometry>
        </visual>
        <inertial>
            <mass value="0.093643" />
            <origin xyz="0.015715  -0.001439  -0.000004 " rpy="0 0 0" />
            <inertia ixx="1.235e-4" ixy="1.570201e-6" ixz="-3.038e-9" iyy="5.1654282e-5" iyz="0.723e-9" izz="1.220e-4" />
        </inertial>
        <collision>
            <origin rpy="0. 0. 0." xyz="0. 0.0 0." />
            <geometry>
                <mesh filename="package://rm_description/meshes/engineer2/link5.stl" />
            </geometry>
        </collision>
    </link>
    <link name="link6">
        <visual>
            <origin rpy="0 0 0" xyz="0. 0. 0." />
            <geometry>
                <mesh filename="package://rm_description/meshes/engineer2/link6.stl" />
            </geometry>
        </visual>
        <inertial>
            <mass value="0.23135" />
            <origin xyz="-0.00304 0. -0.000003" rpy="0 0 0" />
            <inertia ixx="7.760144e-5" ixy="0.01e-9" ixz="0.088e-9" iyy="6.5932798e-5" iyz="-0.008e-9" izz="6.5988593e-5" />
        </inertial>
        <collision>
            <origin rpy="0. 0. 0." xyz="0. 0. 0." />
            <geometry>
                <mesh filename="package://rm_description/meshes/engineer2/link6.stl" />
            </geometry>
        </collision>
    </link>
    <link name="fake_link4">
        <inertial>
            <mass value="0.0001" />
            <origin xyz="0 0 0" />
            <inertia ixx="1.0e-8" ixy="0" ixz="0" iyy="1.0e-8" iyz="0" izz="1.0e-8" />
        </inertial>
        <visual>
            <origin rpy="0 0 0" xyz="0 0 0" />
            <geometry>
                <mesh filename="package://rm_description/meshes/engineer2/fake_link4.stl" />
            </geometry>
        </visual>
    </link>
    <joint name="joint1" type="prismatic">
        <parent link="base_link" />
        <child link="link1" />
        <origin rpy="0 0 0" xyz="0. 0. 0.260" />
        <axis xyz="0 0 1" />
        <limit effort="1000" lower="0" upper="0.3" velocity="2.25" />
        <dynamics damping="0.0" friction="0.1" />
    </joint>
    <joint name="joint2" type="revolute">
        <parent link="link1" />
        <child link="link2" />
        <origin rpy="0 0 0" xyz="0.082 -0.2 0." />
        <axis xyz="0 0 1" />
        <limit effort="40" lower="-1.2" upper="1.2" velocity="10.46" />
        <dynamics damping="0.0" friction="0.1" />
    </joint>
    <joint name="joint3" type="revolute">
        <parent link="link2" />
        <child link="link3" />
        <origin rpy="0 0 0" xyz="0.275 0. 0." />
        <axis xyz="0 0 1" />
        <limit effort="25" lower="-1.2" upper="1.2" velocity="3.76" />
        <dynamics damping="0.0" friction="0.1" />
    </joint>
    <joint name="joint4" type="revolute">
        <parent link="link3" />
        <child link="link4" />
        <origin rpy="0 0 0" xyz="0.153 0. 0.086605" />
        <axis xyz="1 0 0" />
        <limit effort="7" lower="-3.14" upper="3.14" velocity="20.94" />
        <dynamics damping="0.0" friction="0.1" />
    </joint>
    <joint name="joint5" type="revolute">
        <parent link="link4" />
        <child link="link5" />
        <origin rpy="0 0 0" xyz="0.1055 0.0 0." />
        <axis xyz="0 1 0" />
        <limit effort="14" lower="-1.57" upper="1.57" velocity="10" />
        <dynamics damping="0.0" friction="0.1" />
    </joint>
    <joint name="joint6" type="revolute">
        <parent link="link5" />
        <child link="link6" />
        <origin rpy="0 0 0" xyz="0.026183 0 0" />
        <axis xyz="1 0 0" />
        <limit effort="14" lower="-6" upper="6" velocity="10" />
        <dynamics damping="0.0" friction="0.1" />
    </joint>
    <joint name="middle_pitch" type="revolute">
        <parent link="link3" />
        <child link="fake_link4" />
        <origin rpy="0 0 0" xyz="0.0 0 0" />
        <axis xyz="1 0 0" />
        <limit effort="25" lower="0" upper="1.57" velocity="3.76" />
        <dynamics damping="0.0" friction="0.1" />
    </joint>
    <!-- transmission -->
    <transmission name="trans_joint1">
        <type>transmission_interface/SimpleTransmission</type>
        <actuator name="joint1_motor">
            <mechanicalReduction>421.49</mechanicalReduction>
            <hardwareInterface>hardware_interface/EffortJointInterface</hardwareInterface>
        </actuator>
        <joint name="joint1">
            <hardwareInterface>hardware_interface/EffortJointInterface</hardwareInterface>
            <offset>0.</offset>
        </joint>
    </transmission>
    <transmission name="trans_joint2">
        <type>transmission_interface/SimpleTransmission</type>
        <actuator name="joint2_motor">
            <mechanicalReduction>1</mechanicalReduction>
            <hardwareInterface>hardware_interface/EffortJointInterface</hardwareInterface>
        </actuator>
        <joint name="joint2">
            <hardwareInterface>hardware_interface/EffortJointInterface</hardwareInterface>
            <offset>0.</offset>
        </joint>
    </transmission>
    <transmission name="trans_joint3">
        <type>transmission_interface/SimpleTransmission</type>
        <actuator name="joint3_motor">
            <mechanicalReduction>1</mechanicalReduction>
            <hardwareInterface>hardware_interface/EffortJointInterface</hardwareInterface>
        </actuator>
        <joint name="joint3">
            <hardwareInterface>hardware_interface/EffortJointInterface</hardwareInterface>
            <offset>0</offset>
        </joint>
    </transmission>
    <transmission name="trans_joint4">
        <type>transmission_interface/SimpleTransmission</type>
        <actuator name="joint4_motor">
            <mechanicalReduction>1</mechanicalReduction>
            <hardwareInterface>hardware_interface/EffortJointInterface</hardwareInterface>
        </actuator>
        <joint name="joint4">
            <hardwareInterface>hardware_interface/EffortJointInterface</hardwareInterface>
            <offset>0</offset>
        </joint>
    </transmission>
    <transmission name="trans_diff_ee">
        <type>transmission_interface/DifferentialTransmission</type>
        <actuator name="left_diff_motor">
            <role>actuator1</role>
            <mechanicalReduction>1</mechanicalReduction>
        </actuator>
        <actuator name="right_diff_motor">
            <role>actuator2</role>
            <mechanicalReduction>1</mechanicalReduction>
        </actuator>
        <joint name="joint5">
            <hardwareInterface>hardware_interface/EffortJointInterface</hardwareInterface>
            <offset>0</offset>
            <role>joint1</role>
        </joint>
        <joint name="joint6">
            <hardwareInterface>hardware_interface/EffortJointInterface</hardwareInterface>
            <offset>0</offset>
            <role>joint2</role>
        </joint>
    </transmission>
    <!--        <xacro:unless value="$(arg use_simulation)">-->
    <!--            <xacro:include filename="$(find rm_description)/urdf/common/camera.urdf.xacro"/>-->
    <!--            <xacro:camera_sensor xyz="-0.0232 0 0.3765" rpy="0. 0. 0." frame_id="$(arg camera_link)" parent="gimbal_lifter"-->
    <!--                                 camera_sim="$(arg use_simulation)" camera_type="hk_camera"/>-->
    <!--            <xacro:camera_optical_frame xyz="0.0035 0. 0.3765" rpy="-1.570796 0. -1.570796"-->
    <!--                                        frame_id="$(arg camera_optical_frame)" parent="gimbal_lifter"-->
    <!--                                        camera_sim="$(arg use_simulation)"/>-->
    <!--        </xacro:unless>-->
    <transmission name="trans_left_front_roller_0_joint">
        <type>transmission_interface/SimpleTransmission</type>
        <joint name="left_front_roller_0_joint">
            <hardwareInterface>hardware_interface/EffortJointInterface</hardwareInterface>
        </joint>
        <actuator name="left_front_roller_0_joint_motor">
            <hardwareInterface>hardware_interface/EffortJointInterface</hardwareInterface>
            <mechanicalReduction>1</mechanicalReduction>
        </actuator>
    </transmission>
    <transmission name="trans_left_front_roller_1_joint">
        <type>transmission_interface/SimpleTransmission</type>
        <joint name="left_front_roller_1_joint">
            <hardwareInterface>hardware_interface/EffortJointInterface</hardwareInterface>
        </joint>
        <actuator name="left_front_roller_1_joint_motor">
            <hardwareInterface>hardware_interface/EffortJointInterface</hardwareInterface>
            <mechanicalReduction>1</mechanicalReduction>
        </actuator>
    </transmission>
    <transmission name="trans_left_front_roller_2_joint">
        <type>transmission_interface/SimpleTransmission</type>
        <joint name="left_front_roller_2_joint">
            <hardwareInterface>hardware_interface/EffortJointInterface</hardwareInterface>
        </joint>
        <actuator name="left_front_roller_2_joint_motor">
            <hardwareInterface>hardware_interface/EffortJointInterface</hardwareInterface>
            <mechanicalReduction>1</mechanicalReduction>
        </actuator>
    </transmission>
    <transmission name="trans_left_front_roller_3_joint">
        <type>transmission_interface/SimpleTransmission</type>
        <joint name="left_front_roller_3_joint">
            <hardwareInterface>hardware_interface/EffortJointInterface</hardwareInterface>
        </joint>
        <actuator name="left_front_roller_3_joint_motor">
            <hardwareInterface>hardware_interface/EffortJointInterface</hardwareInterface>
            <mechanicalReduction>1</mechanicalReduction>
        </actuator>
    </transmission>
    <transmission name="trans_left_front_roller_4_joint">
        <type>transmission_interface/SimpleTransmission</type>
        <joint name="left_front_roller_4_joint">
            <hardwareInterface>hardware_interface/EffortJointInterface</hardwareInterface>
        </joint>
        <actuator name="left_front_roller_4_joint_motor">
            <hardwareInterface>hardware_interface/EffortJointInterface</hardwareInterface>
            <mechanicalReduction>1</mechanicalReduction>
        </actuator>
    </transmission>
    <transmission name="trans_left_front_roller_5_joint">
        <type>transmission_interface/SimpleTransmission</type>
        <joint name="left_front_roller_5_joint">
            <hardwareInterface>hardware_interface/EffortJointInterface</hardwareInterface>
        </joint>
        <actuator name="left_front_roller_5_joint_motor">
            <hardwareInterface>hardware_interface/EffortJointInterface</hardwareInterface>
            <mechanicalReduction>1</mechanicalReduction>
        </actuator>
    </transmission>
    <transmission name="trans_left_front_roller_6_joint">
        <type>transmission_interface/SimpleTransmission</type>
        <joint name="left_front_roller_6_joint">
            <hardwareInterface>hardware_interface/EffortJointInterface</hardwareInterface>
        </joint>
        <actuator name="left_front_roller_6_joint_motor">
            <hardwareInterface>hardware_interface/EffortJointInterface</hardwareInterface>
            <mechanicalReduction>1</mechanicalReduction>
        </actuator>
    </transmission>
    <transmission name="trans_left_front_roller_7_joint">
        <type>transmission_interface/SimpleTransmission</type>
        <joint name="left_front_roller_7_joint">
            <hardwareInterface>hardware_interface/EffortJointInterface</hardwareInterface>
        </joint>
        <actuator name="left_front_roller_7_joint_motor">
            <hardwareInterface>hardware_interface/EffortJointInterface</hardwareInterface>
            <mechanicalReduction>1</mechanicalReduction>
        </actuator>
    </transmission>
    <transmission name="trans_left_front_roller_8_joint">
        <type>transmission_interface/SimpleTransmission</type>
        <joint name="left_front_roller_8_joint">
            <hardwareInterface>hardware_interface/EffortJointInterface</hardwareInterface>
        </joint>
        <actuator name="left_front_roller_8_joint_motor">
            <hardwareInterface>hardware_interface/EffortJointInterface</hardwareInterface>
            <mechanicalReduction>1</mechanicalReduction>
        </actuator>
    </transmission>
    <transmission name="trans_left_front_roller_9_joint">
        <type>transmission_interface/SimpleTransmission</type>
        <joint name="left_front_roller_9_joint">
            <hardwareInterface>hardware_interface/EffortJointInterface</hardwareInterface>
        </joint>
        <actuator name="left_front_roller_9_joint_motor">
            <hardwareInterface>hardware_interface/EffortJointInterface</hardwareInterface>
            <mechanicalReduction>1</mechanicalReduction>
        </actuator>
    </transmission>
    <transmission name="trans_left_front_roller_10_joint">
        <type>transmission_interface/SimpleTransmission</type>
        <joint name="left_front_roller_10_joint">
            <hardwareInterface>hardware_interface/EffortJointInterface</hardwareInterface>
        </joint>
        <actuator name="left_front_roller_10_joint_motor">
            <hardwareInterface>hardware_interface/EffortJointInterface</hardwareInterface>
            <mechanicalReduction>1</mechanicalReduction>
        </actuator>
    </transmission>
    <transmission name="trans_left_front_roller_11_joint">
        <type>transmission_interface/SimpleTransmission</type>
        <joint name="left_front_roller_11_joint">
            <hardwareInterface>hardware_interface/EffortJointInterface</hardwareInterface>
        </joint>
        <actuator name="left_front_roller_11_joint_motor">
            <hardwareInterface>hardware_interface/EffortJointInterface</hardwareInterface>
            <mechanicalReduction>1</mechanicalReduction>
        </actuator>
    </transmission>
    <transmission name="trans_left_front_roller_12_joint">
        <type>transmission_interface/SimpleTransmission</type>
        <joint name="left_front_roller_12_joint">
            <hardwareInterface>hardware_interface/EffortJointInterface</hardwareInterface>
        </joint>
        <actuator name="left_front_roller_12_joint_motor">
            <hardwareInterface>hardware_interface/EffortJointInterface</hardwareInterface>
            <mechanicalReduction>1</mechanicalReduction>
        </actuator>
    </transmission>
    <transmission name="trans_left_front_roller_13_joint">
        <type>transmission_interface/SimpleTransmission</type>
        <joint name="left_front_roller_13_joint">
            <hardwareInterface>hardware_interface/EffortJointInterface</hardwareInterface>
        </joint>
        <actuator name="left_front_roller_13_joint_motor">
            <hardwareInterface>hardware_interface/EffortJointInterface</hardwareInterface>
            <mechanicalReduction>1</mechanicalReduction>
        </actuator>
    </transmission>
    <transmission name="trans_right_front_roller_0_joint">
        <type>transmission_interface/SimpleTransmission</type>
        <joint name="right_front_roller_0_joint">
            <hardwareInterface>hardware_interface/EffortJointInterface</hardwareInterface>
        </joint>
        <actuator name="right_front_roller_0_joint_motor">
            <hardwareInterface>hardware_interface/EffortJointInterface</hardwareInterface>
            <mechanicalReduction>1</mechanicalReduction>
        </actuator>
    </transmission>
    <transmission name="trans_right_front_roller_1_joint">
        <type>transmission_interface/SimpleTransmission</type>
        <joint name="right_front_roller_1_joint">
            <hardwareInterface>hardware_interface/EffortJointInterface</hardwareInterface>
        </joint>
        <actuator name="right_front_roller_1_joint_motor">
            <hardwareInterface>hardware_interface/EffortJointInterface</hardwareInterface>
            <mechanicalReduction>1</mechanicalReduction>
        </actuator>
    </transmission>
    <transmission name="trans_right_front_roller_2_joint">
        <type>transmission_interface/SimpleTransmission</type>
        <joint name="right_front_roller_2_joint">
            <hardwareInterface>hardware_interface/EffortJointInterface</hardwareInterface>
        </joint>
        <actuator name="right_front_roller_2_joint_motor">
            <hardwareInterface>hardware_interface/EffortJointInterface</hardwareInterface>
            <mechanicalReduction>1</mechanicalReduction>
        </actuator>
    </transmission>
    <transmission name="trans_right_front_roller_3_joint">
        <type>transmission_interface/SimpleTransmission</type>
        <joint name="right_front_roller_3_joint">
            <hardwareInterface>hardware_interface/EffortJointInterface</hardwareInterface>
        </joint>
        <actuator name="right_front_roller_3_joint_motor">
            <hardwareInterface>hardware_interface/EffortJointInterface</hardwareInterface>
            <mechanicalReduction>1</mechanicalReduction>
        </actuator>
    </transmission>
    <transmission name="trans_right_front_roller_4_joint">
        <type>transmission_interface/SimpleTransmission</type>
        <joint name="right_front_roller_4_joint">
            <hardwareInterface>hardware_interface/EffortJointInterface</hardwareInterface>
        </joint>
        <actuator name="right_front_roller_4_joint_motor">
            <hardwareInterface>hardware_interface/EffortJointInterface</hardwareInterface>
            <mechanicalReduction>1</mechanicalReduction>
        </actuator>
    </transmission>
    <transmission name="trans_right_front_roller_5_joint">
        <type>transmission_interface/SimpleTransmission</type>
        <joint name="right_front_roller_5_joint">
            <hardwareInterface>hardware_interface/EffortJointInterface</hardwareInterface>
        </joint>
        <actuator name="right_front_roller_5_joint_motor">
            <hardwareInterface>hardware_interface/EffortJointInterface</hardwareInterface>
            <mechanicalReduction>1</mechanicalReduction>
        </actuator>
    </transmission>
    <transmission name="trans_right_front_roller_6_joint">
        <type>transmission_interface/SimpleTransmission</type>
        <joint name="right_front_roller_6_joint">
            <hardwareInterface>hardware_interface/EffortJointInterface</hardwareInterface>
        </joint>
        <actuator name="right_front_roller_6_joint_motor">
            <hardwareInterface>hardware_interface/EffortJointInterface</hardwareInterface>
            <mechanicalReduction>1</mechanicalReduction>
        </actuator>
    </transmission>
    <transmission name="trans_right_front_roller_7_joint">
        <type>transmission_interface/SimpleTransmission</type>
        <joint name="right_front_roller_7_joint">
            <hardwareInterface>hardware_interface/EffortJointInterface</hardwareInterface>
        </joint>
        <actuator name="right_front_roller_7_joint_motor">
            <hardwareInterface>hardware_interface/EffortJointInterface</hardwareInterface>
            <mechanicalReduction>1</mechanicalReduction>
        </actuator>
    </transmission>
    <transmission name="trans_right_front_roller_8_joint">
        <type>transmission_interface/SimpleTransmission</type>
        <joint name="right_front_roller_8_joint">
            <hardwareInterface>hardware_interface/EffortJointInterface</hardwareInterface>
        </joint>
        <actuator name="right_front_roller_8_joint_motor">
            <hardwareInterface>hardware_interface/EffortJointInterface</hardwareInterface>
            <mechanicalReduction>1</mechanicalReduction>
        </actuator>
    </transmission>
    <transmission name="trans_right_front_roller_9_joint">
        <type>transmission_interface/SimpleTransmission</type>
        <joint name="right_front_roller_9_joint">
            <hardwareInterface>hardware_interface/EffortJointInterface</hardwareInterface>
        </joint>
        <actuator name="right_front_roller_9_joint_motor">
            <hardwareInterface>hardware_interface/EffortJointInterface</hardwareInterface>
            <mechanicalReduction>1</mechanicalReduction>
        </actuator>
    </transmission>
    <transmission name="trans_right_front_roller_10_joint">
        <type>transmission_interface/SimpleTransmission</type>
        <joint name="right_front_roller_10_joint">
            <hardwareInterface>hardware_interface/EffortJointInterface</hardwareInterface>
        </joint>
        <actuator name="right_front_roller_10_joint_motor">
            <hardwareInterface>hardware_interface/EffortJointInterface</hardwareInterface>
            <mechanicalReduction>1</mechanicalReduction>
        </actuator>
    </transmission>
    <transmission name="trans_right_front_roller_11_joint">
        <type>transmission_interface/SimpleTransmission</type>
        <joint name="right_front_roller_11_joint">
            <hardwareInterface>hardware_interface/EffortJointInterface</hardwareInterface>
        </joint>
        <actuator name="right_front_roller_11_joint_motor">
            <hardwareInterface>hardware_interface/EffortJointInterface</hardwareInterface>
            <mechanicalReduction>1</mechanicalReduction>
        </actuator>
    </transmission>
    <transmission name="trans_right_front_roller_12_joint">
        <type>transmission_interface/SimpleTransmission</type>
        <joint name="right_front_roller_12_joint">
            <hardwareInterface>hardware_interface/EffortJointInterface</hardwareInterface>
        </joint>
        <actuator name="right_front_roller_12_joint_motor">
            <hardwareInterface>hardware_interface/EffortJointInterface</hardwareInterface>
            <mechanicalReduction>1</mechanicalReduction>
        </actuator>
    </transmission>
    <transmission name="trans_right_front_roller_13_joint">
        <type>transmission_interface/SimpleTransmission</type>
        <joint name="right_front_roller_13_joint">
            <hardwareInterface>hardware_interface/EffortJointInterface</hardwareInterface>
        </joint>
        <actuator name="right_front_roller_13_joint_motor">
            <hardwareInterface>hardware_interface/EffortJointInterface</hardwareInterface>
            <mechanicalReduction>1</mechanicalReduction>
        </actuator>
    </transmission>
    <transmission name="trans_left_back_roller_0_joint">
        <type>transmission_interface/SimpleTransmission</type>
        <joint name="left_back_roller_0_joint">
            <hardwareInterface>hardware_interface/EffortJointInterface</hardwareInterface>
        </joint>
        <actuator name="left_back_roller_0_joint_motor">
            <hardwareInterface>hardware_interface/EffortJointInterface</hardwareInterface>
            <mechanicalReduction>1</mechanicalReduction>
        </actuator>
    </transmission>
    <transmission name="trans_left_back_roller_1_joint">
        <type>transmission_interface/SimpleTransmission</type>
        <joint name="left_back_roller_1_joint">
            <hardwareInterface>hardware_interface/EffortJointInterface</hardwareInterface>
        </joint>
        <actuator name="left_back_roller_1_joint_motor">
            <hardwareInterface>hardware_interface/EffortJointInterface</hardwareInterface>
            <mechanicalReduction>1</mechanicalReduction>
        </actuator>
    </transmission>
    <transmission name="trans_left_back_roller_2_joint">
        <type>transmission_interface/SimpleTransmission</type>
        <joint name="left_back_roller_2_joint">
            <hardwareInterface>hardware_interface/EffortJointInterface</hardwareInterface>
        </joint>
        <actuator name="left_back_roller_2_joint_motor">
            <hardwareInterface>hardware_interface/EffortJointInterface</hardwareInterface>
            <mechanicalReduction>1</mechanicalReduction>
        </actuator>
    </transmission>
    <transmission name="trans_left_back_roller_3_joint">
        <type>transmission_interface/SimpleTransmission</type>
        <joint name="left_back_roller_3_joint">
            <hardwareInterface>hardware_interface/EffortJointInterface</hardwareInterface>
        </joint>
        <actuator name="left_back_roller_3_joint_motor">
            <hardwareInterface>hardware_interface/EffortJointInterface</hardwareInterface>
            <mechanicalReduction>1</mechanicalReduction>
        </actuator>
    </transmission>
    <transmission name="trans_left_back_roller_4_joint">
        <type>transmission_interface/SimpleTransmission</type>
        <joint name="left_back_roller_4_joint">
            <hardwareInterface>hardware_interface/EffortJointInterface</hardwareInterface>
        </joint>
        <actuator name="left_back_roller_4_joint_motor">
            <hardwareInterface>hardware_interface/EffortJointInterface</hardwareInterface>
            <mechanicalReduction>1</mechanicalReduction>
        </actuator>
    </transmission>
    <transmission name="trans_left_back_roller_5_joint">
        <type>transmission_interface/SimpleTransmission</type>
        <joint name="left_back_roller_5_joint">
            <hardwareInterface>hardware_interface/EffortJointInterface</hardwareInterface>
        </joint>
        <actuator name="left_back_roller_5_joint_motor">
            <hardwareInterface>hardware_interface/EffortJointInterface</hardwareInterface>
            <mechanicalReduction>1</mechanicalReduction>
        </actuator>
    </transmission>
    <transmission name="trans_left_back_roller_6_joint">
        <type>transmission_interface/SimpleTransmission</type>
        <joint name="left_back_roller_6_joint">
            <hardwareInterface>hardware_interface/EffortJointInterface</hardwareInterface>
        </joint>
        <actuator name="left_back_roller_6_joint_motor">
            <hardwareInterface>hardware_interface/EffortJointInterface</hardwareInterface>
            <mechanicalReduction>1</mechanicalReduction>
        </actuator>
    </transmission>
    <transmission name="trans_left_back_roller_7_joint">
        <type>transmission_interface/SimpleTransmission</type>
        <joint name="left_back_roller_7_joint">
            <hardwareInterface>hardware_interface/EffortJointInterface</hardwareInterface>
        </joint>
        <actuator name="left_back_roller_7_joint_motor">
            <hardwareInterface>hardware_interface/EffortJointInterface</hardwareInterface>
            <mechanicalReduction>1</mechanicalReduction>
        </actuator>
    </transmission>
    <transmission name="trans_left_back_roller_8_joint">
        <type>transmission_interface/SimpleTransmission</type>
        <joint name="left_back_roller_8_joint">
            <hardwareInterface>hardware_interface/EffortJointInterface</hardwareInterface>
        </joint>
        <actuator name="left_back_roller_8_joint_motor">
            <hardwareInterface>hardware_interface/EffortJointInterface</hardwareInterface>
            <mechanicalReduction>1</mechanicalReduction>
        </actuator>
    </transmission>
    <transmission name="trans_left_back_roller_9_joint">
        <type>transmission_interface/SimpleTransmission</type>
        <joint name="left_back_roller_9_joint">
            <hardwareInterface>hardware_interface/EffortJointInterface</hardwareInterface>
        </joint>
        <actuator name="left_back_roller_9_joint_motor">
            <hardwareInterface>hardware_interface/EffortJointInterface</hardwareInterface>
            <mechanicalReduction>1</mechanicalReduction>
        </actuator>
    </transmission>
    <transmission name="trans_left_back_roller_10_joint">
        <type>transmission_interface/SimpleTransmission</type>
        <joint name="left_back_roller_10_joint">
            <hardwareInterface>hardware_interface/EffortJointInterface</hardwareInterface>
        </joint>
        <actuator name="left_back_roller_10_joint_motor">
            <hardwareInterface>hardware_interface/EffortJointInterface</hardwareInterface>
            <mechanicalReduction>1</mechanicalReduction>
        </actuator>
    </transmission>
    <transmission name="trans_left_back_roller_11_joint">
        <type>transmission_interface/SimpleTransmission</type>
        <joint name="left_back_roller_11_joint">
            <hardwareInterface>hardware_interface/EffortJointInterface</hardwareInterface>
        </joint>
        <actuator name="left_back_roller_11_joint_motor">
            <hardwareInterface>hardware_interface/EffortJointInterface</hardwareInterface>
            <mechanicalReduction>1</mechanicalReduction>
        </actuator>
    </transmission>
    <transmission name="trans_left_back_roller_12_joint">
        <type>transmission_interface/SimpleTransmission</type>
        <joint name="left_back_roller_12_joint">
            <hardwareInterface>hardware_interface/EffortJointInterface</hardwareInterface>
        </joint>
        <actuator name="left_back_roller_12_joint_motor">
            <hardwareInterface>hardware_interface/EffortJointInterface</hardwareInterface>
            <mechanicalReduction>1</mechanicalReduction>
        </actuator>
    </transmission>
    <transmission name="trans_left_back_roller_13_joint">
        <type>transmission_interface/SimpleTransmission</type>
        <joint name="left_back_roller_13_joint">
            <hardwareInterface>hardware_interface/EffortJointInterface</hardwareInterface>
        </joint>
        <actuator name="left_back_roller_13_joint_motor">
            <hardwareInterface>hardware_interface/EffortJointInterface</hardwareInterface>
            <mechanicalReduction>1</mechanicalReduction>
        </actuator>
    </transmission>
    <transmission name="trans_right_back_roller_0_joint">
        <type>transmission_interface/SimpleTransmission</type>
        <joint name="right_back_roller_0_joint">
            <hardwareInterface>hardware_interface/EffortJointInterface</hardwareInterface>
        </joint>
        <actuator name="right_back_roller_0_joint_motor">
            <hardwareInterface>hardware_interface/EffortJointInterface</hardwareInterface>
            <mechanicalReduction>1</mechanicalReduction>
        </actuator>
    </transmission>
    <transmission name="trans_right_back_roller_1_joint">
        <type>transmission_interface/SimpleTransmission</type>
        <joint name="right_back_roller_1_joint">
            <hardwareInterface>hardware_interface/EffortJointInterface</hardwareInterface>
        </joint>
        <actuator name="right_back_roller_1_joint_motor">
            <hardwareInterface>hardware_interface/EffortJointInterface</hardwareInterface>
            <mechanicalReduction>1</mechanicalReduction>
        </actuator>
    </transmission>
    <transmission name="trans_right_back_roller_2_joint">
        <type>transmission_interface/SimpleTransmission</type>
        <joint name="right_back_roller_2_joint">
            <hardwareInterface>hardware_interface/EffortJointInterface</hardwareInterface>
        </joint>
        <actuator name="right_back_roller_2_joint_motor">
            <hardwareInterface>hardware_interface/EffortJointInterface</hardwareInterface>
            <mechanicalReduction>1</mechanicalReduction>
        </actuator>
    </transmission>
    <transmission name="trans_right_back_roller_3_joint">
        <type>transmission_interface/SimpleTransmission</type>
        <joint name="right_back_roller_3_joint">
            <hardwareInterface>hardware_interface/EffortJointInterface</hardwareInterface>
        </joint>
        <actuator name="right_back_roller_3_joint_motor">
            <hardwareInterface>hardware_interface/EffortJointInterface</hardwareInterface>
            <mechanicalReduction>1</mechanicalReduction>
        </actuator>
    </transmission>
    <transmission name="trans_right_back_roller_4_joint">
        <type>transmission_interface/SimpleTransmission</type>
        <joint name="right_back_roller_4_joint">
            <hardwareInterface>hardware_interface/EffortJointInterface</hardwareInterface>
        </joint>
        <actuator name="right_back_roller_4_joint_motor">
            <hardwareInterface>hardware_interface/EffortJointInterface</hardwareInterface>
            <mechanicalReduction>1</mechanicalReduction>
        </actuator>
    </transmission>
    <transmission name="trans_right_back_roller_5_joint">
        <type>transmission_interface/SimpleTransmission</type>
        <joint name="right_back_roller_5_joint">
            <hardwareInterface>hardware_interface/EffortJointInterface</hardwareInterface>
        </joint>
        <actuator name="right_back_roller_5_joint_motor">
            <hardwareInterface>hardware_interface/EffortJointInterface</hardwareInterface>
            <mechanicalReduction>1</mechanicalReduction>
        </actuator>
    </transmission>
    <transmission name="trans_right_back_roller_6_joint">
        <type>transmission_interface/SimpleTransmission</type>
        <joint name="right_back_roller_6_joint">
            <hardwareInterface>hardware_interface/EffortJointInterface</hardwareInterface>
        </joint>
        <actuator name="right_back_roller_6_joint_motor">
            <hardwareInterface>hardware_interface/EffortJointInterface</hardwareInterface>
            <mechanicalReduction>1</mechanicalReduction>
        </actuator>
    </transmission>
    <transmission name="trans_right_back_roller_7_joint">
        <type>transmission_interface/SimpleTransmission</type>
        <joint name="right_back_roller_7_joint">
            <hardwareInterface>hardware_interface/EffortJointInterface</hardwareInterface>
        </joint>
        <actuator name="right_back_roller_7_joint_motor">
            <hardwareInterface>hardware_interface/EffortJointInterface</hardwareInterface>
            <mechanicalReduction>1</mechanicalReduction>
        </actuator>
    </transmission>
    <transmission name="trans_right_back_roller_8_joint">
        <type>transmission_interface/SimpleTransmission</type>
        <joint name="right_back_roller_8_joint">
            <hardwareInterface>hardware_interface/EffortJointInterface</hardwareInterface>
        </joint>
        <actuator name="right_back_roller_8_joint_motor">
            <hardwareInterface>hardware_interface/EffortJointInterface</hardwareInterface>
            <mechanicalReduction>1</mechanicalReduction>
        </actuator>
    </transmission>
    <transmission name="trans_right_back_roller_9_joint">
        <type>transmission_interface/SimpleTransmission</type>
        <joint name="right_back_roller_9_joint">
            <hardwareInterface>hardware_interface/EffortJointInterface</hardwareInterface>
        </joint>
        <actuator name="right_back_roller_9_joint_motor">
            <hardwareInterface>hardware_interface/EffortJointInterface</hardwareInterface>
            <mechanicalReduction>1</mechanicalReduction>
        </actuator>
    </transmission>
    <transmission name="trans_right_back_roller_10_joint">
        <type>transmission_interface/SimpleTransmission</type>
        <joint name="right_back_roller_10_joint">
            <hardwareInterface>hardware_interface/EffortJointInterface</hardwareInterface>
        </joint>
        <actuator name="right_back_roller_10_joint_motor">
            <hardwareInterface>hardware_interface/EffortJointInterface</hardwareInterface>
            <mechanicalReduction>1</mechanicalReduction>
        </actuator>
    </transmission>
    <transmission name="trans_right_back_roller_11_joint">
        <type>transmission_interface/SimpleTransmission</type>
        <joint name="right_back_roller_11_joint">
            <hardwareInterface>hardware_interface/EffortJointInterface</hardwareInterface>
        </joint>
        <actuator name="right_back_roller_11_joint_motor">
            <hardwareInterface>hardware_interface/EffortJointInterface</hardwareInterface>
            <mechanicalReduction>1</mechanicalReduction>
        </actuator>
    </transmission>
    <transmission name="trans_right_back_roller_12_joint">
        <type>transmission_interface/SimpleTransmission</type>
        <joint name="right_back_roller_12_joint">
            <hardwareInterface>hardware_interface/EffortJointInterface</hardwareInterface>
        </joint>
        <actuator name="right_back_roller_12_joint_motor">
            <hardwareInterface>hardware_interface/EffortJointInterface</hardwareInterface>
            <mechanicalReduction>1</mechanicalReduction>
        </actuator>
    </transmission>
    <transmission name="trans_right_back_roller_13_joint">
        <type>transmission_interface/SimpleTransmission</type>
        <joint name="right_back_roller_13_joint">
            <hardwareInterface>hardware_interface/EffortJointInterface</hardwareInterface>
        </joint>
        <actuator name="right_back_roller_13_joint_motor">
            <hardwareInterface>hardware_interface/EffortJointInterface</hardwareInterface>
            <mechanicalReduction>1</mechanicalReduction>
        </actuator>
    </transmission>
    <transmission name="trans_joint5">
        <type>transmission_interface/SimpleTransmission</type>
        <joint name="joint5">
            <hardwareInterface>hardware_interface/EffortJointInterface</hardwareInterface>
        </joint>
        <actuator name="joint5_motor">
            <hardwareInterface>hardware_interface/EffortJointInterface</hardwareInterface>
            <mechanicalReduction>1</mechanicalReduction>
        </actuator>
    </transmission>
    <transmission name="trans_joint6">
        <type>transmission_interface/SimpleTransmission</type>
        <joint name="joint6">
            <hardwareInterface>hardware_interface/EffortJointInterface</hardwareInterface>
        </joint>
        <actuator name="joint6_motor">
            <hardwareInterface>hardware_interface/EffortJointInterface</hardwareInterface>
            <mechanicalReduction>1</mechanicalReduction>
        </actuator>
    </transmission>
    <transmission name="trans_middle_pitch">
        <type>transmission_interface/SimpleTransmission</type>
        <joint name="middle_pitch">
            <hardwareInterface>hardware_interface/EffortJointInterface</hardwareInterface>
        </joint>
        <actuator name="middle_pitch_motor">
            <hardwareInterface>hardware_interface/EffortJointInterface</hardwareInterface>
            <mechanicalReduction>1</mechanicalReduction>
        </actuator>
    </transmission>
</robot>
